Workbook

Sheet Portada
A1: Seguros Barú, S.A. — Cierres IFRS 17 de 2023, 2024 y 2025
A2: Aseguradora ficticia; datos sintéticos generados con semilla fija. Cifras en USD.
A4: Leyenda
A5: Azul | B5: valor calculado por el motor en Python (src/ifrs17)
A6: Negro | B6: fórmula de Excel
A7: Verde | B7: vínculo a otra hoja
A8: Fondo verde claro | B8: celda de control: debe ser cero
A10: Hoja | B10: Contenido
A11: EEFF | B11: Estado de situación financiera (par. 78-79) y de resultados y ORI (par. 80-92)
A12: Conc_100 | B12: Conciliación LRC sin componente de pérdida, componente de pérdida y LIC (par. 100, 103)
A13: Conc_101 | B13: Conciliación de valor presente, ajuste por riesgo y CSM, contratos GMM y reaseguro (par. 101, 104)
A14: Ingresos_106 | B14: Análisis de los ingresos por seguros de los grupos GMM (par. 106)
A15: NegocioNuevo_107 | B15: Efecto de los contratos reconocidos en el periodo (par. 107)
A16: CSM_109 | B16: Reconocimiento esperado del CSM por bandas de años (par. 109)
A17: Supuestos | B17: Supuestos, curvas de descuento y nivel de confianza (par. 117, 119, 120)
... A21: Controles | B21: Resumen de todas las celdas de control

Sheet EEFF
A1: Estados financieros
A2: Sin impuesto sobre la renta (fuera de alcance). Presentación con NIC 1; ver el anexo IFRS 18 al final.
A4: Estado de situación financiera | B4: 31-dic-2023 | C4: 31-dic-2024 | D4: 31-dic-2025
A5: Inversiones a valor razonable con cambios en resultados | B5: 14299160 | C5: 27410252 | D5: 41779310
A6: Inversiones a valor razonable con cambios en ORI | B6: 20000000 | C6: 20017693 | D6: 20000000
A7: Activos por contratos de seguro | B7: 0 | C7: 0 | D7: 38473.159
A8: Activos por contratos de reaseguro cedido | B8: 844071.92 | C8: 2083847.4 | D8: 3035118.4
A9: Total activos | B9: =SUM(B5:B8) -> 35143232 | C9: =SUM(C5:C8) -> 49511792 | D9: =SUM(D5:D8) -> 64852902
A11: Pasivos por contratos de seguro | B11: 14550189 | C11: 28066153 | D11: 39272810
A13: Capital social | B13: 20000000 | C13: 20000000 | D13: 20000000
A14: Resultados acumulados | B14: =B35 -> 593622.93 | C14: =B14+C35 -> 2608745.1 | D14: =C14+D35 -> 5857942.6
A15: Reserva de finanzas de seguros (ORI) | B15: =B38+B39 -> -579.97655 | C15: =B15+C38+C39 -> 45520.959 | D15: =C15+D38+D39 -> 129270.19
A16: Reserva de inversiones a valor razonable con cambios en ORI | B16: =B40 -> 0 | C16: =B16+C40 -> -1208627.2 | D16: =C16+D40 -> -407121.57
A17: Total patrimonio | B17: =SUM(B13:B16) -> 20593043 | C17: =SUM(C13:C16) -> 21445639 | D17: =SUM(D13:D16) -> 25580091
A18: Control: activos - pasivos - patrimonio | B18: =B9-B11-B17 -> 0 | C18: =C9-C11-C17 -> 0 | D18: =D9-D11-D17 -> 0
A22: Estado de resultados y otro resultado integral | B22: 2023 | C22: 2024 | D22: 2025
A23: Ingresos por seguros | B23: 9780724.3 | C23: 21995636 | D23: 26742566
A24: Gastos del servicio de seguros | B24: -9402411.9 | C24: -19796288 | D24: -23580953
A25: Resultado neto de los contratos de reaseguro cedido | B25: 72221.7 | C25: -311236.34 | D25: -610562.75
A26: Resultado del servicio de seguros | B26: =SUM(B23:B25) -> 450534.08 | C26: =SUM(C23:C25) -> 1888112.6 | D26: =SUM(D23:D25) -> 2551051.2
A28: Ingresos de inversiones | B28: 1279596 | C28: 1761017.4 | D28: 2232567.1
A29: Gastos financieros de seguros emitidos | B29: 69650.905 | C29: -428758.71 | D29: -326366.44
A30: Ingresos financieros del reaseguro cedido | B30: 13219.207 | C30: 40519.167 | D30: 87039.887
A31: Resultado financiero neto | B31: =SUM(B28:B30) -> 1362466.1 | C31: =SUM(C28:C30) -> 1372777.9 | D31: =SUM(D28:D30) -> 1993240.6
A33: Otros gastos de operación (no atribuibles, B66(d)) | B33: -1219377.2 | C33: -1245768.4 | D33: -1295094.2
A35: Resultado del año antes de impuestos | B35: =B26+B31+B33 -> 593622.93 | C35: =C26+C31+C33 -> 2015122.1 | D35: =D26+D31+D33 -> 3249197.6
A37: Otro resultado integral (partidas que se reclasificarán)
A38: Finanzas de seguros emitidos | B38: -25501.892 | C38: 108963.98 | D38: 58759.951
A39: Finanzas del reaseguro cedido | B39: 24921.916 | C39: -62863.047 | D39: 24989.276
A40: Inversiones a valor razonable con cambios en ORI | B40: 0 | C40: -1208627.2 | D40: 801505.63
A42: Resultado integral total | B42: =B35+SUM(B38:B40) -> 593042.96 | C42: =C35+SUM(C38:C40) -> 852595.86 | D42: =D35+SUM(D38:D40) -> 4134452.4
A43: Control: resultado de la fórmula - resultado del motor | B43: =B35-593622.933065355 -> 0 | C43: =C35-2015122.1254712 -> 0 | D43: =D35-3249197.58347216 -> 0

Sheet Conc_100
A1: Conciliación del pasivo por cobertura restante y por siniestros incurridos (par. 100, 103)
A2: Contratos emitidos por portafolio. Los saldos iniciales de 2024 y 2025 son el saldo final del año anterior (fórmula).
A4: Vida temporal
A5: Vida temporal — 2023 | B5: LRC sin componente de pérdida | C5: Componente de pérdida | D5: LIC | E5: Total
A6: Saldo inicial | B6: 0 | C6: 0 | D6: 0 | E6: =SUM(B6:D6) -> 0
A7: Ingresos por seguros | B7: -1189126.7 | C7: 0 | D7: 0 | E7: =SUM(B7:D7) -> -1189126.7
A8: Siniestros y otros gastos incurridos | B8: 0 | C8: 0 | D8: 1026865.5 | E8: =SUM(B8:D8) -> 1026865.5
A9: Amortización de flujos de adquisición | B9: 108886.1 | C9: 0 | D9: 0 | E9: =SUM(B9:D9) -> 108886.1
A10: Pérdidas y reversiones en grupos onerosos | B10: 0 | C10: 217843.79 | D10: 0 | E10: =SUM(B10:D10) -> 217843.79
A11: Cambios del LIC por servicio pasado | B11: 0 | C11: 0 | D11: 315.9382 | E11: =SUM(B11:D11) -> 315.9382
A12: Componentes de inversión | B12: 0 | C12: 0 | D12: 0 | E12: =SUM(B12:D12) -> 0
A13: Ingresos o gastos financieros de seguros | B13: 14758.52 | C13: 71.110996 | D13: 0 | E13: =SUM(B13:D13) -> 14829.631
A14: Primas recibidas | B14: 3330340.9 | C14: 0 | D14: 0 | E14: =SUM(B14:D14) -> 3330340.9
A15: Siniestros y gastos pagados | B15: 0 | C15: 0 | D15: -963677.89 | E15: =SUM(B15:D15) -> -963677.89
A16: Flujos de adquisición pagados | B16: -2120728.7 | C16: 0 | D16: 0 | E16: =SUM(B16:D16) -> -2120728.7
A17: Saldo final | B17: =SUM(B6:B16) -> 144130.15 | C17: =SUM(C6:C16) -> 217914.9 | D17: =SUM(D6:D16) -> 63503.579 | E17: =SUM(E6:E16) -> 425548.63
A18: Control: saldo final de la fórmula - saldo del motor | B18: =B17-144130.150100621 -> 5.2386895e-10 | C18: =C17-217914.897137835 -> 0 | D18: =D17-63503.5789585253 -> 3.4197001e-10
A20: Vida temporal — 2024 | B20: LRC sin componente de pérdida | C20: Componente de pérdida | D20: LIC | E20: Total
A21: Saldo inicial | B21: =B17 -> 144130.15 | C21: =C17 -> 217914.9 | D21: =D17 -> 63503.579 | E21: =SUM(B21:D21) -> 425548.63
A22: Ingresos por seguros | B22: -3665183 | C22: 0 | D22: 0 | E22: =SUM(B22:D22) -> -3665183
A23: Siniestros y otros gastos incurridos | B23: 0 | C23: 0 | D23: 1961017.6 | E23: =SUM(B23:D23) -> 1961017.6
A24: Amortización de flujos de adquisición | B24: 300495.83 | C24: 0 | D24: 0 | E24: =SUM(B24:D24) -> 300495.83
A25: Pérdidas y reversiones en grupos onerosos | B25: 0 | C25: 645672.35 | D25: 0 | E25: =SUM(B25:D25) -> 645672.35
A26: Cambios del LIC por servicio pasado | B26: 0 | C26: 0 | D26: -61568.303 | E26: =SUM(B26:D26) -> -61568.303
A27: Componentes de inversión | B27: 0 | C27: 0 | D27: 0 | E27: =SUM(B27:D27) -> 0
A28: Ingresos o gastos financieros de seguros | B28: -125353.79 | C28: 519.55935 | D28: 0 | E28: =SUM(B28:D28) -> -124834.23
A29: Primas recibidas | B29: 6304236.5 | C29: 0 | D29: 0 | E29: =SUM(B29:D29) -> 6304236.5
A30: Siniestros y gastos pagados | B30: 0 | C30: 0 | D30: -1573962.3 | E30: =SUM(B30:D30) -> -1573962.3
A31: Flujos de adquisición pagados | B31: -2109882.6 | C31: 0 | D31: 0 | E31: =SUM(B31:D31) -> -2109882.6
A32: Saldo final | B32: =SUM(B21:B31) -> 848443.09 | C32: =SUM(C21:C31) -> 864106.8 | D32: =SUM(D21:D31) -> 388990.52 | E32: =SUM(E21:E31) -> 2101540.4
A33: Control: saldo final de la fórmula - saldo del motor | B33: =B32-848443.090026392 -> 0 | C33: =C32-864106.801529094 -> 0 | D33: =D32-388990.518563933 -> 0
A35: Vida temporal — 2025 | B35: LRC sin componente de pérdida | C35: Componente de pérdida | D35: LIC | E35: Total
A36: Saldo inicial | B36: =B32 -> 848443.09 | C36: =C32 -> 864106.8 | D36: =D32 -> 388990.52 | E36: =SUM(B36:D36) -> 2101540.4
A37: Ingresos por seguros | B37: -6126829.5 | C37: 0 | D37: 0 | E37: =SUM(B37:D37) -> -6126829.5
A38: Siniestros y otros gastos incurridos | B38: 0 | C38: 0 | D38: 4296058 | E38: =SUM(B38:D38) -> 4296058
A39: Amortización de flujos de adquisición | B39: 490841.3 | C39: 0 | D39: 0 | E39: =SUM(B39:D39) -> 490841.3
A40: Pérdidas y reversiones en grupos onerosos | B40: 0 | C40: -644767.29 | D40: 0 | E40: =SUM(B40:D40) -> -644767.29
A41: Cambios del LIC por servicio pasado | B41: 0 | C41: 0 | D41: 368389.41 | E41: =SUM(B41:D41) -> 368389.41
A42: Componentes de inversión | B42: 0 | C42: 0 | D42: 0 | E42: =SUM(B42:D42) -> 0
A43: Ingresos o gastos financieros de seguros | B43: -27468.105 | C43: 3213.5777 | D43: 0 | E43: =SUM(B43:D43) -> -24254.527
...

Sheet Conc_101
A1: Conciliación del valor presente de los flujos, el ajuste por riesgo y el CSM (par. 101, 104)
A2: Contratos medidos con el GMM. El reaseguro cedido se muestra como activo (signo positivo) y por separado (par. 98).
A4: Vida temporal
A5: Vida temporal — 2023 | B5: Valor presente de flujos futuros | C5: Ajuste por riesgo no financiero | D5: Margen contractual de servicio | E5: Total
A6: Saldo inicial | B6: 0 | C6: 0 | D6: 0 | E6: =SUM(B6:D6) -> 0
A7: Cambios en estimaciones que ajustan el CSM | B7: 320955.88 | C7: 17259.844 | D7: -338215.72 | E7: =SUM(B7:D7) -> 0
A8: Cambios que no ajustan el CSM (onerosos) | B8: 57414.146 | C8: 4482.5578 | D8: 0 | E8: =SUM(B8:D8) -> 61896.704
A9: Recuperación de pérdidas (reaseguro, 66A) | B9: 0 | C9: 0 | D9: 0 | E9: =SUM(B9:D9) -> 0
A10: Contratos reconocidos en el periodo | B10: -4164573.5 | C10: 1210744.3 | D10: 3117508.9 | E10: =SUM(B10:D10) -> 163679.61
A11: CSM reconocido por servicios | B11: 0 | C11: 0 | D11: -144388.95 | E11: =SUM(B11:D11) -> -144388.95
A12: Cambio del ajuste por riesgo por riesgo vencido | B12: 0 | C12: -2541.8914 | D12: 0 | E12: =SUM(B12:D12) -> -2541.8914
A13: Ajustes por experiencia | B13: 85823.223 | C13: 0 | D13: 0 | E13: =SUM(B13:D13) -> 85823.223
A14: Ingresos o gastos financieros de seguros | B14: -76281.167 | C14: 0 | D14: 91110.798 | E14: =SUM(B14:D14) -> 14829.631
A15: Primas recibidas / pagadas | B15: 3330340.9 | C15: 0 | D15: 0 | E15: =SUM(B15:D15) -> 3330340.9
A16: Siniestros y gastos incurridos / recuperaciones | B16: -1026865.5 | C16: 0 | D16: 0 | E16: =SUM(B16:D16) -> -1026865.5
A17: Componentes de inversión | B17: 0 | C17: 0 | D17: 0 | E17: =SUM(B17:D17) -> 0
A18: Flujos de adquisición pagados | B18: -2120728.7 | C18: 0 | D18: 0 | E18: =SUM(B18:D18) -> -2120728.7
A19: Saldo final | B19: =SUM(B6:B18) -> -3593914.7 | C19: =SUM(C6:C18) -> 1229944.8 | D19: =SUM(D6:D18) -> 2726015 | E19: =SUM(E6:E18) -> 362045.05
A20: Control: saldo final de la fórmula - saldo del motor | B20: =B19--3593914.74723631 -> 0 | C20: =C19-1229944.8094988 -> 0 | D20: =D19-2726014.98497596 -> 0
A22: Vida temporal — 2024 | B22: Valor presente de flujos futuros | C22: Ajuste por riesgo no financiero | D22: Margen contractual de servicio | E22: Total
A23: Saldo inicial | B23: =B19 -> -3593914.7 | C23: =C19 -> 1229944.8 | D23: =D19 -> 2726015 | E23: =SUM(B23:D23) -> 362045.05
A24: Cambios en estimaciones que ajustan el CSM | B24: 695871.31 | C24: 44478.291 | D24: -740349.6 | E24: =SUM(B24:D24) -> 0
A25: Cambios que no ajustan el CSM (onerosos) | B25: 494066.72 | C25: 27820.115 | D25: 0 | E25: =SUM(B25:D25) -> 521886.84
A26: Recuperación de pérdidas (reaseguro, 66A) | B26: 0 | C26: 0 | D26: 0 | E26: =SUM(B26:D26) -> 0
A27: Contratos reconocidos en el periodo | B27: -4020735.1 | C27: 1231288.8 | D27: 2940782.7 | E27: =SUM(B27:D27) -> 151336.34
A28: CSM reconocido por servicios | B28: 0 | C28: 0 | D28: -365540.56 | E28: =SUM(B28:D28) -> -365540.56
A29: Cambio del ajuste por riesgo por riesgo vencido | B29: 0 | C29: -216542.84 | D29: 0 | E29: =SUM(B29:D29) -> -216542.84
A30: Ajustes por experiencia | B30: -849137.05 | C30: 0 | D30: 0 | E30: =SUM(B30:D30) -> -849137.05
A31: Ingresos o gastos financieros de seguros | B31: -349291.01 | C31: 0 | D31: 224456.78 | E31: =SUM(B31:D31) -> -124834.23
A32: Primas recibidas / pagadas | B32: 6304236.5 | C32: 0 | D32: 0 | E32: =SUM(B32:D32) -> 6304236.5
A33: Siniestros y gastos incurridos / recuperaciones | B33: -1961017.6 | C33: 0 | D33: 0 | E33: =SUM(B33:D33) -> -1961017.6
A34: Componentes de inversión | B34: 0 | C34: 0 | D34: 0 | E34: =SUM(B34:D34) -> 0
A35: Flujos de adquisición pagados | B35: -2109882.6 | C35: 0 | D35: 0 | E35: =SUM(B35:D35) -> -2109882.6
A36: Saldo final | B36: =SUM(B23:B35) -> -5389803.5 | C36: =SUM(C23:C35) -> 2316989.1 | D36: =SUM(D23:D35) -> 4785364.3 | E36: =SUM(E23:E35) -> 1712549.9
A37: Control: saldo final de la fórmula - saldo del motor | B37: =B36--5389803.49147336 -> 0 | C37: =C36-2316989.13124314 -> 0 | D37: =D36-4785364.25178571 -> 0
A39: Vida temporal — 2025 | B39: Valor presente de flujos futuros | C39: Ajuste por riesgo no financiero | D39: Margen contractual de servicio | E39: Total
A40: Saldo inicial | B40: =B36 -> -5389803.5 | C40: =C36 -> 2316989.1 | D40: =D36 -> 4785364.3 | E40: =SUM(B40:D40) -> 1712549.9
A41: Cambios en estimaciones que ajustan el CSM | B41: -2251074.1 | C41: -105580.53 | D41: 2356654.7 | E41: =SUM(B41:D41) -> 0
A42: Cambios que no ajustan el CSM (onerosos) | B42: -532040.79 | C42: -33433.07 | D42: 0 | E42: =SUM(B42:D42) -> -565473.86
A43: Recuperación de pérdidas (reaseguro, 66A) | B43: 0 | C43: 0 | D43: 0 | E43: =SUM(B43:D43) -> 0
...

Sheet Ingresos_106
A1: Análisis de los ingresos por seguros, grupos GMM (par. 106)
A2: Siniestros y gastos esperados, liberación del ajuste por riesgo y del CSM, y recuperación de adquisición (B121-B125).
A4: closing | B4: portfolio | C4: expected_claims_and_expenses | D4: loss_component_exclusion | E4: ra_release | F4: csm_release | G4: acquisition_recovery | H4: insurance_revenue | I4: Total por fórmula
A5: 2023-12-31 | B5: VA | C5: 199855.63 | D5: 0 | E5: -23872.702 | F5: 18642.239 | G5: 150431.17 | H5: 345056.34 | I5: =SUM(C5:G5) -> 345056.34 | J5: =I5-H5 -> 0
A6: 2023-12-31 | B6: VT | C6: 941042.31 | D6: -7732.5257 | E6: 2541.8914 | F6: 144388.95 | G6: 108886.1 | H6: 1189126.7 | I6: =SUM(C6:G6) -> 1189126.7 | J6: =I6-H6 -> 0
A7: 2024-12-31 | B7: VA | C7: 597430.86 | D7: 0 | E7: 108105.06 | F7: 56118.692 | G7: 297391.42 | H7: 1059046 | I7: =SUM(C7:G7) -> 1059046 | J7: =I7-H7 -> 0
A8: 2024-12-31 | B8: VT | C8: 2810154.6 | D8: -27550.836 | E8: 216542.84 | F8: 365540.56 | G8: 300495.83 | H8: 3665183 | I8: =SUM(C8:G8) -> 3665183 | J8: =I8-H8 -> 0
A9: 2025-12-31 | B9: VA | C9: 968066.26 | D9: 0 | E9: -11388.897 | F9: 100439.22 | G9: 441716.23 | H9: 1498832.8 | I9: =SUM(C9:G9) -> 1498832.8 | J9: =I9-H9 -> 0
A10: 2025-12-31 | B10: VT | C10: 4773577.7 | D10: -79293.436 | E10: 44458.571 | F10: 897245.39 | G10: 490841.3 | H10: 6126829.5 | I10: =SUM(C10:G10) -> 6126829.5 | J10: =I10-H10 -> 0
A11: Control: total por fórmula - ingresos del motor

Sheet NegocioNuevo_107
A1: Contratos reconocidos en el periodo (par. 107)
A2: Salidas (con adquisición aparte), entradas, ajuste por riesgo y CSM; los grupos onerosos van aparte. La suma es la pérdida inicial.
A4: closing | B4: portfolio | C4: onerous | D4: pv_acquisition_outflows | E4: pv_other_outflows | F4: pv_inflows | G4: ra | H4: csm | I4: loss | J4: Suma = pérdida | K4: Control: suma - pérdida
A5: 2023-12-31 | B5: VA | C5: =FALSE() -> FALSE | D5: 1987549.6 | E5: 33190296 | F5: -38193830 | G5: 772192.83 | H5: 2243790.7 | I5: 0 | J5: =SUM(D5:H5) -> 1.0244548e-08 | K5: =J5-I5 -> 1.0244548e-08
A6: 2023-12-31 | B6: VT | C6: =FALSE() -> FALSE | D6: 1853044.4 | E6: 16733824 | F6: -22736501 | G6: 1032123.3 | H6: 3117508.9 | I6: 0 | J6: =SUM(D6:H6) -> 0 | K6: =J6-I6 -> 0
A7: 2023-12-31 | B7: VT | C7: =TRUE() -> TRUE | D7: 267684.25 | E7: 2872075.6 | F7: -3154701.3 | G7: 178621.03 | H7: 0 | I7: 163679.61 | J7: =SUM(D7:H7) -> 163679.61 | K7: =J7-I7 -> 0
A8: 2024-12-31 | B8: VA | C8: =FALSE() -> FALSE | D8: 1976308.8 | E8: 33191215 | F8: -38069649 | G8: 773206.31 | H8: 2128919.5 | I8: 0 | J8: =SUM(D8:H8) -> 0 | K8: =J8-I8 -> 0
A9: 2024-12-31 | B9: VT | C9: =FALSE() -> FALSE | D9: 1864574.9 | E9: 17110707 | F9: -22984741 | G9: 1068676.5 | H9: 2940782.7 | I9: 0 | J9: =SUM(D9:H9) -> 0 | K9: =J9-I9 -> 0
A10: 2024-12-31 | B10: VT | C10: =TRUE() -> TRUE | D10: 245307.69 | E10: 2578273.9 | F10: -2834857.6 | G10: 162612.27 | H10: 0 | I10: 151336.34 | J10: =SUM(D10:H10) -> 151336.34 | K10: =J10-I10 -> 0
A11: 2025-12-31 | B11: VA | C11: =FALSE() -> FALSE | D11: 1965802.5 | E11: 32973789 | F11: -37794820 | G11: 767372.67 | H11: 2087856.3 | I11: 0 | J11: =SUM(D11:H11) -> 0 | K11: =J11-I11 -> 0
A12: 2025-12-31 | B12: VT | C12: =FALSE() -> FALSE | D12: 2251768 | E12: 20295053 | F12: -28081522 | G12: 1279700.1 | H12: 4255001 | I12: 0 | J12: =SUM(D12:H12) -> 0 | K12: =J12-I12 -> 0

Sheet CSM_109
A1: Reconocimiento esperado del CSM al 31-dic-2025 (par. 109)
A2: Años en que se espera reconocer el CSM según las unidades de cobertura futuras, sin acreción futura. El reaseguro se muestra con signo de costo (negativo).
A4: portfolio | B4: 1 | C4: 2 | D4: 3 | E4: 4 | F4: 5 | G4: 6-10 | H4: >10 | I4: Total
A5: VT | B5: 1072955.2 | C5: 1009117.9 | D5: 961013.32 | E5: 919008.13 | F5: 878603.69 | G5: 3535818.8 | H5: 2459703.2 | I5: =SUM(B5:H5) -> 10836220
A6: RE_VT | B6: -393574.4 | C6: -370267.43 | D6: -352713.3 | E6: -337393.7 | F6: -322659.85 | G6: -1301621.4 | H6: -939261.36 | I6: =SUM(B6:H6) -> -4017491.4
A7: VA | B7: 126562.23 | C7: 141819.87 | D7: 156597.49 | E7: 170293.59 | F7: 184008.14 | G7: 1137020 | H7: 5168104 | I7: =SUM(B7:H7) -> 7084405.4

Sheet Supuestos
A1: Supuestos, curvas y nivel de confianza (par. 117, 119, 120)
A2: Factores de mortalidad por cierre, curvas spot (anual efectiva) y nivel de confianza.
A4: Supuestos
A5: closing | B5: assumption | C5: value | D5: basis | E5: own_factor | F5: credibility
A6: 2023-12-31 | B6: mortalidad (default) | C6: 0.7714629655051102 | D6: factor sobre CSO 1980 | E6: 1.0382224 | F6: 0.074466681
A7: 2023-12-31 | B7: mortalidad (older_high_si) | C7: 0.75 | D7: factor sobre CSO 1980 | E7: 0 | F7: 0
A8: 2024-12-31 | B8: mortalidad (default) | C8: 0.7475383180864552 | D8: factor sobre CSO 1980 | E8: 0.7297565 | F8: 0.12160358
A9: 2024-12-31 | B9: mortalidad (older_high_si) | C9: 1.15 | D9: factor sobre CSO 1980 | E9: 0 | F9: 0
A10: 2025-12-31 | B10: mortalidad (default) | C10: 0.7379584723545553 | D10: factor sobre CSO 1980 | E10: 0.68104937 | F10: 0.17463985
A11: 2025-12-31 | B11: mortalidad (older_high_si) | C11: 0.8515890474076682 | D11: factor sobre CSO 1980 | E11: 0.88017796 | F11: 0.052655895
A12: todos | B12: mejora de mortalidad | C12: 0.01 | D12: anual
A13: todos | B13: caducidad vida temporal (años 1, 2, 3+) | C13: (0.08, 0.06, 0.04) | D13: anual
A14: todos | B14: caducidad vida con ahorro (años 1-7+) | C14: (0.1, 0.08, 0.07, 0.06, 0.05, 0.07, 0.04) | D14: anual
A15: todos | B15: inflación de gastos | C15: 0.025 | D15: anual
A16: todos | B16: diferencial de tasa acreditada | C16: 0.0125 | D16: HQM a 1 año menos diferencial, mínimo 2,5% (B98)
A19: Curvas de descuento (spot anual)
A20: closing | B20: portfolio | C20: 1y | D20: 5y | E20: 10y | F20: 20y | G20: 30y | H20: 40y
A21: 2023-12-31 | B21: VT | C21: 0.051855 | D21: 0.046324 | E21: 0.049703 | F21: 0.051753 | G21: 0.05165 | H21: 0.05165
A22: 2023-12-31 | B22: VA | C22: 0.051855 | D22: 0.046324 | E22: 0.049703 | F22: 0.051753 | G22: 0.05165 | H22: 0.05165
A23: 2023-12-31 | B23: AUTO | C23: 0.051855 | D23: 0.046324 | E23: 0.049703 | F23: 0.051753 | G23: 0.05165 | H23: 0.05165
A24: 2023-12-31 | B24: TRC | C24: 0.051855 | D24: 0.046324 | E24: 0.049703 | F24: 0.051753 | G24: 0.05165 | H24: 0.05165
A25: 2024-12-31 | B25: VT | C25: 0.046427 | D25: 0.0496 | E25: 0.054318 | F25: 0.058429 | G25: 0.058738 | H25: 0.059356
A26: 2024-12-31 | B26: VA | C26: 0.046427 | D26: 0.0496 | E26: 0.054318 | F26: 0.058429 | G26: 0.058738 | H26: 0.059356
A27: 2024-12-31 | B27: AUTO | C27: 0.046427 | D27: 0.0496 | E27: 0.054318 | F27: 0.058429 | G27: 0.058738 | H27: 0.059356
A28: 2024-12-31 | B28: TRC | C28: 0.046427 | D28: 0.0496 | E28: 0.054318 | F28: 0.058429 | G28: 0.058738 | H28: 0.059356
A29: 2025-12-31 | B29: VT | C29: 0.038769 | D29: 0.042952 | E29: 0.050215 | F29: 0.058429 | G29: 0.061312 | H29: 0.062858
A30: 2025-12-31 | B30: VA | C30: 0.038769 | D30: 0.042952 | E30: 0.050215 | F30: 0.058429 | G30: 0.061312 | H30: 0.062858
A31: 2025-12-31 | B31: AUTO | C31: 0.038769 | D31: 0.042952 | E31: 0.050215 | F31: 0.058429 | G31: 0.061312 | H31: 0.062858
A32: 2025-12-31 | B32: TRC | C32: 0.038769 | D32: 0.042952 | E32: 0.050215 | F32: 0.058429 | G32: 0.061312 | H32: 0.062858
A35: Nivel de confianza del ajuste por riesgo
A36: portfolio | B36: technique | C36: risk_adjustment | D36: capital_99_5 | E36: confidence_level
A37: Vida temporal | B37: costo de capital 6% | C37: 3413217 | D37: 7491576 | E37: 0.8797157
A38: Daños (LIC) | B38: percentil 75, lognormal, correlación 25% | C38: 769958.27 | E38: 0.7326508

Sheet Sensibilidades_128
A1: Sensibilidades al 31-dic-2025 (par. 128(a))
A2: Efecto en resultados y patrimonio, bruto y neto de reaseguro. Los cambios no financieros que absorbe el CSM no afectan el resultado.
A4: portfolio | B4: change | C4: profit_gross | D4: equity_gross | E4: profit_net | F4: equity_net
A5: VT | B5: mortalidad +10% | C5: -470262.99 | D5: -470262.99 | E5: -282157.8 | F5: -282157.8
A6: VT | B6: mortalidad -10% | C6: 222553.09 | D6: 222553.09 | E6: 133531.85 | F6: 133531.85
A7: VT | B7: caducidad +10% | C7: 19154.621 | D7: 19154.621 | E7: 19154.621 | F7: 19154.621
A8: VT | B8: caducidad -10% | C8: -20327.389 | D8: -20327.389 | E8: -20327.389 | F8: -20327.389
A9: VT | B9: gastos +10% | C9: -27723.12 | D9: -27723.12 | E9: -27723.12 | F9: -27723.12
A10: VT | B10: tasas +100 pb | C10: 0 | D10: 48767.651 | E10: 0 | F10: 29260.59
A11: VT | B11: tasas -100 pb | C11: 0 | D11: -97195.453 | E11: 0 | F11: -58317.272
A12: VA | B12: mortalidad +10% | C12: 0 | D12: 0 | E12: 0 | F12: 0
A13: VA | B13: caducidad +10% | C13: 0 | D13: 0 | E13: 0 | F13: 0
A14: VA | B14: caducidad -10% | C14: 0 | D14: 0 | E14: 0 | F14: 0
A15: VA | B15: gastos +10% | C15: 0 | D15: 0 | E15: 0 | F15: 0
A16: VA | B16: tasas +100 pb | C16: -818868.24 | D16: -818868.24 | E16: -818868.24 | F16: -818868.24
... A26: Inversiones | B26: tasas -100 pb | C26: 208896.55 | D26: 1808896.6 | E26: 208896.55 | F26: 1808896.6

Sheet Desarrollo_130
A1: Desarrollo de siniestros (par. 130)
A2: Estimación no descontada del último costo por año de accidente en cada cierre; última = pagado + pendiente (fórmula).
A4: Autos
A5: Cierre | B5: Año de accidente | C5: Pagado acumulado | D5: Pendiente no descontado | E5: Última estimación (fórmula) | F5: LIC descontado (sin ajuste por riesgo) | G5: Efecto del descuento (fórmula)
A6: 2023-12-31 | B6: 2023 | C6: 1401589.2 | D6: 2649679 | E6: =C6+D6 -> 4051268.3 | F6: 2503680.8 | G6: =F6-D6 -> -145998.18
A7: 2024-12-31 | B7: 2023 | C7: 3348181 | D7: 616105.51 | E7: =C7+D7 -> 3964286.5 | F7: 574505.84 | G7: =F7-D7 -> -41599.671
A8: 2024-12-31 | B8: 2024 | C8: 4009360.8 | D8: 4793743.8 | E8: =C8+D8 -> 8803104.6 | F8: 4516930.9 | G8: =F8-D8 -> -276812.92
A9: 2025-12-31 | B9: 2023 | C9: 3701037.6 | D9: 311704.36 | E9: =C9+D9 -> 4012742 | F9: 294354.56 | G9: =F9-D9 -> -17349.802
A10: 2025-12-31 | B10: 2024 | C10: 7215936.2 | D10: 1761852.9 | E10: =C10+D10 -> 8977789.1 | F10: 1659988.9 | G10: =F10-D10 -> -101864.01
A11: 2025-12-31 | B11: 2025 | C11: 4441340.5 | D11: 4390151.3 | E11: =C11+D11 -> 8831491.8 | F11: 4175358.6 | G11: =F11-D11 -> -214792.7
A14: Todo riesgo construcción
A15: Cierre | B15: Año de accidente | C15: Pagado acumulado | D15: Pendiente no descontado | E15: Última estimación (fórmula) | F15: LIC descontado (sin ajuste por riesgo) | G15: Efecto del descuento (fórmula)
A16: 2023-12-31 | B16: 2023 | C16: 5029.11 | D16: 23398.039 | E16: =C16+D16 -> 28427.149 | F16: 22610.088 | G16: =F16-D16 -> -787.95126
A17: 2024-12-31 | B17: 2023 | C17: 7194.99 | D17: 12274.921 | E17: =C17+D17 -> 19469.911 | F17: 12000.866 | G17: =F17-D17 -> -274.05513
A18: 2024-12-31 | B18: 2024 | C18: 298130.44 | D18: 583068.98 | E18: =C18+D18 -> 881199.42 | F18: 569153.63 | G18: =F18-D18 -> -13915.35
A19: 2025-12-31 | B19: 2023 | C19: 17949.85 | D19: 0.14258656 | E19: =C19+D19 -> 17949.993 | F19: 0.13903457 | G19: =F19-D19 -> -0.0035519866
A20: 2025-12-31 | B20: 2024 | C20: 1383205.2 | D20: 70134.553 | E20: =C20+D20 -> 1453339.7 | F20: 68824.913 | G20: =F20-D20 -> -1309.6401
A21: 2025-12-31 | B21: 2025 | C21: 531532.04 | D21: 1026024.5 | E21: =C21+D21 -> 1557556.6 | F21: 1005076.6 | G21: =F21-D21 -> -20947.897

Sheet Liquidez_132
A1: Flujos netos esperados no descontados al 31-dic-2025 (par. 132(b)(i))
A2: Salidas netas positivas. Vida incluye primas futuras (entradas, negativas) y el LIC; daños solo el LIC (132(b)).
A4: portfolio | B4: año 1 | C4: año 2 | D4: año 3 | E4: año 4 | F4: año 5 | G4: más de 5 años | H4: Total
A5: VT | B5: -3146086.4 | C5: -3047206.6 | D5: -2623935.5 | E5: -2195450 | F5: -1775231.6 | G5: 3583332.3 | H5: =SUM(B5:G5) -> -9204577.7
A6: VA | B6: -8171716.1 | C6: -7120727.9 | D6: -6074786.1 | E6: -5228058.2 | F6: -4635947 | G6: 1.7848267e+08 | H6: =SUM(B6:G6) -> 1.4725144e+08
A7: AUTO | B7: 3536595.2 | C7: 1394263.6 | D7: 755119.49 | E7: 394479.5 | F7: 197343.61 | G7: 185907.19 | H7: =SUM(B7:G7) -> 6463708.6
A8: INC | B8: 638499.1 | C8: 0 | D8: 0 | E8: 0 | F8: 0 | G8: 0 | H8: =SUM(B8:G8) -> 638499.1
A9: TRC | B9: 1096159.2 | C9: 0 | D9: 0 | E9: 0 | F9: 0 | G9: 0 | H9: =SUM(B9:G9) -> 1096159.2

Sheet Controles
A1: Resumen de controles
A2: Cada celda enlaza a un control de otra hoja; el total absoluto debe ser cero.
A4: Celda | B4: Valor
A5: EEFF!B18 | B5: =EEFF!B18 -> 0
A6: EEFF!C18 | B6: =EEFF!C18 -> 0
A7: EEFF!D18 | B7: =EEFF!D18 -> 0
A8: EEFF!B43 | B8: =EEFF!B43 -> 0
A9: EEFF!C43 | B9: =EEFF!C43 -> 0
A10: EEFF!D43 | B10: =EEFF!D43 -> 0
A11: Conc_100!B18 | B11: =Conc_100!B18 -> 5.2386895e-10
A12: Conc_100!C18 | B12: =Conc_100!C18 -> 0
A13: Conc_100!D18 | B13: =Conc_100!D18 -> 3.4197001e-10
A14: Conc_100!B33 | B14: =Conc_100!B33 -> 0
A15: Conc_100!C33 | B15: =Conc_100!C33 -> 0
A16: Conc_100!D33 | B16: =Conc_100!D33 -> 0
A17: Conc_100!B48 | B17: =Conc_100!B48 -> 0
A18: Conc_100!C48 | B18: =Conc_100!C48 -> 0
A19: Conc_100!D48 | B19: =Conc_100!D48 -> 0
A20: Conc_100!B65 | B20: =Conc_100!B65 -> 0
A21: Conc_100!C65 | B21: =Conc_100!C65 -> 0
A22: Conc_100!D65 | B22: =Conc_100!D65 -> -1.0641088e-10
A23: Conc_100!B80 | B23: =Conc_100!B80 -> 0
A24: Conc_100!C80 | B24: =Conc_100!C80 -> 0
A25: Conc_100!D80 | B25: =Conc_100!D80 -> -3.0377123e-10
A26: Conc_100!B95 | B26: =Conc_100!B95 -> 0
A27: Conc_100!C95 | B27: =Conc_100!C95 -> 0
A28: Conc_100!D95 | B28: =Conc_100!D95 -> -5.657057e-10
A29: Conc_100!B112 | B29: =Conc_100!B112 -> 0
A30: Conc_100!C112 | B30: =Conc_100!C112 -> 0
A31: Conc_100!D112 | B31: =Conc_100!D112 -> 0
A32: Conc_100!B127 | B32: =Conc_100!B127 -> 0
A33: Conc_100!C127 | B33: =Conc_100!C127 -> 0
A34: Conc_100!D127 | B34: =Conc_100!D127 -> 0
A35: Conc_100!B142 | B35: =Conc_100!B142 -> 0
A36: Conc_100!C142 | B36: =Conc_100!C142 -> 0
A37: Conc_100!D142 | B37: =Conc_100!D142 -> 0
A38: Conc_100!B159 | B38: =Conc_100!B159 -> 0
A39: Conc_100!C159 | B39: =Conc_100!C159 -> 0
A40: Conc_100!D159 | B40: =Conc_100!D159 -> 0
A41: Conc_100!B174 | B41: =Conc_100!B174 -> 0
...
