Workbook

Sheet Parametros
A1: Seguros Barú — parámetros de la curva de descuento IFRS 17
A2: Celdas amarillas con texto azul: supuestos que se pueden cambiar; todo el libro se recalcula.
A4: Parámetro | B4: Valor | C4: Fuente o razón
A5: Porcentaje del diferencial HQM − TNC atribuido a crédito | B5: 0 | C5: Política elegida: 0% (la curva es la HQM). Opción: 55%, con base en CDS (Longstaff, Mithal y Neis 2005: 51% AAA/AA, 56% A; IFRS 17 B78, B79, B85). Ver hoja Metodo_credito.
A6: Factor de liquidez — Alta | B6: 1 | C6: Vida temporal y su reaseguro (sin valor de rescate). Política: 100%. Opción graduada: 100%.
A7: Factor de liquidez — Media | B7: 1 | C7: Autos, incendio/hogar y TRC. Política: 100%. Opción graduada: 75%.
A8: Factor de liquidez — Baja | B8: 1 | C8: Vida con ahorro (el asegurado puede rescatar). Política: 100%. Opción graduada: 50%.
A11: Método
A12: 1. Curva base: TNC del Tesoro de EE. UU., tasas spot de fin de mes, 0,5 a 100 años, capitalización semestral.
A13: 2. Prima de iliquidez por plazo = MAX(0; HQM − TNC) × (1 − % crédito) × factor de liquidez (IFRS 17 B79–B80).
A14: 3. Tasa semestral = TNC + prima; tasa anual efectiva = (1 + s/2)^2 − 1; factor de descuento = (1 + r)^(−t).
A15: 4. Hojas Mensual_: interpolación lineal del logaritmo del factor de descuento entre puntos semestrales; plana por debajo de 0,5 años.
A16: Política elegida: 0% de crédito y factor 100%, así que la curva es exactamente la HQM, porque TNC + (HQM − TNC) = HQM.
A17: Fuente de datos: U.S. Treasury, Office of Economic Policy, archivos tnceom_23_27.xlsx, hqmeom_19_23.xls y hqmeom_24_28.xls.

Sheet Resumen
A1: Tasas spot anuales efectivas a plazos seleccionados
A2: Fórmulas que leen las hojas de cada cierre; cambian si cambian los parámetros.
A4: Cierre | B4: Curva | C4: 1 años | D4: 5 años | E4: 10 años | F4: 20 años | G4: 30 años | H4: 40 años | I4: 60 años | J4: 100 años
A5: Dic2023 | B5: TNC (Tesoro) | C5: =(1+INDEX(Dic2023!$B$6:$B$205,MATCH(1,Dic2023!$A$6:$A$205,0))/2)^2-1 -> 0.04837121 | D5: =(1+INDEX(Dic2023!$B$6:$B$205,MATCH(5,Dic2023!$A$6:$A$205,0))/2)^2-1 -> 0.03917636 | E5: =(1+INDEX(Dic2023!$B$6:$B$205,MATCH(10,Dic2023!$A$6:$A$205,0))/2)^2-1 -> 0.037851562 | F5: =(1+INDEX(Dic2023!$B$6:$B$205,MATCH(20,Dic2023!$A$6:$A$205,0))/2)^2-1 -> 0.04346225 | G5: =(1+INDEX(Dic2023!$B$6:$B$205,MATCH(30,Dic2023!$A$6:$A$205,0))/2)^2-1 -> 0.04080804 | H5: =(1+INDEX(Dic2023!$B$6:$B$205,MATCH(40,Dic2023!$A$6:$A$205,0))/2)^2-1 -> 0.041930563 | I5: =(1+INDEX(Dic2023!$B$6:$B$205,MATCH(60,Dic2023!$A$6:$A$205,0))/2)^2-1 -> 0.043155822 | J5: =(1+INDEX(Dic2023!$B$6:$B$205,MATCH(100,Dic2023!$A$6:$A$205,0))/2)^2-1 -> 0.04407524
A6: Dic2023 | B6: IFRS 17 — liquidez alta | C6: =INDEX(Dic2023!$G$6:$G$205,MATCH(1,Dic2023!$A$6:$A$205,0)) -> 0.05185536 | D6: =INDEX(Dic2023!$G$6:$G$205,MATCH(5,Dic2023!$A$6:$A$205,0)) -> 0.04632441 | E6: =INDEX(Dic2023!$G$6:$G$205,MATCH(10,Dic2023!$A$6:$A$205,0)) -> 0.049702703 | F6: =INDEX(Dic2023!$G$6:$G$205,MATCH(20,Dic2023!$A$6:$A$205,0)) -> 0.051752803 | G6: =INDEX(Dic2023!$G$6:$G$205,MATCH(30,Dic2023!$A$6:$A$205,0)) -> 0.05165025 | H6: =INDEX(Dic2023!$G$6:$G$205,MATCH(40,Dic2023!$A$6:$A$205,0)) -> 0.05165025 | I6: =INDEX(Dic2023!$G$6:$G$205,MATCH(60,Dic2023!$A$6:$A$205,0)) -> 0.051752803 | J6: =INDEX(Dic2023!$G$6:$G$205,MATCH(100,Dic2023!$A$6:$A$205,0)) -> 0.051752803
A7: Dic2023 | B7: IFRS 17 — liquidez media | C7: =INDEX(Dic2023!$J$6:$J$205,MATCH(1,Dic2023!$A$6:$A$205,0)) -> 0.05185536 | D7: =INDEX(Dic2023!$J$6:$J$205,MATCH(5,Dic2023!$A$6:$A$205,0)) -> 0.04632441 | E7: =INDEX(Dic2023!$J$6:$J$205,MATCH(10,Dic2023!$A$6:$A$205,0)) -> 0.049702703 | F7: =INDEX(Dic2023!$J$6:$J$205,MATCH(20,Dic2023!$A$6:$A$205,0)) -> 0.051752803 | G7: =INDEX(Dic2023!$J$6:$J$205,MATCH(30,Dic2023!$A$6:$A$205,0)) -> 0.05165025 | H7: =INDEX(Dic2023!$J$6:$J$205,MATCH(40,Dic2023!$A$6:$A$205,0)) -> 0.05165025 | I7: =INDEX(Dic2023!$J$6:$J$205,MATCH(60,Dic2023!$A$6:$A$205,0)) -> 0.051752803 | J7: =INDEX(Dic2023!$J$6:$J$205,MATCH(100,Dic2023!$A$6:$A$205,0)) -> 0.051752803
A8: Dic2023 | B8: IFRS 17 — liquidez baja | C8: =INDEX(Dic2023!$M$6:$M$205,MATCH(1,Dic2023!$A$6:$A$205,0)) -> 0.05185536 | D8: =INDEX(Dic2023!$M$6:$M$205,MATCH(5,Dic2023!$A$6:$A$205,0)) -> 0.04632441 | E8: =INDEX(Dic2023!$M$6:$M$205,MATCH(10,Dic2023!$A$6:$A$205,0)) -> 0.049702703 | F8: =INDEX(Dic2023!$M$6:$M$205,MATCH(20,Dic2023!$A$6:$A$205,0)) -> 0.051752803 | G8: =INDEX(Dic2023!$M$6:$M$205,MATCH(30,Dic2023!$A$6:$A$205,0)) -> 0.05165025 | H8: =INDEX(Dic2023!$M$6:$M$205,MATCH(40,Dic2023!$A$6:$A$205,0)) -> 0.05165025 | I8: =INDEX(Dic2023!$M$6:$M$205,MATCH(60,Dic2023!$A$6:$A$205,0)) -> 0.051752803 | J8: =INDEX(Dic2023!$M$6:$M$205,MATCH(100,Dic2023!$A$6:$A$205,0)) -> 0.051752803
A9: Dic2023 | B9: HQM (corporativos) | C9: =(1+INDEX(Dic2023!$C$6:$C$205,MATCH(1,Dic2023!$A$6:$A$205,0))/2)^2-1 -> 0.05185536 | D9: =(1+INDEX(Dic2023!$C$6:$C$205,MATCH(5,Dic2023!$A$6:$A$205,0))/2)^2-1 -> 0.04632441 | E9: =(1+INDEX(Dic2023!$C$6:$C$205,MATCH(10,Dic2023!$A$6:$A$205,0))/2)^2-1 -> 0.049702703 | F9: =(1+INDEX(Dic2023!$C$6:$C$205,MATCH(20,Dic2023!$A$6:$A$205,0))/2)^2-1 -> 0.051752803 | G9: =(1+INDEX(Dic2023!$C$6:$C$205,MATCH(30,Dic2023!$A$6:$A$205,0))/2)^2-1 -> 0.05165025 | H9: =(1+INDEX(Dic2023!$C$6:$C$205,MATCH(40,Dic2023!$A$6:$A$205,0))/2)^2-1 -> 0.05165025 | I9: =(1+INDEX(Dic2023!$C$6:$C$205,MATCH(60,Dic2023!$A$6:$A$205,0))/2)^2-1 -> 0.051752803 | J9: =(1+INDEX(Dic2023!$C$6:$C$205,MATCH(100,Dic2023!$A$6:$A$205,0))/2)^2-1 -> 0.051752803
A11: Dic2024 | B11: TNC (Tesoro) | C11: =(1+INDEX(Dic2024!$B$6:$B$205,MATCH(1,Dic2024!$A$6:$A$205,0))/2)^2-1 -> 0.04284944 | D11: =(1+INDEX(Dic2024!$B$6:$B$205,MATCH(5,Dic2024!$A$6:$A$205,0))/2)^2-1 -> 0.04468841 | E11: =(1+INDEX(Dic2024!$B$6:$B$205,MATCH(10,Dic2024!$A$6:$A$205,0))/2)^2-1 -> 0.04632441 | F11: =(1+INDEX(Dic2024!$B$6:$B$205,MATCH(20,Dic2024!$A$6:$A$205,0))/2)^2-1 -> 0.050522502 | G11: =(1+INDEX(Dic2024!$B$6:$B$205,MATCH(30,Dic2024!$A$6:$A$205,0))/2)^2-1 -> 0.04919049 | H11: =(1+INDEX(Dic2024!$B$6:$B$205,MATCH(40,Dic2024!$A$6:$A$205,0))/2)^2-1 -> 0.05001009 | I11: =(1+INDEX(Dic2024!$B$6:$B$205,MATCH(60,Dic2024!$A$6:$A$205,0))/2)^2-1 -> 0.050727503 | J11: =(1+INDEX(Dic2024!$B$6:$B$205,MATCH(100,Dic2024!$A$6:$A$205,0))/2)^2-1 -> 0.051342622
A12: Dic2024 | B12: IFRS 17 — liquidez alta | C12: =INDEX(Dic2024!$G$6:$G$205,MATCH(1,Dic2024!$A$6:$A$205,0)) -> 0.046426702 | D12: =INDEX(Dic2024!$G$6:$G$205,MATCH(5,Dic2024!$A$6:$A$205,0)) -> 0.04960025 | E12: =INDEX(Dic2024!$G$6:$G$205,MATCH(10,Dic2024!$A$6:$A$205,0)) -> 0.05431824 | F12: =INDEX(Dic2024!$G$6:$G$205,MATCH(20,Dic2024!$A$6:$A$205,0)) -> 0.05842944 | G12: =INDEX(Dic2024!$G$6:$G$205,MATCH(30,Dic2024!$A$6:$A$205,0)) -> 0.058738103 | H12: =INDEX(Dic2024!$G$6:$G$205,MATCH(40,Dic2024!$A$6:$A$205,0)) -> 0.059355563 | I12: =INDEX(Dic2024!$G$6:$G$205,MATCH(60,Dic2024!$A$6:$A$205,0)) -> 0.059973202 | J12: =INDEX(Dic2024!$G$6:$G$205,MATCH(100,Dic2024!$A$6:$A$205,0)) -> 0.060385063
A13: Dic2024 | B13: IFRS 17 — liquidez media | C13: =INDEX(Dic2024!$J$6:$J$205,MATCH(1,Dic2024!$A$6:$A$205,0)) -> 0.046426702 | D13: =INDEX(Dic2024!$J$6:$J$205,MATCH(5,Dic2024!$A$6:$A$205,0)) -> 0.04960025 | E13: =INDEX(Dic2024!$J$6:$J$205,MATCH(10,Dic2024!$A$6:$A$205,0)) -> 0.05431824 | F13: =INDEX(Dic2024!$J$6:$J$205,MATCH(20,Dic2024!$A$6:$A$205,0)) -> 0.05842944 | G13: =INDEX(Dic2024!$J$6:$J$205,MATCH(30,Dic2024!$A$6:$A$205,0)) -> 0.058738103 | H13: =INDEX(Dic2024!$J$6:$J$205,MATCH(40,Dic2024!$A$6:$A$205,0)) -> 0.059355563 | I13: =INDEX(Dic2024!$J$6:$J$205,MATCH(60,Dic2024!$A$6:$A$205,0)) -> 0.059973202 | J13: =INDEX(Dic2024!$J$6:$J$205,MATCH(100,Dic2024!$A$6:$A$205,0)) -> 0.060385063
A14: Dic2024 | B14: IFRS 17 — liquidez baja | C14: =INDEX(Dic2024!$M$6:$M$205,MATCH(1,Dic2024!$A$6:$A$205,0)) -> 0.046426702 | D14: =INDEX(Dic2024!$M$6:$M$205,MATCH(5,Dic2024!$A$6:$A$205,0)) -> 0.04960025 | E14: =INDEX(Dic2024!$M$6:$M$205,MATCH(10,Dic2024!$A$6:$A$205,0)) -> 0.05431824 | F14: =INDEX(Dic2024!$M$6:$M$205,MATCH(20,Dic2024!$A$6:$A$205,0)) -> 0.05842944 | G14: =INDEX(Dic2024!$M$6:$M$205,MATCH(30,Dic2024!$A$6:$A$205,0)) -> 0.058738103 | H14: =INDEX(Dic2024!$M$6:$M$205,MATCH(40,Dic2024!$A$6:$A$205,0)) -> 0.059355563 | I14: =INDEX(Dic2024!$M$6:$M$205,MATCH(60,Dic2024!$A$6:$A$205,0)) -> 0.059973202 | J14: =INDEX(Dic2024!$M$6:$M$205,MATCH(100,Dic2024!$A$6:$A$205,0)) -> 0.060385063
A15: Dic2024 | B15: HQM (corporativos) | C15: =(1+INDEX(Dic2024!$C$6:$C$205,MATCH(1,Dic2024!$A$6:$A$205,0))/2)^2-1 -> 0.046426702 | D15: =(1+INDEX(Dic2024!$C$6:$C$205,MATCH(5,Dic2024!$A$6:$A$205,0))/2)^2-1 -> 0.04960025 | E15: =(1+INDEX(Dic2024!$C$6:$C$205,MATCH(10,Dic2024!$A$6:$A$205,0))/2)^2-1 -> 0.05431824 | F15: =(1+INDEX(Dic2024!$C$6:$C$205,MATCH(20,Dic2024!$A$6:$A$205,0))/2)^2-1 -> 0.05842944 | G15: =(1+INDEX(Dic2024!$C$6:$C$205,MATCH(30,Dic2024!$A$6:$A$205,0))/2)^2-1 -> 0.058738103 | H15: =(1+INDEX(Dic2024!$C$6:$C$205,MATCH(40,Dic2024!$A$6:$A$205,0))/2)^2-1 -> 0.059355563 | I15: =(1+INDEX(Dic2024!$C$6:$C$205,MATCH(60,Dic2024!$A$6:$A$205,0))/2)^2-1 -> 0.059973202 | J15: =(1+INDEX(Dic2024!$C$6:$C$205,MATCH(100,Dic2024!$A$6:$A$205,0))/2)^2-1 -> 0.060385063
A17: Dic2025 | B17: TNC (Tesoro) | C17: =(1+INDEX(Dic2025!$B$6:$B$205,MATCH(1,Dic2025!$A$6:$A$205,0))/2)^2-1 -> 0.03550976 | D17: =(1+INDEX(Dic2025!$B$6:$B$205,MATCH(5,Dic2025!$A$6:$A$205,0))/2)^2-1 -> 0.03774969 | E17: =(1+INDEX(Dic2025!$B$6:$B$205,MATCH(10,Dic2025!$A$6:$A$205,0))/2)^2-1 -> 0.04264521 | F17: =(1+INDEX(Dic2025!$B$6:$B$205,MATCH(20,Dic2025!$A$6:$A$205,0))/2)^2-1 -> 0.050932522 | G17: =(1+INDEX(Dic2025!$B$6:$B$205,MATCH(30,Dic2025!$A$6:$A$205,0))/2)^2-1 -> 0.05103504 | H17: =(1+INDEX(Dic2025!$B$6:$B$205,MATCH(40,Dic2025!$A$6:$A$205,0))/2)^2-1 -> 0.052573402 | I17: =(1+INDEX(Dic2025!$B$6:$B$205,MATCH(60,Dic2025!$A$6:$A$205,0))/2)^2-1 -> 0.05411289 | J17: =(1+INDEX(Dic2025!$B$6:$B$205,MATCH(100,Dic2025!$A$6:$A$205,0))/2)^2-1 -> 0.05534529
A18: Dic2025 | B18: IFRS 17 — liquidez alta | C18: =INDEX(Dic2025!$G$6:$G$205,MATCH(1,Dic2025!$A$6:$A$205,0)) -> 0.03876864 | D18: =INDEX(Dic2025!$G$6:$G$205,MATCH(5,Dic2025!$A$6:$A$205,0)) -> 0.042951562 | E18: =INDEX(Dic2025!$G$6:$G$205,MATCH(10,Dic2025!$A$6:$A$205,0)) -> 0.05021504 | F18: =INDEX(Dic2025!$G$6:$G$205,MATCH(20,Dic2025!$A$6:$A$205,0)) -> 0.05842944 | G18: =INDEX(Dic2025!$G$6:$G$205,MATCH(30,Dic2025!$A$6:$A$205,0)) -> 0.06131204 | H18: =INDEX(Dic2025!$G$6:$G$205,MATCH(40,Dic2025!$A$6:$A$205,0)) -> 0.062857903 | I18: =INDEX(Dic2025!$G$6:$G$205,MATCH(60,Dic2025!$A$6:$A$205,0)) -> 0.06440489 | J18: =INDEX(Dic2025!$G$6:$G$205,MATCH(100,Dic2025!$A$6:$A$205,0)) -> 0.06564329
A19: Dic2025 | B19: IFRS 17 — liquidez media | C19: =INDEX(Dic2025!$J$6:$J$205,MATCH(1,Dic2025!$A$6:$A$205,0)) -> 0.03876864 | D19: =INDEX(Dic2025!$J$6:$J$205,MATCH(5,Dic2025!$A$6:$A$205,0)) -> 0.042951562 | E19: =INDEX(Dic2025!$J$6:$J$205,MATCH(10,Dic2025!$A$6:$A$205,0)) -> 0.05021504 | F19: =INDEX(Dic2025!$J$6:$J$205,MATCH(20,Dic2025!$A$6:$A$205,0)) -> 0.05842944 | G19: =INDEX(Dic2025!$J$6:$J$205,MATCH(30,Dic2025!$A$6:$A$205,0)) -> 0.06131204 | H19: =INDEX(Dic2025!$J$6:$J$205,MATCH(40,Dic2025!$A$6:$A$205,0)) -> 0.062857903 | I19: =INDEX(Dic2025!$J$6:$J$205,MATCH(60,Dic2025!$A$6:$A$205,0)) -> 0.06440489 | J19: =INDEX(Dic2025!$J$6:$J$205,MATCH(100,Dic2025!$A$6:$A$205,0)) -> 0.06564329
A20: Dic2025 | B20: IFRS 17 — liquidez baja | C20: =INDEX(Dic2025!$M$6:$M$205,MATCH(1,Dic2025!$A$6:$A$205,0)) -> 0.03876864 | D20: =INDEX(Dic2025!$M$6:$M$205,MATCH(5,Dic2025!$A$6:$A$205,0)) -> 0.042951562 | E20: =INDEX(Dic2025!$M$6:$M$205,MATCH(10,Dic2025!$A$6:$A$205,0)) -> 0.05021504 | F20: =INDEX(Dic2025!$M$6:$M$205,MATCH(20,Dic2025!$A$6:$A$205,0)) -> 0.05842944 | G20: =INDEX(Dic2025!$M$6:$M$205,MATCH(30,Dic2025!$A$6:$A$205,0)) -> 0.06131204 | H20: =INDEX(Dic2025!$M$6:$M$205,MATCH(40,Dic2025!$A$6:$A$205,0)) -> 0.062857903 | I20: =INDEX(Dic2025!$M$6:$M$205,MATCH(60,Dic2025!$A$6:$A$205,0)) -> 0.06440489 | J20: =INDEX(Dic2025!$M$6:$M$205,MATCH(100,Dic2025!$A$6:$A$205,0)) -> 0.06564329
A21: Dic2025 | B21: HQM (corporativos) | C21: =(1+INDEX(Dic2025!$C$6:$C$205,MATCH(1,Dic2025!$A$6:$A$205,0))/2)^2-1 -> 0.03876864 | D21: =(1+INDEX(Dic2025!$C$6:$C$205,MATCH(5,Dic2025!$A$6:$A$205,0))/2)^2-1 -> 0.042951562 | E21: =(1+INDEX(Dic2025!$C$6:$C$205,MATCH(10,Dic2025!$A$6:$A$205,0))/2)^2-1 -> 0.05021504 | F21: =(1+INDEX(Dic2025!$C$6:$C$205,MATCH(20,Dic2025!$A$6:$A$205,0))/2)^2-1 -> 0.05842944 | G21: =(1+INDEX(Dic2025!$C$6:$C$205,MATCH(30,Dic2025!$A$6:$A$205,0))/2)^2-1 -> 0.06131204 | H21: =(1+INDEX(Dic2025!$C$6:$C$205,MATCH(40,Dic2025!$A$6:$A$205,0))/2)^2-1 -> 0.062857903 | I21: =(1+INDEX(Dic2025!$C$6:$C$205,MATCH(60,Dic2025!$A$6:$A$205,0))/2)^2-1 -> 0.06440489 | J21: =(1+INDEX(Dic2025!$C$6:$C$205,MATCH(100,Dic2025!$A$6:$A$205,0))/2)^2-1 -> 0.06564329

Sheet Dic2023
A1: Curva de descuento al cierre de December 2023 — malla semestral
A2: TNC y HQM: datos del Tesoro (texto azul). Resto: fórmulas. Tasas como fracción, formato %.
A5: Plazo (años) | B5: TNC semestral | C5: HQM semestral | D5: Diferencial HQM − TNC (pb) | E5: Prima neta de crédito | F5: Alta: tasa semestral | G5: Alta: tasa anual efectiva | H5: Alta: factor de descuento | I5: Media: tasa semestral | J5: Media: tasa anual efectiva | K5: Media: factor de descuento | L5: Baja: tasa semestral | M5: Baja: tasa anual efectiva | N5: Baja: factor de descuento
A6: 0.5 | B6: 0.0517 | C6: 0.0529 | D6: =(C6-B6)*10000 -> 12 | E6: =MAX(0,C6-B6)*(1-Parametros!$B$5) -> 0.0012 | F6: =B6+E6*Parametros!$B$6 -> 0.0529 | G6: =(1+F6/2)^2-1 -> 0.053599603 | H6: =(1+G6)^(-A6) -> 0.97423157 | I6: =B6+E6*Parametros!$B$7 -> 0.0529 | J6: =(1+I6/2)^2-1 -> 0.053599603 | K6: =(1+J6)^(-A6) -> 0.97423157 | L6: =B6+E6*Parametros!$B$8 -> 0.0529 | M6: =(1+L6/2)^2-1 -> 0.053599603 | N6: =(1+M6)^(-A6) -> 0.97423157
A7: 1 | B7: 0.0478 | C7: 0.0512 | D7: =(C7-B7)*10000 -> 34 | E7: =MAX(0,C7-B7)*(1-Parametros!$B$5) -> 0.0034 | F7: =B7+E7*Parametros!$B$6 -> 0.0512 | G7: =(1+F7/2)^2-1 -> 0.05185536 | H7: =(1+G7)^(-A7) -> 0.95070105 | I7: =B7+E7*Parametros!$B$7 -> 0.0512 | J7: =(1+I7/2)^2-1 -> 0.05185536 | K7: =(1+J7)^(-A7) -> 0.95070105 | L7: =B7+E7*Parametros!$B$8 -> 0.0512 | M7: =(1+L7/2)^2-1 -> 0.05185536 | N7: =(1+M7)^(-A7) -> 0.95070105
A8: 1.5 | B8: 0.0446 | C8: 0.0497 | D8: =(C8-B8)*10000 -> 51 | E8: =MAX(0,C8-B8)*(1-Parametros!$B$5) -> 0.0051 | F8: =B8+E8*Parametros!$B$6 -> 0.0497 | G8: =(1+F8/2)^2-1 -> 0.050317523 | H8: =(1+G8)^(-A8) -> 0.92900721 | I8: =B8+E8*Parametros!$B$7 -> 0.0497 | J8: =(1+I8/2)^2-1 -> 0.050317523 | K8: =(1+J8)^(-A8) -> 0.92900721 | L8: =B8+E8*Parametros!$B$8 -> 0.0497 | M8: =(1+L8/2)^2-1 -> 0.050317523 | N8: =(1+M8)^(-A8) -> 0.92900721
A9: 2 | B9: 0.0421 | C9: 0.0484 | D9: =(C9-B9)*10000 -> 63 | E9: =MAX(0,C9-B9)*(1-Parametros!$B$5) -> 0.0063 | F9: =B9+E9*Parametros!$B$6 -> 0.0484 | G9: =(1+F9/2)^2-1 -> 0.04898564 | H9: =(1+G9)^(-A9) -> 0.90878451 | I9: =B9+E9*Parametros!$B$7 -> 0.0484 | J9: =(1+I9/2)^2-1 -> 0.04898564 | K9: =(1+J9)^(-A9) -> 0.90878451 | L9: =B9+E9*Parametros!$B$8 -> 0.0484 | M9: =(1+L9/2)^2-1 -> 0.04898564 | N9: =(1+M9)^(-A9) -> 0.90878451
A10: 2.5 | B10: 0.0406 | C10: 0.0474 | D10: =(C10-B10)*10000 -> 68 | E10: =MAX(0,C10-B10)*(1-Parametros!$B$5) -> 0.0068 | F10: =B10+E10*Parametros!$B$6 -> 0.0474 | G10: =(1+F10/2)^2-1 -> 0.04796169 | H10: =(1+G10)^(-A10) -> 0.88948061 | I10: =B10+E10*Parametros!$B$7 -> 0.0474 | J10: =(1+I10/2)^2-1 -> 0.04796169 | K10: =(1+J10)^(-A10) -> 0.88948061 | L10: =B10+E10*Parametros!$B$8 -> 0.0474 | M10: =(1+L10/2)^2-1 -> 0.04796169 | N10: =(1+M10)^(-A10) -> 0.88948061
A11: 3 | B11: 0.0397 | C11: 0.0467 | D11: =(C11-B11)*10000 -> 70 | E11: =MAX(0,C11-B11)*(1-Parametros!$B$5) -> 0.007 | F11: =B11+E11*Parametros!$B$6 -> 0.0467 | G11: =(1+F11/2)^2-1 -> 0.047245223 | H11: =(1+G11)^(-A11) -> 0.87067252 | I11: =B11+E11*Parametros!$B$7 -> 0.0467 | J11: =(1+I11/2)^2-1 -> 0.047245223 | K11: =(1+J11)^(-A11) -> 0.87067252 | L11: =B11+E11*Parametros!$B$8 -> 0.0467 | M11: =(1+L11/2)^2-1 -> 0.047245223 | N11: =(1+M11)^(-A11) -> 0.87067252
A12: 3.5 | B12: 0.0393 | C12: 0.0462 | D12: =(C12-B12)*10000 -> 69 | E12: =MAX(0,C12-B12)*(1-Parametros!$B$5) -> 0.0069 | F12: =B12+E12*Parametros!$B$6 -> 0.0462 | G12: =(1+F12/2)^2-1 -> 0.04673361 | H12: =(1+G12)^(-A12) -> 0.85226255 | I12: =B12+E12*Parametros!$B$7 -> 0.0462 | J12: =(1+I12/2)^2-1 -> 0.04673361 | K12: =(1+J12)^(-A12) -> 0.85226255 | L12: =B12+E12*Parametros!$B$8 -> 0.0462 | M12: =(1+L12/2)^2-1 -> 0.04673361 | N12: =(1+M12)^(-A12) -> 0.85226255
A13: 4 | B13: 0.0391 | C13: 0.0459 | D13: =(C13-B13)*10000 -> 68 | E13: =MAX(0,C13-B13)*(1-Parametros!$B$5) -> 0.0068 | F13: =B13+E13*Parametros!$B$6 -> 0.0459 | G13: =(1+F13/2)^2-1 -> 0.046426702 | H13: =(1+G13)^(-A13) -> 0.8339975 | I13: =B13+E13*Parametros!$B$7 -> 0.0459 | J13: =(1+I13/2)^2-1 -> 0.046426702 | K13: =(1+J13)^(-A13) -> 0.8339975 | L13: =B13+E13*Parametros!$B$8 -> 0.0459 | M13: =(1+L13/2)^2-1 -> 0.046426702 | N13: =(1+M13)^(-A13) -> 0.8339975
A14: 4.5 | B14: 0.0389 | C14: 0.0458 | D14: =(C14-B14)*10000 -> 69 | E14: =MAX(0,C14-B14)*(1-Parametros!$B$5) -> 0.0069 | F14: =B14+E14*Parametros!$B$6 -> 0.0458 | G14: =(1+F14/2)^2-1 -> 0.04632441 | H14: =(1+G14)^(-A14) -> 0.8156454 | I14: =B14+E14*Parametros!$B$7 -> 0.0458 | J14: =(1+I14/2)^2-1 -> 0.04632441 | K14: =(1+J14)^(-A14) -> 0.8156454 | L14: =B14+E14*Parametros!$B$8 -> 0.0458 | M14: =(1+L14/2)^2-1 -> 0.04632441 | N14: =(1+M14)^(-A14) -> 0.8156454
A15: 5 | B15: 0.0388 | C15: 0.0458 | D15: =(C15-B15)*10000 -> 70 | E15: =MAX(0,C15-B15)*(1-Parametros!$B$5) -> 0.007 | F15: =B15+E15*Parametros!$B$6 -> 0.0458 | G15: =(1+F15/2)^2-1 -> 0.04632441 | H15: =(1+G15)^(-A15) -> 0.79738528 | I15: =B15+E15*Parametros!$B$7 -> 0.0458 | J15: =(1+I15/2)^2-1 -> 0.04632441 | K15: =(1+J15)^(-A15) -> 0.79738528 | L15: =B15+E15*Parametros!$B$8 -> 0.0458 | M15: =(1+L15/2)^2-1 -> 0.04632441 | N15: =(1+M15)^(-A15) -> 0.79738528
A16: 5.5 | B16: 0.0387 | C16: 0.046 | D16: =(C16-B16)*10000 -> 73 | E16: =MAX(0,C16-B16)*(1-Parametros!$B$5) -> 0.0073 | F16: =B16+E16*Parametros!$B$6 -> 0.046 | G16: =(1+F16/2)^2-1 -> 0.046529 | H16: =(1+G16)^(-A16) -> 0.77869615 | I16: =B16+E16*Parametros!$B$7 -> 0.046 | J16: =(1+I16/2)^2-1 -> 0.046529 | K16: =(1+J16)^(-A16) -> 0.77869615 | L16: =B16+E16*Parametros!$B$8 -> 0.046 | M16: =(1+L16/2)^2-1 -> 0.046529 | N16: =(1+M16)^(-A16) -> 0.77869615
A17: 6 | B17: 0.0385 | C17: 0.0462 | D17: =(C17-B17)*10000 -> 77 | E17: =MAX(0,C17-B17)*(1-Parametros!$B$5) -> 0.0077 | F17: =B17+E17*Parametros!$B$6 -> 0.0462 | G17: =(1+F17/2)^2-1 -> 0.04673361 | H17: =(1+G17)^(-A17) -> 0.76029649 | I17: =B17+E17*Parametros!$B$7 -> 0.0462 | J17: =(1+I17/2)^2-1 -> 0.04673361 | K17: =(1+J17)^(-A17) -> 0.76029649 | L17: =B17+E17*Parametros!$B$8 -> 0.0462 | M17: =(1+L17/2)^2-1 -> 0.04673361 | N17: =(1+M17)^(-A17) -> 0.76029649
... A205: 100 | B205: 0.0436 | C205: 0.0511 | D205: =(C205-B205)*10000 -> 75 | E205: =MAX(0,C205-B205)*(1-Parametros!$B$5) -> 0.0075 | F205: =B205+E205*Parametros!$B$6 -> 0.0511 | G205: =(1+F205/2)^2-1 -> 0.051752803 | H205: =(1+G205)^(-A205) -> 0.0064362397 | I205: =B205+E205*Parametros!$B$7 -> 0.0511 | J205: =(1+I205/2)^2-1 -> 0.051752803 | K205: =(1+J205)^(-A205) -> 0.0064362397 | L205: =B205+E205*Parametros!$B$8 -> 0.0511 | M205: =(1+L205/2)^2-1 -> 0.051752803 | N205: =(1+M205)^(-A205) -> 0.0064362397

Sheet Dic2024
A1: Curva de descuento al cierre de December 2024 — malla semestral
A2: TNC y HQM: datos del Tesoro (texto azul). Resto: fórmulas. Tasas como fracción, formato %.
A5: Plazo (años) | B5: TNC semestral | C5: HQM semestral | D5: Diferencial HQM − TNC (pb) | E5: Prima neta de crédito | F5: Alta: tasa semestral | G5: Alta: tasa anual efectiva | H5: Alta: factor de descuento | I5: Media: tasa semestral | J5: Media: tasa anual efectiva | K5: Media: factor de descuento | L5: Baja: tasa semestral | M5: Baja: tasa anual efectiva | N5: Baja: factor de descuento
A6: 0.5 | B6: 0.0425 | C6: 0.0456 | D6: =(C6-B6)*10000 -> 31 | E6: =MAX(0,C6-B6)*(1-Parametros!$B$5) -> 0.0031 | F6: =B6+E6*Parametros!$B$6 -> 0.0456 | G6: =(1+F6/2)^2-1 -> 0.04611984 | H6: =(1+G6)^(-A6) -> 0.97770825 | I6: =B6+E6*Parametros!$B$7 -> 0.0456 | J6: =(1+I6/2)^2-1 -> 0.04611984 | K6: =(1+J6)^(-A6) -> 0.97770825 | L6: =B6+E6*Parametros!$B$8 -> 0.0456 | M6: =(1+L6/2)^2-1 -> 0.04611984 | N6: =(1+M6)^(-A6) -> 0.97770825
A7: 1 | B7: 0.0424 | C7: 0.0459 | D7: =(C7-B7)*10000 -> 35 | E7: =MAX(0,C7-B7)*(1-Parametros!$B$5) -> 0.0035 | F7: =B7+E7*Parametros!$B$6 -> 0.0459 | G7: =(1+F7/2)^2-1 -> 0.046426702 | H7: =(1+G7)^(-A7) -> 0.95563311 | I7: =B7+E7*Parametros!$B$7 -> 0.0459 | J7: =(1+I7/2)^2-1 -> 0.046426702 | K7: =(1+J7)^(-A7) -> 0.95563311 | L7: =B7+E7*Parametros!$B$8 -> 0.0459 | M7: =(1+L7/2)^2-1 -> 0.046426702 | N7: =(1+M7)^(-A7) -> 0.95563311
A8: 1.5 | B8: 0.0424 | C8: 0.0462 | D8: =(C8-B8)*10000 -> 38 | E8: =MAX(0,C8-B8)*(1-Parametros!$B$5) -> 0.0038 | F8: =B8+E8*Parametros!$B$6 -> 0.0462 | G8: =(1+F8/2)^2-1 -> 0.04673361 | H8: =(1+G8)^(-A8) -> 0.93378253 | I8: =B8+E8*Parametros!$B$7 -> 0.0462 | J8: =(1+I8/2)^2-1 -> 0.04673361 | K8: =(1+J8)^(-A8) -> 0.93378253 | L8: =B8+E8*Parametros!$B$8 -> 0.0462 | M8: =(1+L8/2)^2-1 -> 0.04673361 | N8: =(1+M8)^(-A8) -> 0.93378253
A9: 2 | B9: 0.0425 | C9: 0.0465 | D9: =(C9-B9)*10000 -> 40 | E9: =MAX(0,C9-B9)*(1-Parametros!$B$5) -> 0.004 | F9: =B9+E9*Parametros!$B$6 -> 0.0465 | G9: =(1+F9/2)^2-1 -> 0.047040562 | H9: =(1+G9)^(-A9) -> 0.91216412 | I9: =B9+E9*Parametros!$B$7 -> 0.0465 | J9: =(1+I9/2)^2-1 -> 0.047040562 | K9: =(1+J9)^(-A9) -> 0.91216412 | L9: =B9+E9*Parametros!$B$8 -> 0.0465 | M9: =(1+L9/2)^2-1 -> 0.047040562 | N9: =(1+M9)^(-A9) -> 0.91216412
A10: 2.5 | B10: 0.0427 | C10: 0.0469 | D10: =(C10-B10)*10000 -> 42 | E10: =MAX(0,C10-B10)*(1-Parametros!$B$5) -> 0.0042 | F10: =B10+E10*Parametros!$B$6 -> 0.0469 | G10: =(1+F10/2)^2-1 -> 0.047449902 | H10: =(1+G10)^(-A10) -> 0.89056751 | I10: =B10+E10*Parametros!$B$7 -> 0.0469 | J10: =(1+I10/2)^2-1 -> 0.047449902 | K10: =(1+J10)^(-A10) -> 0.89056751 | L10: =B10+E10*Parametros!$B$8 -> 0.0469 | M10: =(1+L10/2)^2-1 -> 0.047449902 | N10: =(1+M10)^(-A10) -> 0.89056751
A11: 3 | B11: 0.043 | C11: 0.0473 | D11: =(C11-B11)*10000 -> 43 | E11: =MAX(0,C11-B11)*(1-Parametros!$B$5) -> 0.0043 | F11: =B11+E11*Parametros!$B$6 -> 0.0473 | G11: =(1+F11/2)^2-1 -> 0.047859322 | H11: =(1+G11)^(-A11) -> 0.86914264 | I11: =B11+E11*Parametros!$B$7 -> 0.0473 | J11: =(1+I11/2)^2-1 -> 0.047859322 | K11: =(1+J11)^(-A11) -> 0.86914264 | L11: =B11+E11*Parametros!$B$8 -> 0.0473 | M11: =(1+L11/2)^2-1 -> 0.047859322 | N11: =(1+M11)^(-A11) -> 0.86914264
A12: 3.5 | B12: 0.0433 | C12: 0.0477 | D12: =(C12-B12)*10000 -> 44 | E12: =MAX(0,C12-B12)*(1-Parametros!$B$5) -> 0.0044 | F12: =B12+E12*Parametros!$B$6 -> 0.0477 | G12: =(1+F12/2)^2-1 -> 0.048268822 | H12: =(1+G12)^(-A12) -> 0.847902 | I12: =B12+E12*Parametros!$B$7 -> 0.0477 | J12: =(1+I12/2)^2-1 -> 0.048268822 | K12: =(1+J12)^(-A12) -> 0.847902 | L12: =B12+E12*Parametros!$B$8 -> 0.0477 | M12: =(1+L12/2)^2-1 -> 0.048268822 | N12: =(1+M12)^(-A12) -> 0.847902
A13: 4 | B13: 0.0436 | C13: 0.0481 | D13: =(C13-B13)*10000 -> 45 | E13: =MAX(0,C13-B13)*(1-Parametros!$B$5) -> 0.0045 | F13: =B13+E13*Parametros!$B$6 -> 0.0481 | G13: =(1+F13/2)^2-1 -> 0.048678402 | H13: =(1+G13)^(-A13) -> 0.82685757 | I13: =B13+E13*Parametros!$B$7 -> 0.0481 | J13: =(1+I13/2)^2-1 -> 0.048678402 | K13: =(1+J13)^(-A13) -> 0.82685757 | L13: =B13+E13*Parametros!$B$8 -> 0.0481 | M13: =(1+L13/2)^2-1 -> 0.048678402 | N13: =(1+M13)^(-A13) -> 0.82685757
A14: 4.5 | B14: 0.0439 | C14: 0.0485 | D14: =(C14-B14)*10000 -> 46 | E14: =MAX(0,C14-B14)*(1-Parametros!$B$5) -> 0.0046 | F14: =B14+E14*Parametros!$B$6 -> 0.0485 | G14: =(1+F14/2)^2-1 -> 0.049088063 | H14: =(1+G14)^(-A14) -> 0.80602079 | I14: =B14+E14*Parametros!$B$7 -> 0.0485 | J14: =(1+I14/2)^2-1 -> 0.049088063 | K14: =(1+J14)^(-A14) -> 0.80602079 | L14: =B14+E14*Parametros!$B$8 -> 0.0485 | M14: =(1+L14/2)^2-1 -> 0.049088063 | N14: =(1+M14)^(-A14) -> 0.80602079
A15: 5 | B15: 0.0442 | C15: 0.049 | D15: =(C15-B15)*10000 -> 48 | E15: =MAX(0,C15-B15)*(1-Parametros!$B$5) -> 0.0048 | F15: =B15+E15*Parametros!$B$6 -> 0.049 | G15: =(1+F15/2)^2-1 -> 0.04960025 | H15: =(1+G15)^(-A15) -> 0.78501937 | I15: =B15+E15*Parametros!$B$7 -> 0.049 | J15: =(1+I15/2)^2-1 -> 0.04960025 | K15: =(1+J15)^(-A15) -> 0.78501937 | L15: =B15+E15*Parametros!$B$8 -> 0.049 | M15: =(1+L15/2)^2-1 -> 0.04960025 | N15: =(1+M15)^(-A15) -> 0.78501937
A16: 5.5 | B16: 0.0444 | C16: 0.0495 | D16: =(C16-B16)*10000 -> 51 | E16: =MAX(0,C16-B16)*(1-Parametros!$B$5) -> 0.0051 | F16: =B16+E16*Parametros!$B$6 -> 0.0495 | G16: =(1+F16/2)^2-1 -> 0.050112563 | H16: =(1+G16)^(-A16) -> 0.76419256 | I16: =B16+E16*Parametros!$B$7 -> 0.0495 | J16: =(1+I16/2)^2-1 -> 0.050112563 | K16: =(1+J16)^(-A16) -> 0.76419256 | L16: =B16+E16*Parametros!$B$8 -> 0.0495 | M16: =(1+L16/2)^2-1 -> 0.050112563 | N16: =(1+M16)^(-A16) -> 0.76419256
A17: 6 | B17: 0.0447 | C17: 0.05 | D17: =(C17-B17)*10000 -> 53 | E17: =MAX(0,C17-B17)*(1-Parametros!$B$5) -> 0.0053 | F17: =B17+E17*Parametros!$B$6 -> 0.05 | G17: =(1+F17/2)^2-1 -> 0.050625 | H17: =(1+G17)^(-A17) -> 0.74355589 | I17: =B17+E17*Parametros!$B$7 -> 0.05 | J17: =(1+I17/2)^2-1 -> 0.050625 | K17: =(1+J17)^(-A17) -> 0.74355589 | L17: =B17+E17*Parametros!$B$8 -> 0.05 | M17: =(1+L17/2)^2-1 -> 0.050625 | N17: =(1+M17)^(-A17) -> 0.74355589
... A205: 100 | B205: 0.0507 | C205: 0.0595 | D205: =(C205-B205)*10000 -> 88 | E205: =MAX(0,C205-B205)*(1-Parametros!$B$5) -> 0.0088 | F205: =B205+E205*Parametros!$B$6 -> 0.0595 | G205: =(1+F205/2)^2-1 -> 0.060385063 | H205: =(1+G205)^(-A205) -> 0.0028421034 | I205: =B205+E205*Parametros!$B$7 -> 0.0595 | J205: =(1+I205/2)^2-1 -> 0.060385063 | K205: =(1+J205)^(-A205) -> 0.0028421034 | L205: =B205+E205*Parametros!$B$8 -> 0.0595 | M205: =(1+L205/2)^2-1 -> 0.060385063 | N205: =(1+M205)^(-A205) -> 0.0028421034

Sheet Dic2025
A1: Curva de descuento al cierre de December 2025 — malla semestral
A2: TNC y HQM: datos del Tesoro (texto azul). Resto: fórmulas. Tasas como fracción, formato %.
A5: Plazo (años) | B5: TNC semestral | C5: HQM semestral | D5: Diferencial HQM − TNC (pb) | E5: Prima neta de crédito | F5: Alta: tasa semestral | G5: Alta: tasa anual efectiva | H5: Alta: factor de descuento | I5: Media: tasa semestral | J5: Media: tasa anual efectiva | K5: Media: factor de descuento | L5: Baja: tasa semestral | M5: Baja: tasa anual efectiva | N5: Baja: factor de descuento
A6: 0.5 | B6: 0.0356 | C6: 0.038 | D6: =(C6-B6)*10000 -> 24 | E6: =MAX(0,C6-B6)*(1-Parametros!$B$5) -> 0.0024 | F6: =B6+E6*Parametros!$B$6 -> 0.038 | G6: =(1+F6/2)^2-1 -> 0.038361 | H6: =(1+G6)^(-A6) -> 0.98135427 | I6: =B6+E6*Parametros!$B$7 -> 0.038 | J6: =(1+I6/2)^2-1 -> 0.038361 | K6: =(1+J6)^(-A6) -> 0.98135427 | L6: =B6+E6*Parametros!$B$8 -> 0.038 | M6: =(1+L6/2)^2-1 -> 0.038361 | N6: =(1+M6)^(-A6) -> 0.98135427
A7: 1 | B7: 0.0352 | C7: 0.0384 | D7: =(C7-B7)*10000 -> 32 | E7: =MAX(0,C7-B7)*(1-Parametros!$B$5) -> 0.0032 | F7: =B7+E7*Parametros!$B$6 -> 0.0384 | G7: =(1+F7/2)^2-1 -> 0.03876864 | H7: =(1+G7)^(-A7) -> 0.96267827 | I7: =B7+E7*Parametros!$B$7 -> 0.0384 | J7: =(1+I7/2)^2-1 -> 0.03876864 | K7: =(1+J7)^(-A7) -> 0.96267827 | L7: =B7+E7*Parametros!$B$8 -> 0.0384 | M7: =(1+L7/2)^2-1 -> 0.03876864 | N7: =(1+M7)^(-A7) -> 0.96267827
A8: 1.5 | B8: 0.0349 | C8: 0.0387 | D8: =(C8-B8)*10000 -> 38 | E8: =MAX(0,C8-B8)*(1-Parametros!$B$5) -> 0.0038 | F8: =B8+E8*Parametros!$B$6 -> 0.0387 | G8: =(1+F8/2)^2-1 -> 0.039074422 | H8: =(1+G8)^(-A8) -> 0.94412613 | I8: =B8+E8*Parametros!$B$7 -> 0.0387 | J8: =(1+I8/2)^2-1 -> 0.039074422 | K8: =(1+J8)^(-A8) -> 0.94412613 | L8: =B8+E8*Parametros!$B$8 -> 0.0387 | M8: =(1+L8/2)^2-1 -> 0.039074422 | N8: =(1+M8)^(-A8) -> 0.94412613
A9: 2 | B9: 0.0349 | C9: 0.0391 | D9: =(C9-B9)*10000 -> 42 | E9: =MAX(0,C9-B9)*(1-Parametros!$B$5) -> 0.0042 | F9: =B9+E9*Parametros!$B$6 -> 0.0391 | G9: =(1+F9/2)^2-1 -> 0.039482202 | H9: =(1+G9)^(-A9) -> 0.92547754 | I9: =B9+E9*Parametros!$B$7 -> 0.0391 | J9: =(1+I9/2)^2-1 -> 0.039482202 | K9: =(1+J9)^(-A9) -> 0.92547754 | L9: =B9+E9*Parametros!$B$8 -> 0.0391 | M9: =(1+L9/2)^2-1 -> 0.039482202 | N9: =(1+M9)^(-A9) -> 0.92547754
A10: 2.5 | B10: 0.035 | C10: 0.0396 | D10: =(C10-B10)*10000 -> 46 | E10: =MAX(0,C10-B10)*(1-Parametros!$B$5) -> 0.0046 | F10: =B10+E10*Parametros!$B$6 -> 0.0396 | G10: =(1+F10/2)^2-1 -> 0.03999204 | H10: =(1+G10)^(-A10) -> 0.9066193 | I10: =B10+E10*Parametros!$B$7 -> 0.0396 | J10: =(1+I10/2)^2-1 -> 0.03999204 | K10: =(1+J10)^(-A10) -> 0.9066193 | L10: =B10+E10*Parametros!$B$8 -> 0.0396 | M10: =(1+L10/2)^2-1 -> 0.03999204 | N10: =(1+M10)^(-A10) -> 0.9066193
A11: 3 | B11: 0.0354 | C11: 0.0401 | D11: =(C11-B11)*10000 -> 47 | E11: =MAX(0,C11-B11)*(1-Parametros!$B$5) -> 0.0047 | F11: =B11+E11*Parametros!$B$6 -> 0.0401 | G11: =(1+F11/2)^2-1 -> 0.040502002 | H11: =(1+G11)^(-A11) -> 0.88771026 | I11: =B11+E11*Parametros!$B$7 -> 0.0401 | J11: =(1+I11/2)^2-1 -> 0.040502002 | K11: =(1+J11)^(-A11) -> 0.88771026 | L11: =B11+E11*Parametros!$B$8 -> 0.0401 | M11: =(1+L11/2)^2-1 -> 0.040502002 | N11: =(1+M11)^(-A11) -> 0.88771026
A12: 3.5 | B12: 0.0358 | C12: 0.0406 | D12: =(C12-B12)*10000 -> 48 | E12: =MAX(0,C12-B12)*(1-Parametros!$B$5) -> 0.0048 | F12: =B12+E12*Parametros!$B$6 -> 0.0406 | G12: =(1+F12/2)^2-1 -> 0.04101209 | H12: =(1+G12)^(-A12) -> 0.86876996 | I12: =B12+E12*Parametros!$B$7 -> 0.0406 | J12: =(1+I12/2)^2-1 -> 0.04101209 | K12: =(1+J12)^(-A12) -> 0.86876996 | L12: =B12+E12*Parametros!$B$8 -> 0.0406 | M12: =(1+L12/2)^2-1 -> 0.04101209 | N12: =(1+M12)^(-A12) -> 0.86876996
A13: 4 | B13: 0.0363 | C13: 0.0412 | D13: =(C13-B13)*10000 -> 49 | E13: =MAX(0,C13-B13)*(1-Parametros!$B$5) -> 0.0049 | F13: =B13+E13*Parametros!$B$6 -> 0.0412 | G13: =(1+F13/2)^2-1 -> 0.04162436 | H13: =(1+G13)^(-A13) -> 0.84948456 | I13: =B13+E13*Parametros!$B$7 -> 0.0412 | J13: =(1+I13/2)^2-1 -> 0.04162436 | K13: =(1+J13)^(-A13) -> 0.84948456 | L13: =B13+E13*Parametros!$B$8 -> 0.0412 | M13: =(1+L13/2)^2-1 -> 0.04162436 | N13: =(1+M13)^(-A13) -> 0.84948456
A14: 4.5 | B14: 0.0368 | C14: 0.0419 | D14: =(C14-B14)*10000 -> 51 | E14: =MAX(0,C14-B14)*(1-Parametros!$B$5) -> 0.0051 | F14: =B14+E14*Parametros!$B$6 -> 0.0419 | G14: =(1+F14/2)^2-1 -> 0.042338903 | H14: =(1+G14)^(-A14) -> 0.82977384 | I14: =B14+E14*Parametros!$B$7 -> 0.0419 | J14: =(1+I14/2)^2-1 -> 0.042338903 | K14: =(1+J14)^(-A14) -> 0.82977384 | L14: =B14+E14*Parametros!$B$8 -> 0.0419 | M14: =(1+L14/2)^2-1 -> 0.042338903 | N14: =(1+M14)^(-A14) -> 0.82977384
A15: 5 | B15: 0.0374 | C15: 0.0425 | D15: =(C15-B15)*10000 -> 51 | E15: =MAX(0,C15-B15)*(1-Parametros!$B$5) -> 0.0051 | F15: =B15+E15*Parametros!$B$6 -> 0.0425 | G15: =(1+F15/2)^2-1 -> 0.042951562 | H15: =(1+G15)^(-A15) -> 0.81036244 | I15: =B15+E15*Parametros!$B$7 -> 0.0425 | J15: =(1+I15/2)^2-1 -> 0.042951562 | K15: =(1+J15)^(-A15) -> 0.81036244 | L15: =B15+E15*Parametros!$B$8 -> 0.0425 | M15: =(1+L15/2)^2-1 -> 0.042951562 | N15: =(1+M15)^(-A15) -> 0.81036244
A16: 5.5 | B16: 0.0379 | C16: 0.0432 | D16: =(C16-B16)*10000 -> 53 | E16: =MAX(0,C16-B16)*(1-Parametros!$B$5) -> 0.0053 | F16: =B16+E16*Parametros!$B$6 -> 0.0432 | G16: =(1+F16/2)^2-1 -> 0.04366656 | H16: =(1+G16)^(-A16) -> 0.79051529 | I16: =B16+E16*Parametros!$B$7 -> 0.0432 | J16: =(1+I16/2)^2-1 -> 0.04366656 | K16: =(1+J16)^(-A16) -> 0.79051529 | L16: =B16+E16*Parametros!$B$8 -> 0.0432 | M16: =(1+L16/2)^2-1 -> 0.04366656 | N16: =(1+M16)^(-A16) -> 0.79051529
A17: 6 | B17: 0.0384 | C17: 0.044 | D17: =(C17-B17)*10000 -> 56 | E17: =MAX(0,C17-B17)*(1-Parametros!$B$5) -> 0.0056 | F17: =B17+E17*Parametros!$B$6 -> 0.044 | G17: =(1+F17/2)^2-1 -> 0.044484 | H17: =(1+G17)^(-A17) -> 0.7701747 | I17: =B17+E17*Parametros!$B$7 -> 0.044 | J17: =(1+I17/2)^2-1 -> 0.044484 | K17: =(1+J17)^(-A17) -> 0.7701747 | L17: =B17+E17*Parametros!$B$8 -> 0.044 | M17: =(1+L17/2)^2-1 -> 0.044484 | N17: =(1+M17)^(-A17) -> 0.7701747
... A205: 100 | B205: 0.0546 | C205: 0.0646 | D205: =(C205-B205)*10000 -> 100 | E205: =MAX(0,C205-B205)*(1-Parametros!$B$5) -> 0.01 | F205: =B205+E205*Parametros!$B$6 -> 0.0646 | G205: =(1+F205/2)^2-1 -> 0.06564329 | H205: =(1+G205)^(-A205) -> 0.0017330637 | I205: =B205+E205*Parametros!$B$7 -> 0.0646 | J205: =(1+I205/2)^2-1 -> 0.06564329 | K205: =(1+J205)^(-A205) -> 0.0017330637 | L205: =B205+E205*Parametros!$B$8 -> 0.0646 | M205: =(1+L205/2)^2-1 -> 0.06564329 | N205: =(1+M205)^(-A205) -> 0.0017330637

Sheet Mensual_Dic2023
A1: Curva mensual interpolada — Dic2023
A2: Interpolación lineal del ln(factor de descuento) entre puntos semestrales de la hoja Dic2023; por debajo de 0,5 años se mantiene la tasa de 0,5 años.
A4: Mes | B4: Plazo (años) | C4: Semestres completos k | D4: Alta: factor de descuento | E4: Alta: tasa anual efectiva | F4: Alta: tasa mensual | G4: Media: factor de descuento | H4: Media: tasa anual efectiva | I4: Media: tasa mensual | J4: Baja: factor de descuento | K4: Baja: tasa anual efectiva | L4: Baja: tasa mensual
A5: 1 | B5: =A5/12 -> 0.083333333 | C5: =INT(A5/6) -> 0 | D5: =IF(C5=0,(1+Dic2023!$G$6)^(-B5),EXP(LN(INDEX(Dic2023!$H$6:$H$205,C5))+(LN(INDEX(Dic2023!$H$6:$H$205,MIN(C5+1,200)))-LN(INDEX(Dic2023!$H$6:$H$205,C5)))*(A5-6*C5)/6)) -> 0.99565841 | E5: =D5^(-1/B5)-1 -> 0.053599603 | F5: =(1+E5)^(1/12)-1 -> 0.0043605207 | G5: =IF(C5=0,(1+Dic2023!$J$6)^(-B5),EXP(LN(INDEX(Dic2023!$K$6:$K$205,C5))+(LN(INDEX(Dic2023!$K$6:$K$205,MIN(C5+1,200)))-LN(INDEX(Dic2023!$K$6:$K$205,C5)))*(A5-6*C5)/6)) -> 0.99565841 | H5: =G5^(-1/B5)-1 -> 0.053599603 | I5: =(1+H5)^(1/12)-1 -> 0.0043605207 | J5: =IF(C5=0,(1+Dic2023!$M$6)^(-B5),EXP(LN(INDEX(Dic2023!$N$6:$N$205,C5))+(LN(INDEX(Dic2023!$N$6:$N$205,MIN(C5+1,200)))-LN(INDEX(Dic2023!$N$6:$N$205,C5)))*(A5-6*C5)/6)) -> 0.99565841 | K5: =J5^(-1/B5)-1 -> 0.053599603 | L5: =(1+K5)^(1/12)-1 -> 0.0043605207
A6: 2 | B6: =A6/12 -> 0.16666667 | C6: =INT(A6/6) -> 0 | D6: =IF(C6=0,(1+Dic2023!$G$6)^(-B6),EXP(LN(INDEX(Dic2023!$H$6:$H$205,C6))+(LN(INDEX(Dic2023!$H$6:$H$205,MIN(C6+1,200)))-LN(INDEX(Dic2023!$H$6:$H$205,C6)))*(A6-6*C6)/6)) -> 0.99133567 | E6: =D6^(-1/B6)-1 -> 0.053599603 | F6: =(1+E6)^(1/12)-1 -> 0.0043605207 | G6: =IF(C6=0,(1+Dic2023!$J$6)^(-B6),EXP(LN(INDEX(Dic2023!$K$6:$K$205,C6))+(LN(INDEX(Dic2023!$K$6:$K$205,MIN(C6+1,200)))-LN(INDEX(Dic2023!$K$6:$K$205,C6)))*(A6-6*C6)/6)) -> 0.99133567 | H6: =G6^(-1/B6)-1 -> 0.053599603 | I6: =(1+H6)^(1/12)-1 -> 0.0043605207 | J6: =IF(C6=0,(1+Dic2023!$M$6)^(-B6),EXP(LN(INDEX(Dic2023!$N$6:$N$205,C6))+(LN(INDEX(Dic2023!$N$6:$N$205,MIN(C6+1,200)))-LN(INDEX(Dic2023!$N$6:$N$205,C6)))*(A6-6*C6)/6)) -> 0.99133567 | K6: =J6^(-1/B6)-1 -> 0.053599603 | L6: =(1+K6)^(1/12)-1 -> 0.0043605207
A7: 3 | B7: =A7/12 -> 0.25 | C7: =INT(A7/6) -> 0 | D7: =IF(C7=0,(1+Dic2023!$G$6)^(-B7),EXP(LN(INDEX(Dic2023!$H$6:$H$205,C7))+(LN(INDEX(Dic2023!$H$6:$H$205,MIN(C7+1,200)))-LN(INDEX(Dic2023!$H$6:$H$205,C7)))*(A7-6*C7)/6)) -> 0.9870317 | E7: =D7^(-1/B7)-1 -> 0.053599602 | F7: =(1+E7)^(1/12)-1 -> 0.0043605207 | G7: =IF(C7=0,(1+Dic2023!$J$6)^(-B7),EXP(LN(INDEX(Dic2023!$K$6:$K$205,C7))+(LN(INDEX(Dic2023!$K$6:$K$205,MIN(C7+1,200)))-LN(INDEX(Dic2023!$K$6:$K$205,C7)))*(A7-6*C7)/6)) -> 0.9870317 | H7: =G7^(-1/B7)-1 -> 0.053599602 | I7: =(1+H7)^(1/12)-1 -> 0.0043605207 | J7: =IF(C7=0,(1+Dic2023!$M$6)^(-B7),EXP(LN(INDEX(Dic2023!$N$6:$N$205,C7))+(LN(INDEX(Dic2023!$N$6:$N$205,MIN(C7+1,200)))-LN(INDEX(Dic2023!$N$6:$N$205,C7)))*(A7-6*C7)/6)) -> 0.9870317 | K7: =J7^(-1/B7)-1 -> 0.053599602 | L7: =(1+K7)^(1/12)-1 -> 0.0043605207
A8: 4 | B8: =A8/12 -> 0.33333333 | C8: =INT(A8/6) -> 0 | D8: =IF(C8=0,(1+Dic2023!$G$6)^(-B8),EXP(LN(INDEX(Dic2023!$H$6:$H$205,C8))+(LN(INDEX(Dic2023!$H$6:$H$205,MIN(C8+1,200)))-LN(INDEX(Dic2023!$H$6:$H$205,C8)))*(A8-6*C8)/6)) -> 0.98274641 | E8: =D8^(-1/B8)-1 -> 0.053599603 | F8: =(1+E8)^(1/12)-1 -> 0.0043605207 | G8: =IF(C8=0,(1+Dic2023!$J$6)^(-B8),EXP(LN(INDEX(Dic2023!$K$6:$K$205,C8))+(LN(INDEX(Dic2023!$K$6:$K$205,MIN(C8+1,200)))-LN(INDEX(Dic2023!$K$6:$K$205,C8)))*(A8-6*C8)/6)) -> 0.98274641 | H8: =G8^(-1/B8)-1 -> 0.053599603 | I8: =(1+H8)^(1/12)-1 -> 0.0043605207 | J8: =IF(C8=0,(1+Dic2023!$M$6)^(-B8),EXP(LN(INDEX(Dic2023!$N$6:$N$205,C8))+(LN(INDEX(Dic2023!$N$6:$N$205,MIN(C8+1,200)))-LN(INDEX(Dic2023!$N$6:$N$205,C8)))*(A8-6*C8)/6)) -> 0.98274641 | K8: =J8^(-1/B8)-1 -> 0.053599603 | L8: =(1+K8)^(1/12)-1 -> 0.0043605207
A9: 5 | B9: =A9/12 -> 0.41666667 | C9: =INT(A9/6) -> 0 | D9: =IF(C9=0,(1+Dic2023!$G$6)^(-B9),EXP(LN(INDEX(Dic2023!$H$6:$H$205,C9))+(LN(INDEX(Dic2023!$H$6:$H$205,MIN(C9+1,200)))-LN(INDEX(Dic2023!$H$6:$H$205,C9)))*(A9-6*C9)/6)) -> 0.97847973 | E9: =D9^(-1/B9)-1 -> 0.053599603 | F9: =(1+E9)^(1/12)-1 -> 0.0043605207 | G9: =IF(C9=0,(1+Dic2023!$J$6)^(-B9),EXP(LN(INDEX(Dic2023!$K$6:$K$205,C9))+(LN(INDEX(Dic2023!$K$6:$K$205,MIN(C9+1,200)))-LN(INDEX(Dic2023!$K$6:$K$205,C9)))*(A9-6*C9)/6)) -> 0.97847973 | H9: =G9^(-1/B9)-1 -> 0.053599603 | I9: =(1+H9)^(1/12)-1 -> 0.0043605207 | J9: =IF(C9=0,(1+Dic2023!$M$6)^(-B9),EXP(LN(INDEX(Dic2023!$N$6:$N$205,C9))+(LN(INDEX(Dic2023!$N$6:$N$205,MIN(C9+1,200)))-LN(INDEX(Dic2023!$N$6:$N$205,C9)))*(A9-6*C9)/6)) -> 0.97847973 | K9: =J9^(-1/B9)-1 -> 0.053599603 | L9: =(1+K9)^(1/12)-1 -> 0.0043605207
A10: 6 | B10: =A10/12 -> 0.5 | C10: =INT(A10/6) -> 1 | D10: =IF(C10=0,(1+Dic2023!$G$6)^(-B10),EXP(LN(INDEX(Dic2023!$H$6:$H$205,C10))+(LN(INDEX(Dic2023!$H$6:$H$205,MIN(C10+1,200)))-LN(INDEX(Dic2023!$H$6:$H$205,C10)))*(A10-6*C10)/6)) -> 0.97423157 | E10: =D10^(-1/B10)-1 -> 0.053599603 | F10: =(1+E10)^(1/12)-1 -> 0.0043605207 | G10: =IF(C10=0,(1+Dic2023!$J$6)^(-B10),EXP(LN(INDEX(Dic2023!$K$6:$K$205,C10))+(LN(INDEX(Dic2023!$K$6:$K$205,MIN(C10+1,200)))-LN(INDEX(Dic2023!$K$6:$K$205,C10)))*(A10-6*C10)/6)) -> 0.97423157 | H10: =G10^(-1/B10)-1 -> 0.053599603 | I10: =(1+H10)^(1/12)-1 -> 0.0043605207 | J10: =IF(C10=0,(1+Dic2023!$M$6)^(-B10),EXP(LN(INDEX(Dic2023!$N$6:$N$205,C10))+(LN(INDEX(Dic2023!$N$6:$N$205,MIN(C10+1,200)))-LN(INDEX(Dic2023!$N$6:$N$205,C10)))*(A10-6*C10)/6)) -> 0.97423157 | K10: =J10^(-1/B10)-1 -> 0.053599603 | L10: =(1+K10)^(1/12)-1 -> 0.0043605207
A11: 7 | B11: =A11/12 -> 0.58333333 | C11: =INT(A11/6) -> 1 | D11: =IF(C11=0,(1+Dic2023!$G$6)^(-B11),EXP(LN(INDEX(Dic2023!$H$6:$H$205,C11))+(LN(INDEX(Dic2023!$H$6:$H$205,MIN(C11+1,200)))-LN(INDEX(Dic2023!$H$6:$H$205,C11)))*(A11-6*C11)/6)) -> 0.97026976 | E11: =D11^(-1/B11)-1 -> 0.053100953 | F11: =(1+E11)^(1/12)-1 -> 0.0043208999 | G11: =IF(C11=0,(1+Dic2023!$J$6)^(-B11),EXP(LN(INDEX(Dic2023!$K$6:$K$205,C11))+(LN(INDEX(Dic2023!$K$6:$K$205,MIN(C11+1,200)))-LN(INDEX(Dic2023!$K$6:$K$205,C11)))*(A11-6*C11)/6)) -> 0.97026976 | H11: =G11^(-1/B11)-1 -> 0.053100953 | I11: =(1+H11)^(1/12)-1 -> 0.0043208999 | J11: =IF(C11=0,(1+Dic2023!$M$6)^(-B11),EXP(LN(INDEX(Dic2023!$N$6:$N$205,C11))+(LN(INDEX(Dic2023!$N$6:$N$205,MIN(C11+1,200)))-LN(INDEX(Dic2023!$N$6:$N$205,C11)))*(A11-6*C11)/6)) -> 0.97026976 | K11: =J11^(-1/B11)-1 -> 0.053100953 | L11: =(1+K11)^(1/12)-1 -> 0.0043208999
A12: 8 | B12: =A12/12 -> 0.66666667 | C12: =INT(A12/6) -> 1 | D12: =IF(C12=0,(1+Dic2023!$G$6)^(-B12),EXP(LN(INDEX(Dic2023!$H$6:$H$205,C12))+(LN(INDEX(Dic2023!$H$6:$H$205,MIN(C12+1,200)))-LN(INDEX(Dic2023!$H$6:$H$205,C12)))*(A12-6*C12)/6)) -> 0.96632406 | E12: =D12^(-1/B12)-1 -> 0.05272712 | F12: =(1+E12)^(1/12)-1 -> 0.0042911854 | G12: =IF(C12=0,(1+Dic2023!$J$6)^(-B12),EXP(LN(INDEX(Dic2023!$K$6:$K$205,C12))+(LN(INDEX(Dic2023!$K$6:$K$205,MIN(C12+1,200)))-LN(INDEX(Dic2023!$K$6:$K$205,C12)))*(A12-6*C12)/6)) -> 0.96632406 | H12: =G12^(-1/B12)-1 -> 0.05272712 | I12: =(1+H12)^(1/12)-1 -> 0.0042911854 | J12: =IF(C12=0,(1+Dic2023!$M$6)^(-B12),EXP(LN(INDEX(Dic2023!$N$6:$N$205,C12))+(LN(INDEX(Dic2023!$N$6:$N$205,MIN(C12+1,200)))-LN(INDEX(Dic2023!$N$6:$N$205,C12)))*(A12-6*C12)/6)) -> 0.96632406 | K12: =J12^(-1/B12)-1 -> 0.05272712 | L12: =(1+K12)^(1/12)-1 -> 0.0042911854
A13: 9 | B13: =A13/12 -> 0.75 | C13: =INT(A13/6) -> 1 | D13: =IF(C13=0,(1+Dic2023!$G$6)^(-B13),EXP(LN(INDEX(Dic2023!$H$6:$H$205,C13))+(LN(INDEX(Dic2023!$H$6:$H$205,MIN(C13+1,200)))-LN(INDEX(Dic2023!$H$6:$H$205,C13)))*(A13-6*C13)/6)) -> 0.9623944 | E13: =D13^(-1/B13)-1 -> 0.052436453 | F13: =(1+E13)^(1/12)-1 -> 0.0042680747 | G13: =IF(C13=0,(1+Dic2023!$J$6)^(-B13),EXP(LN(INDEX(Dic2023!$K$6:$K$205,C13))+(LN(INDEX(Dic2023!$K$6:$K$205,MIN(C13+1,200)))-LN(INDEX(Dic2023!$K$6:$K$205,C13)))*(A13-6*C13)/6)) -> 0.9623944 | H13: =G13^(-1/B13)-1 -> 0.052436453 | I13: =(1+H13)^(1/12)-1 -> 0.0042680747 | J13: =IF(C13=0,(1+Dic2023!$M$6)^(-B13),EXP(LN(INDEX(Dic2023!$N$6:$N$205,C13))+(LN(INDEX(Dic2023!$N$6:$N$205,MIN(C13+1,200)))-LN(INDEX(Dic2023!$N$6:$N$205,C13)))*(A13-6*C13)/6)) -> 0.9623944 | K13: =J13^(-1/B13)-1 -> 0.052436453 | L13: =(1+K13)^(1/12)-1 -> 0.0042680747
A14: 10 | B14: =A14/12 -> 0.83333333 | C14: =INT(A14/6) -> 1 | D14: =IF(C14=0,(1+Dic2023!$G$6)^(-B14),EXP(LN(INDEX(Dic2023!$H$6:$H$205,C14))+(LN(INDEX(Dic2023!$H$6:$H$205,MIN(C14+1,200)))-LN(INDEX(Dic2023!$H$6:$H$205,C14)))*(A14-6*C14)/6)) -> 0.95848073 | E14: =D14^(-1/B14)-1 -> 0.052203977 | F14: =(1+E14)^(1/12)-1 -> 0.0042495865 | G14: =IF(C14=0,(1+Dic2023!$J$6)^(-B14),EXP(LN(INDEX(Dic2023!$K$6:$K$205,C14))+(LN(INDEX(Dic2023!$K$6:$K$205,MIN(C14+1,200)))-LN(INDEX(Dic2023!$K$6:$K$205,C14)))*(A14-6*C14)/6)) -> 0.95848073 | H14: =G14^(-1/B14)-1 -> 0.052203977 | I14: =(1+H14)^(1/12)-1 -> 0.0042495865 | J14: =IF(C14=0,(1+Dic2023!$M$6)^(-B14),EXP(LN(INDEX(Dic2023!$N$6:$N$205,C14))+(LN(INDEX(Dic2023!$N$6:$N$205,MIN(C14+1,200)))-LN(INDEX(Dic2023!$N$6:$N$205,C14)))*(A14-6*C14)/6)) -> 0.95848073 | K14: =J14^(-1/B14)-1 -> 0.052203977 | L14: =(1+K14)^(1/12)-1 -> 0.0042495865
A15: 11 | B15: =A15/12 -> 0.91666667 | C15: =INT(A15/6) -> 1 | D15: =IF(C15=0,(1+Dic2023!$G$6)^(-B15),EXP(LN(INDEX(Dic2023!$H$6:$H$205,C15))+(LN(INDEX(Dic2023!$H$6:$H$205,MIN(C15+1,200)))-LN(INDEX(Dic2023!$H$6:$H$205,C15)))*(A15-6*C15)/6)) -> 0.95458296 | E15: =D15^(-1/B15)-1 -> 0.052013808 | F15: =(1+E15)^(1/12)-1 -> 0.0042344601 | G15: =IF(C15=0,(1+Dic2023!$J$6)^(-B15),EXP(LN(INDEX(Dic2023!$K$6:$K$205,C15))+(LN(INDEX(Dic2023!$K$6:$K$205,MIN(C15+1,200)))-LN(INDEX(Dic2023!$K$6:$K$205,C15)))*(A15-6*C15)/6)) -> 0.95458296 | H15: =G15^(-1/B15)-1 -> 0.052013808 | I15: =(1+H15)^(1/12)-1 -> 0.0042344601 | J15: =IF(C15=0,(1+Dic2023!$M$6)^(-B15),EXP(LN(INDEX(Dic2023!$N$6:$N$205,C15))+(LN(INDEX(Dic2023!$N$6:$N$205,MIN(C15+1,200)))-LN(INDEX(Dic2023!$N$6:$N$205,C15)))*(A15-6*C15)/6)) -> 0.95458296 | K15: =J15^(-1/B15)-1 -> 0.052013808 | L15: =(1+K15)^(1/12)-1 -> 0.0042344601
A16: 12 | B16: =A16/12 -> 1 | C16: =INT(A16/6) -> 2 | D16: =IF(C16=0,(1+Dic2023!$G$6)^(-B16),EXP(LN(INDEX(Dic2023!$H$6:$H$205,C16))+(LN(INDEX(Dic2023!$H$6:$H$205,MIN(C16+1,200)))-LN(INDEX(Dic2023!$H$6:$H$205,C16)))*(A16-6*C16)/6)) -> 0.95070105 | E16: =D16^(-1/B16)-1 -> 0.05185536 | F16: =(1+E16)^(1/12)-1 -> 0.0042218549 | G16: =IF(C16=0,(1+Dic2023!$J$6)^(-B16),EXP(LN(INDEX(Dic2023!$K$6:$K$205,C16))+(LN(INDEX(Dic2023!$K$6:$K$205,MIN(C16+1,200)))-LN(INDEX(Dic2023!$K$6:$K$205,C16)))*(A16-6*C16)/6)) -> 0.95070105 | H16: =G16^(-1/B16)-1 -> 0.05185536 | I16: =(1+H16)^(1/12)-1 -> 0.0042218549 | J16: =IF(C16=0,(1+Dic2023!$M$6)^(-B16),EXP(LN(INDEX(Dic2023!$N$6:$N$205,C16))+(LN(INDEX(Dic2023!$N$6:$N$205,MIN(C16+1,200)))-LN(INDEX(Dic2023!$N$6:$N$205,C16)))*(A16-6*C16)/6)) -> 0.95070105 | K16: =J16^(-1/B16)-1 -> 0.05185536 | L16: =(1+K16)^(1/12)-1 -> 0.0042218549
... A1204: 1200 | B1204: =A1204/12 -> 100 | C1204: =INT(A1204/6) -> 200 | D1204: =IF(C1204=0,(1+Dic2023!$G$6)^(-B1204),EXP(LN(INDEX(Dic2023!$H$6:$H$205,C1204))+(LN(INDEX(Dic2023!$H$6:$H$205,MIN(C1204+1,200)))-LN(INDEX(Dic2023!$H$6:$H$205,C1204)))*(A1204-6*C1204)/6)) -> 0.0064362397 | E1204: =D1204^(-1/B1204)-1 -> 0.051752803 | F1204: =(1+E1204)^(1/12)-1 -> 0.0042136951 | G1204: =IF(C1204=0,(1+Dic2023!$J$6)^(-B1204),EXP(LN(INDEX(Dic2023!$K$6:$K$205,C1204))+(LN(INDEX(Dic2023!$K$6:$K$205,MIN(C1204+1,200)))-LN(INDEX(Dic2023!$K$6:$K$205,C1204)))*(A1204-6*C1204)/6)) -> 0.0064362397 | H1204: =G1204^(-1/B1204)-1 -> 0.051752803 | I1204: =(1+H1204)^(1/12)-1 -> 0.0042136951 | J1204: =IF(C1204=0,(1+Dic2023!$M$6)^(-B1204),EXP(LN(INDEX(Dic2023!$N$6:$N$205,C1204))+(LN(INDEX(Dic2023!$N$6:$N$205,MIN(C1204+1,200)))-LN(INDEX(Dic2023!$N$6:$N$205,C1204)))*(A1204-6*C1204)/6)) -> 0.0064362397 | K1204: =J1204^(-1/B1204)-1 -> 0.051752803 | L1204: =(1+K1204)^(1/12)-1 -> 0.0042136951

Sheet Mensual_Dic2024
A1: Curva mensual interpolada — Dic2024
A2: Interpolación lineal del ln(factor de descuento) entre puntos semestrales de la hoja Dic2024; por debajo de 0,5 años se mantiene la tasa de 0,5 años.
A4: Mes | B4: Plazo (años) | C4: Semestres completos k | D4: Alta: factor de descuento | E4: Alta: tasa anual efectiva | F4: Alta: tasa mensual | G4: Media: factor de descuento | H4: Media: tasa anual efectiva | I4: Media: tasa mensual | J4: Baja: factor de descuento | K4: Baja: tasa anual efectiva | L4: Baja: tasa mensual
A5: 1 | B5: =A5/12 -> 0.083333333 | C5: =INT(A5/6) -> 0 | D5: =IF(C5=0,(1+Dic2024!$G$6)^(-B5),EXP(LN(INDEX(Dic2024!$H$6:$H$205,C5))+(LN(INDEX(Dic2024!$H$6:$H$205,MIN(C5+1,200)))-LN(INDEX(Dic2024!$H$6:$H$205,C5)))*(A5-6*C5)/6)) -> 0.99624972 | E5: =D5^(-1/B5)-1 -> 0.04611984 | F5: =(1+E5)^(1/12)-1 -> 0.003764395 | G5: =IF(C5=0,(1+Dic2024!$J$6)^(-B5),EXP(LN(INDEX(Dic2024!$K$6:$K$205,C5))+(LN(INDEX(Dic2024!$K$6:$K$205,MIN(C5+1,200)))-LN(INDEX(Dic2024!$K$6:$K$205,C5)))*(A5-6*C5)/6)) -> 0.99624972 | H5: =G5^(-1/B5)-1 -> 0.04611984 | I5: =(1+H5)^(1/12)-1 -> 0.003764395 | J5: =IF(C5=0,(1+Dic2024!$M$6)^(-B5),EXP(LN(INDEX(Dic2024!$N$6:$N$205,C5))+(LN(INDEX(Dic2024!$N$6:$N$205,MIN(C5+1,200)))-LN(INDEX(Dic2024!$N$6:$N$205,C5)))*(A5-6*C5)/6)) -> 0.99624972 | K5: =J5^(-1/B5)-1 -> 0.04611984 | L5: =(1+K5)^(1/12)-1 -> 0.003764395
A6: 2 | B6: =A6/12 -> 0.16666667 | C6: =INT(A6/6) -> 0 | D6: =IF(C6=0,(1+Dic2024!$G$6)^(-B6),EXP(LN(INDEX(Dic2024!$H$6:$H$205,C6))+(LN(INDEX(Dic2024!$H$6:$H$205,MIN(C6+1,200)))-LN(INDEX(Dic2024!$H$6:$H$205,C6)))*(A6-6*C6)/6)) -> 0.99251351 | E6: =D6^(-1/B6)-1 -> 0.04611984 | F6: =(1+E6)^(1/12)-1 -> 0.003764395 | G6: =IF(C6=0,(1+Dic2024!$J$6)^(-B6),EXP(LN(INDEX(Dic2024!$K$6:$K$205,C6))+(LN(INDEX(Dic2024!$K$6:$K$205,MIN(C6+1,200)))-LN(INDEX(Dic2024!$K$6:$K$205,C6)))*(A6-6*C6)/6)) -> 0.99251351 | H6: =G6^(-1/B6)-1 -> 0.04611984 | I6: =(1+H6)^(1/12)-1 -> 0.003764395 | J6: =IF(C6=0,(1+Dic2024!$M$6)^(-B6),EXP(LN(INDEX(Dic2024!$N$6:$N$205,C6))+(LN(INDEX(Dic2024!$N$6:$N$205,MIN(C6+1,200)))-LN(INDEX(Dic2024!$N$6:$N$205,C6)))*(A6-6*C6)/6)) -> 0.99251351 | K6: =J6^(-1/B6)-1 -> 0.04611984 | L6: =(1+K6)^(1/12)-1 -> 0.003764395
A7: 3 | B7: =A7/12 -> 0.25 | C7: =INT(A7/6) -> 0 | D7: =IF(C7=0,(1+Dic2024!$G$6)^(-B7),EXP(LN(INDEX(Dic2024!$H$6:$H$205,C7))+(LN(INDEX(Dic2024!$H$6:$H$205,MIN(C7+1,200)))-LN(INDEX(Dic2024!$H$6:$H$205,C7)))*(A7-6*C7)/6)) -> 0.98879131 | E7: =D7^(-1/B7)-1 -> 0.04611984 | F7: =(1+E7)^(1/12)-1 -> 0.003764395 | G7: =IF(C7=0,(1+Dic2024!$J$6)^(-B7),EXP(LN(INDEX(Dic2024!$K$6:$K$205,C7))+(LN(INDEX(Dic2024!$K$6:$K$205,MIN(C7+1,200)))-LN(INDEX(Dic2024!$K$6:$K$205,C7)))*(A7-6*C7)/6)) -> 0.98879131 | H7: =G7^(-1/B7)-1 -> 0.04611984 | I7: =(1+H7)^(1/12)-1 -> 0.003764395 | J7: =IF(C7=0,(1+Dic2024!$M$6)^(-B7),EXP(LN(INDEX(Dic2024!$N$6:$N$205,C7))+(LN(INDEX(Dic2024!$N$6:$N$205,MIN(C7+1,200)))-LN(INDEX(Dic2024!$N$6:$N$205,C7)))*(A7-6*C7)/6)) -> 0.98879131 | K7: =J7^(-1/B7)-1 -> 0.04611984 | L7: =(1+K7)^(1/12)-1 -> 0.003764395
A8: 4 | B8: =A8/12 -> 0.33333333 | C8: =INT(A8/6) -> 0 | D8: =IF(C8=0,(1+Dic2024!$G$6)^(-B8),EXP(LN(INDEX(Dic2024!$H$6:$H$205,C8))+(LN(INDEX(Dic2024!$H$6:$H$205,MIN(C8+1,200)))-LN(INDEX(Dic2024!$H$6:$H$205,C8)))*(A8-6*C8)/6)) -> 0.98508307 | E8: =D8^(-1/B8)-1 -> 0.04611984 | F8: =(1+E8)^(1/12)-1 -> 0.003764395 | G8: =IF(C8=0,(1+Dic2024!$J$6)^(-B8),EXP(LN(INDEX(Dic2024!$K$6:$K$205,C8))+(LN(INDEX(Dic2024!$K$6:$K$205,MIN(C8+1,200)))-LN(INDEX(Dic2024!$K$6:$K$205,C8)))*(A8-6*C8)/6)) -> 0.98508307 | H8: =G8^(-1/B8)-1 -> 0.04611984 | I8: =(1+H8)^(1/12)-1 -> 0.003764395 | J8: =IF(C8=0,(1+Dic2024!$M$6)^(-B8),EXP(LN(INDEX(Dic2024!$N$6:$N$205,C8))+(LN(INDEX(Dic2024!$N$6:$N$205,MIN(C8+1,200)))-LN(INDEX(Dic2024!$N$6:$N$205,C8)))*(A8-6*C8)/6)) -> 0.98508307 | K8: =J8^(-1/B8)-1 -> 0.04611984 | L8: =(1+K8)^(1/12)-1 -> 0.003764395
A9: 5 | B9: =A9/12 -> 0.41666667 | C9: =INT(A9/6) -> 0 | D9: =IF(C9=0,(1+Dic2024!$G$6)^(-B9),EXP(LN(INDEX(Dic2024!$H$6:$H$205,C9))+(LN(INDEX(Dic2024!$H$6:$H$205,MIN(C9+1,200)))-LN(INDEX(Dic2024!$H$6:$H$205,C9)))*(A9-6*C9)/6)) -> 0.98138873 | E9: =D9^(-1/B9)-1 -> 0.04611984 | F9: =(1+E9)^(1/12)-1 -> 0.003764395 | G9: =IF(C9=0,(1+Dic2024!$J$6)^(-B9),EXP(LN(INDEX(Dic2024!$K$6:$K$205,C9))+(LN(INDEX(Dic2024!$K$6:$K$205,MIN(C9+1,200)))-LN(INDEX(Dic2024!$K$6:$K$205,C9)))*(A9-6*C9)/6)) -> 0.98138873 | H9: =G9^(-1/B9)-1 -> 0.04611984 | I9: =(1+H9)^(1/12)-1 -> 0.003764395 | J9: =IF(C9=0,(1+Dic2024!$M$6)^(-B9),EXP(LN(INDEX(Dic2024!$N$6:$N$205,C9))+(LN(INDEX(Dic2024!$N$6:$N$205,MIN(C9+1,200)))-LN(INDEX(Dic2024!$N$6:$N$205,C9)))*(A9-6*C9)/6)) -> 0.98138873 | K9: =J9^(-1/B9)-1 -> 0.04611984 | L9: =(1+K9)^(1/12)-1 -> 0.003764395
A10: 6 | B10: =A10/12 -> 0.5 | C10: =INT(A10/6) -> 1 | D10: =IF(C10=0,(1+Dic2024!$G$6)^(-B10),EXP(LN(INDEX(Dic2024!$H$6:$H$205,C10))+(LN(INDEX(Dic2024!$H$6:$H$205,MIN(C10+1,200)))-LN(INDEX(Dic2024!$H$6:$H$205,C10)))*(A10-6*C10)/6)) -> 0.97770825 | E10: =D10^(-1/B10)-1 -> 0.04611984 | F10: =(1+E10)^(1/12)-1 -> 0.003764395 | G10: =IF(C10=0,(1+Dic2024!$J$6)^(-B10),EXP(LN(INDEX(Dic2024!$K$6:$K$205,C10))+(LN(INDEX(Dic2024!$K$6:$K$205,MIN(C10+1,200)))-LN(INDEX(Dic2024!$K$6:$K$205,C10)))*(A10-6*C10)/6)) -> 0.97770825 | H10: =G10^(-1/B10)-1 -> 0.04611984 | I10: =(1+H10)^(1/12)-1 -> 0.003764395 | J10: =IF(C10=0,(1+Dic2024!$M$6)^(-B10),EXP(LN(INDEX(Dic2024!$N$6:$N$205,C10))+(LN(INDEX(Dic2024!$N$6:$N$205,MIN(C10+1,200)))-LN(INDEX(Dic2024!$N$6:$N$205,C10)))*(A10-6*C10)/6)) -> 0.97770825 | K10: =J10^(-1/B10)-1 -> 0.04611984 | L10: =(1+K10)^(1/12)-1 -> 0.003764395
A11: 7 | B11: =A11/12 -> 0.58333333 | C11: =INT(A11/6) -> 1 | D11: =IF(C11=0,(1+Dic2024!$G$6)^(-B11),EXP(LN(INDEX(Dic2024!$H$6:$H$205,C11))+(LN(INDEX(Dic2024!$H$6:$H$205,MIN(C11+1,200)))-LN(INDEX(Dic2024!$H$6:$H$205,C11)))*(A11-6*C11)/6)) -> 0.97399396 | E11: =D11^(-1/B11)-1 -> 0.046207506 | F11: =(1+E11)^(1/12)-1 -> 0.0037714044 | G11: =IF(C11=0,(1+Dic2024!$J$6)^(-B11),EXP(LN(INDEX(Dic2024!$K$6:$K$205,C11))+(LN(INDEX(Dic2024!$K$6:$K$205,MIN(C11+1,200)))-LN(INDEX(Dic2024!$K$6:$K$205,C11)))*(A11-6*C11)/6)) -> 0.97399396 | H11: =G11^(-1/B11)-1 -> 0.046207506 | I11: =(1+H11)^(1/12)-1 -> 0.0037714044 | J11: =IF(C11=0,(1+Dic2024!$M$6)^(-B11),EXP(LN(INDEX(Dic2024!$N$6:$N$205,C11))+(LN(INDEX(Dic2024!$N$6:$N$205,MIN(C11+1,200)))-LN(INDEX(Dic2024!$N$6:$N$205,C11)))*(A11-6*C11)/6)) -> 0.97399396 | K11: =J11^(-1/B11)-1 -> 0.046207506 | L11: =(1+K11)^(1/12)-1 -> 0.0037714044
A12: 8 | B12: =A12/12 -> 0.66666667 | C12: =INT(A12/6) -> 1 | D12: =IF(C12=0,(1+Dic2024!$G$6)^(-B12),EXP(LN(INDEX(Dic2024!$H$6:$H$205,C12))+(LN(INDEX(Dic2024!$H$6:$H$205,MIN(C12+1,200)))-LN(INDEX(Dic2024!$H$6:$H$205,C12)))*(A12-6*C12)/6)) -> 0.97029378 | E12: =D12^(-1/B12)-1 -> 0.04627326 | F12: =(1+E12)^(1/12)-1 -> 0.0037766615 | G12: =IF(C12=0,(1+Dic2024!$J$6)^(-B12),EXP(LN(INDEX(Dic2024!$K$6:$K$205,C12))+(LN(INDEX(Dic2024!$K$6:$K$205,MIN(C12+1,200)))-LN(INDEX(Dic2024!$K$6:$K$205,C12)))*(A12-6*C12)/6)) -> 0.97029378 | H12: =G12^(-1/B12)-1 -> 0.04627326 | I12: =(1+H12)^(1/12)-1 -> 0.0037766615 | J12: =IF(C12=0,(1+Dic2024!$M$6)^(-B12),EXP(LN(INDEX(Dic2024!$N$6:$N$205,C12))+(LN(INDEX(Dic2024!$N$6:$N$205,MIN(C12+1,200)))-LN(INDEX(Dic2024!$N$6:$N$205,C12)))*(A12-6*C12)/6)) -> 0.97029378 | K12: =J12^(-1/B12)-1 -> 0.04627326 | L12: =(1+K12)^(1/12)-1 -> 0.0037766615
A13: 9 | B13: =A13/12 -> 0.75 | C13: =INT(A13/6) -> 1 | D13: =IF(C13=0,(1+Dic2024!$G$6)^(-B13),EXP(LN(INDEX(Dic2024!$H$6:$H$205,C13))+(LN(INDEX(Dic2024!$H$6:$H$205,MIN(C13+1,200)))-LN(INDEX(Dic2024!$H$6:$H$205,C13)))*(A13-6*C13)/6)) -> 0.96660766 | E13: =D13^(-1/B13)-1 -> 0.046324405 | F13: =(1+E13)^(1/12)-1 -> 0.0037807504 | G13: =IF(C13=0,(1+Dic2024!$J$6)^(-B13),EXP(LN(INDEX(Dic2024!$K$6:$K$205,C13))+(LN(INDEX(Dic2024!$K$6:$K$205,MIN(C13+1,200)))-LN(INDEX(Dic2024!$K$6:$K$205,C13)))*(A13-6*C13)/6)) -> 0.96660766 | H13: =G13^(-1/B13)-1 -> 0.046324405 | I13: =(1+H13)^(1/12)-1 -> 0.0037807504 | J13: =IF(C13=0,(1+Dic2024!$M$6)^(-B13),EXP(LN(INDEX(Dic2024!$N$6:$N$205,C13))+(LN(INDEX(Dic2024!$N$6:$N$205,MIN(C13+1,200)))-LN(INDEX(Dic2024!$N$6:$N$205,C13)))*(A13-6*C13)/6)) -> 0.96660766 | K13: =J13^(-1/B13)-1 -> 0.046324405 | L13: =(1+K13)^(1/12)-1 -> 0.0037807504
A14: 10 | B14: =A14/12 -> 0.83333333 | C14: =INT(A14/6) -> 1 | D14: =IF(C14=0,(1+Dic2024!$G$6)^(-B14),EXP(LN(INDEX(Dic2024!$H$6:$H$205,C14))+(LN(INDEX(Dic2024!$H$6:$H$205,MIN(C14+1,200)))-LN(INDEX(Dic2024!$H$6:$H$205,C14)))*(A14-6*C14)/6)) -> 0.96293554 | E14: =D14^(-1/B14)-1 -> 0.046365323 | F14: =(1+E14)^(1/12)-1 -> 0.0037840215 | G14: =IF(C14=0,(1+Dic2024!$J$6)^(-B14),EXP(LN(INDEX(Dic2024!$K$6:$K$205,C14))+(LN(INDEX(Dic2024!$K$6:$K$205,MIN(C14+1,200)))-LN(INDEX(Dic2024!$K$6:$K$205,C14)))*(A14-6*C14)/6)) -> 0.96293554 | H14: =G14^(-1/B14)-1 -> 0.046365323 | I14: =(1+H14)^(1/12)-1 -> 0.0037840215 | J14: =IF(C14=0,(1+Dic2024!$M$6)^(-B14),EXP(LN(INDEX(Dic2024!$N$6:$N$205,C14))+(LN(INDEX(Dic2024!$N$6:$N$205,MIN(C14+1,200)))-LN(INDEX(Dic2024!$N$6:$N$205,C14)))*(A14-6*C14)/6)) -> 0.96293554 | K14: =J14^(-1/B14)-1 -> 0.046365323 | L14: =(1+K14)^(1/12)-1 -> 0.0037840215
A15: 11 | B15: =A15/12 -> 0.91666667 | C15: =INT(A15/6) -> 1 | D15: =IF(C15=0,(1+Dic2024!$G$6)^(-B15),EXP(LN(INDEX(Dic2024!$H$6:$H$205,C15))+(LN(INDEX(Dic2024!$H$6:$H$205,MIN(C15+1,200)))-LN(INDEX(Dic2024!$H$6:$H$205,C15)))*(A15-6*C15)/6)) -> 0.95927738 | E15: =D15^(-1/B15)-1 -> 0.046398802 | F15: =(1+E15)^(1/12)-1 -> 0.0037866979 | G15: =IF(C15=0,(1+Dic2024!$J$6)^(-B15),EXP(LN(INDEX(Dic2024!$K$6:$K$205,C15))+(LN(INDEX(Dic2024!$K$6:$K$205,MIN(C15+1,200)))-LN(INDEX(Dic2024!$K$6:$K$205,C15)))*(A15-6*C15)/6)) -> 0.95927738 | H15: =G15^(-1/B15)-1 -> 0.046398802 | I15: =(1+H15)^(1/12)-1 -> 0.0037866979 | J15: =IF(C15=0,(1+Dic2024!$M$6)^(-B15),EXP(LN(INDEX(Dic2024!$N$6:$N$205,C15))+(LN(INDEX(Dic2024!$N$6:$N$205,MIN(C15+1,200)))-LN(INDEX(Dic2024!$N$6:$N$205,C15)))*(A15-6*C15)/6)) -> 0.95927738 | K15: =J15^(-1/B15)-1 -> 0.046398802 | L15: =(1+K15)^(1/12)-1 -> 0.0037866979
A16: 12 | B16: =A16/12 -> 1 | C16: =INT(A16/6) -> 2 | D16: =IF(C16=0,(1+Dic2024!$G$6)^(-B16),EXP(LN(INDEX(Dic2024!$H$6:$H$205,C16))+(LN(INDEX(Dic2024!$H$6:$H$205,MIN(C16+1,200)))-LN(INDEX(Dic2024!$H$6:$H$205,C16)))*(A16-6*C16)/6)) -> 0.95563311 | E16: =D16^(-1/B16)-1 -> 0.046426702 | F16: =(1+E16)^(1/12)-1 -> 0.0037889282 | G16: =IF(C16=0,(1+Dic2024!$J$6)^(-B16),EXP(LN(INDEX(Dic2024!$K$6:$K$205,C16))+(LN(INDEX(Dic2024!$K$6:$K$205,MIN(C16+1,200)))-LN(INDEX(Dic2024!$K$6:$K$205,C16)))*(A16-6*C16)/6)) -> 0.95563311 | H16: =G16^(-1/B16)-1 -> 0.046426702 | I16: =(1+H16)^(1/12)-1 -> 0.0037889282 | J16: =IF(C16=0,(1+Dic2024!$M$6)^(-B16),EXP(LN(INDEX(Dic2024!$N$6:$N$205,C16))+(LN(INDEX(Dic2024!$N$6:$N$205,MIN(C16+1,200)))-LN(INDEX(Dic2024!$N$6:$N$205,C16)))*(A16-6*C16)/6)) -> 0.95563311 | K16: =J16^(-1/B16)-1 -> 0.046426702 | L16: =(1+K16)^(1/12)-1 -> 0.0037889282
... A1204: 1200 | B1204: =A1204/12 -> 100 | C1204: =INT(A1204/6) -> 200 | D1204: =IF(C1204=0,(1+Dic2024!$G$6)^(-B1204),EXP(LN(INDEX(Dic2024!$H$6:$H$205,C1204))+(LN(INDEX(Dic2024!$H$6:$H$205,MIN(C1204+1,200)))-LN(INDEX(Dic2024!$H$6:$H$205,C1204)))*(A1204-6*C1204)/6)) -> 0.0028421034 | E1204: =D1204^(-1/B1204)-1 -> 0.060385063 | F1204: =(1+E1204)^(1/12)-1 -> 0.0048979651 | G1204: =IF(C1204=0,(1+Dic2024!$J$6)^(-B1204),EXP(LN(INDEX(Dic2024!$K$6:$K$205,C1204))+(LN(INDEX(Dic2024!$K$6:$K$205,MIN(C1204+1,200)))-LN(INDEX(Dic2024!$K$6:$K$205,C1204)))*(A1204-6*C1204)/6)) -> 0.0028421034 | H1204: =G1204^(-1/B1204)-1 -> 0.060385063 | I1204: =(1+H1204)^(1/12)-1 -> 0.0048979651 | J1204: =IF(C1204=0,(1+Dic2024!$M$6)^(-B1204),EXP(LN(INDEX(Dic2024!$N$6:$N$205,C1204))+(LN(INDEX(Dic2024!$N$6:$N$205,MIN(C1204+1,200)))-LN(INDEX(Dic2024!$N$6:$N$205,C1204)))*(A1204-6*C1204)/6)) -> 0.0028421034 | K1204: =J1204^(-1/B1204)-1 -> 0.060385063 | L1204: =(1+K1204)^(1/12)-1 -> 0.0048979651

Sheet Mensual_Dic2025
A1: Curva mensual interpolada — Dic2025
A2: Interpolación lineal del ln(factor de descuento) entre puntos semestrales de la hoja Dic2025; por debajo de 0,5 años se mantiene la tasa de 0,5 años.
A4: Mes | B4: Plazo (años) | C4: Semestres completos k | D4: Alta: factor de descuento | E4: Alta: tasa anual efectiva | F4: Alta: tasa mensual | G4: Media: factor de descuento | H4: Media: tasa anual efectiva | I4: Media: tasa mensual | J4: Baja: factor de descuento | K4: Baja: tasa anual efectiva | L4: Baja: tasa mensual
A5: 1 | B5: =A5/12 -> 0.083333333 | C5: =INT(A5/6) -> 0 | D5: =IF(C5=0,(1+Dic2025!$G$6)^(-B5),EXP(LN(INDEX(Dic2025!$H$6:$H$205,C5))+(LN(INDEX(Dic2025!$H$6:$H$205,MIN(C5+1,200)))-LN(INDEX(Dic2025!$H$6:$H$205,C5)))*(A5-6*C5)/6)) -> 0.99686796 | E5: =D5^(-1/B5)-1 -> 0.038361 | F5: =(1+E5)^(1/12)-1 -> 0.0031418844 | G5: =IF(C5=0,(1+Dic2025!$J$6)^(-B5),EXP(LN(INDEX(Dic2025!$K$6:$K$205,C5))+(LN(INDEX(Dic2025!$K$6:$K$205,MIN(C5+1,200)))-LN(INDEX(Dic2025!$K$6:$K$205,C5)))*(A5-6*C5)/6)) -> 0.99686796 | H5: =G5^(-1/B5)-1 -> 0.038361 | I5: =(1+H5)^(1/12)-1 -> 0.0031418844 | J5: =IF(C5=0,(1+Dic2025!$M$6)^(-B5),EXP(LN(INDEX(Dic2025!$N$6:$N$205,C5))+(LN(INDEX(Dic2025!$N$6:$N$205,MIN(C5+1,200)))-LN(INDEX(Dic2025!$N$6:$N$205,C5)))*(A5-6*C5)/6)) -> 0.99686796 | K5: =J5^(-1/B5)-1 -> 0.038361 | L5: =(1+K5)^(1/12)-1 -> 0.0031418844
A6: 2 | B6: =A6/12 -> 0.16666667 | C6: =INT(A6/6) -> 0 | D6: =IF(C6=0,(1+Dic2025!$G$6)^(-B6),EXP(LN(INDEX(Dic2025!$H$6:$H$205,C6))+(LN(INDEX(Dic2025!$H$6:$H$205,MIN(C6+1,200)))-LN(INDEX(Dic2025!$H$6:$H$205,C6)))*(A6-6*C6)/6)) -> 0.99374572 | E6: =D6^(-1/B6)-1 -> 0.038361 | F6: =(1+E6)^(1/12)-1 -> 0.0031418844 | G6: =IF(C6=0,(1+Dic2025!$J$6)^(-B6),EXP(LN(INDEX(Dic2025!$K$6:$K$205,C6))+(LN(INDEX(Dic2025!$K$6:$K$205,MIN(C6+1,200)))-LN(INDEX(Dic2025!$K$6:$K$205,C6)))*(A6-6*C6)/6)) -> 0.99374572 | H6: =G6^(-1/B6)-1 -> 0.038361 | I6: =(1+H6)^(1/12)-1 -> 0.0031418844 | J6: =IF(C6=0,(1+Dic2025!$M$6)^(-B6),EXP(LN(INDEX(Dic2025!$N$6:$N$205,C6))+(LN(INDEX(Dic2025!$N$6:$N$205,MIN(C6+1,200)))-LN(INDEX(Dic2025!$N$6:$N$205,C6)))*(A6-6*C6)/6)) -> 0.99374572 | K6: =J6^(-1/B6)-1 -> 0.038361 | L6: =(1+K6)^(1/12)-1 -> 0.0031418844
A7: 3 | B7: =A7/12 -> 0.25 | C7: =INT(A7/6) -> 0 | D7: =IF(C7=0,(1+Dic2025!$G$6)^(-B7),EXP(LN(INDEX(Dic2025!$H$6:$H$205,C7))+(LN(INDEX(Dic2025!$H$6:$H$205,MIN(C7+1,200)))-LN(INDEX(Dic2025!$H$6:$H$205,C7)))*(A7-6*C7)/6)) -> 0.99063327 | E7: =D7^(-1/B7)-1 -> 0.038361 | F7: =(1+E7)^(1/12)-1 -> 0.0031418844 | G7: =IF(C7=0,(1+Dic2025!$J$6)^(-B7),EXP(LN(INDEX(Dic2025!$K$6:$K$205,C7))+(LN(INDEX(Dic2025!$K$6:$K$205,MIN(C7+1,200)))-LN(INDEX(Dic2025!$K$6:$K$205,C7)))*(A7-6*C7)/6)) -> 0.99063327 | H7: =G7^(-1/B7)-1 -> 0.038361 | I7: =(1+H7)^(1/12)-1 -> 0.0031418844 | J7: =IF(C7=0,(1+Dic2025!$M$6)^(-B7),EXP(LN(INDEX(Dic2025!$N$6:$N$205,C7))+(LN(INDEX(Dic2025!$N$6:$N$205,MIN(C7+1,200)))-LN(INDEX(Dic2025!$N$6:$N$205,C7)))*(A7-6*C7)/6)) -> 0.99063327 | K7: =J7^(-1/B7)-1 -> 0.038361 | L7: =(1+K7)^(1/12)-1 -> 0.0031418844
A8: 4 | B8: =A8/12 -> 0.33333333 | C8: =INT(A8/6) -> 0 | D8: =IF(C8=0,(1+Dic2025!$G$6)^(-B8),EXP(LN(INDEX(Dic2025!$H$6:$H$205,C8))+(LN(INDEX(Dic2025!$H$6:$H$205,MIN(C8+1,200)))-LN(INDEX(Dic2025!$H$6:$H$205,C8)))*(A8-6*C8)/6)) -> 0.98753056 | E8: =D8^(-1/B8)-1 -> 0.038361 | F8: =(1+E8)^(1/12)-1 -> 0.0031418844 | G8: =IF(C8=0,(1+Dic2025!$J$6)^(-B8),EXP(LN(INDEX(Dic2025!$K$6:$K$205,C8))+(LN(INDEX(Dic2025!$K$6:$K$205,MIN(C8+1,200)))-LN(INDEX(Dic2025!$K$6:$K$205,C8)))*(A8-6*C8)/6)) -> 0.98753056 | H8: =G8^(-1/B8)-1 -> 0.038361 | I8: =(1+H8)^(1/12)-1 -> 0.0031418844 | J8: =IF(C8=0,(1+Dic2025!$M$6)^(-B8),EXP(LN(INDEX(Dic2025!$N$6:$N$205,C8))+(LN(INDEX(Dic2025!$N$6:$N$205,MIN(C8+1,200)))-LN(INDEX(Dic2025!$N$6:$N$205,C8)))*(A8-6*C8)/6)) -> 0.98753056 | K8: =J8^(-1/B8)-1 -> 0.038361 | L8: =(1+K8)^(1/12)-1 -> 0.0031418844
