Workbook

Sheet Leeme
A1: Revisión independiente de vida temporal: modelo de una póliza
A2: Seguros Barú, S.A. (ficticia) · reconocimiento inicial al 1-ene-2025 · gemelo en Excel del notebook 08
A4: Qué es | B4: La póliza de la sección 3.1 del notebook 08, calculada con fórmulas vivas: proyección de flujos, valor presente de los flujos de cumplimiento, ajuste por riesgo por costo de capital, CSM y su amortización.
A5: Para qué | B5: Mostrar que el mismo cálculo se puede revisar celda por celda en Excel y automatizar en Python, y que ambos dan el mismo resultado (hoja Conciliacion).
A6: Hojas | B6: Supuestos: datos de la póliza y supuestos de la entidad · Tablas: CSO 1980 y curva bloqueada · Proy_Base y cuatro escenarios de choque con la misma estructura · RA_CSM: capital, ajuste por riesgo, sensibilidad a la tasa, CSM y amortización · Conciliacion: Excel contra el notebook.
A7: Cómo usarlo | B7: Cambia solo las celdas en azul de Supuestos (por ejemplo, la tasa de costo de capital, resaltada en amarillo). Todo lo demás se recalcula. La conciliación deja de cuadrar si cambias un supuesto, porque los valores de Python corresponden a los supuestos de la entidad.
A8: Colores | B8: Azul = dato o supuesto escrito a mano · Negro = fórmula · Verde = vínculo a otra hoja · Amarillo = palanca clave para pruebas de sensibilidad.
A9: Ajuste por riesgo | B9: Aquí es el de una póliza sola, sin diversificación. En el notebook el capital se diversifica en toda la cohorte y se asigna a cada celda (B88(a)), así que las cifras no son comparables una a una.
A10: Convenciones | B10: Pasos anuales. Primas, comisiones y gastos al inicio del año; muertes y gastos de siniestros al final. Flujos de cumplimiento = salidas − entradas (negativo = entrada neta).
A11: Fuentes | B11: IFRS 17 (párrafos citados en cada bloque) · SOA, 1980 CSO, tablas 42 y 36 · U.S. Treasury, curva HQM (datos del repositorio) · Reglamento Delegado (UE) 2015/35, art. 39, 137, 140 y 142 (choques de referencia).
A12: Aviso | B12: Proyecto personal con fines demostrativos. Datos sintéticos de una aseguradora ficticia. No es una opinión de auditoría ni representa la metodología, las herramientas o la opinión de ningún empleador o cliente.

Sheet Supuestos
A1: Supuestos
A2: Datos de la póliza (censo de la entidad) y documento de supuestos de la entidad
A3: Concepto | B3: Valor | C3: Fuente o nota
A4: Póliza
A5: Identificador | B5: VT2025-05533 | C5: census.csv
A6: Sexo | B6: M | C6: census.csv (M/F)
A7: Edad de emisión | B7: 45 | C7: census.csv
A8: Plazo (años) | B8: 20 | C8: census.csv; límite del contrato = plazo completo (par. 34)
A9: Suma asegurada (USD) | B9: 150000 | C9: census.csv
A10: Prima anual nivelada (USD) | B10: 1793.78 | C10: census.csv
A11: Canal | B11: agentes | C11: census.csv
A12: Comisión del primer año | B12: 0.5 | C12: assumptions.json
A13: Comisión de renovación | B13: 0.05 | C13: assumptions.json
A14: Mejor estimación (par. 33, B37–B41)
A15: Factor sobre CSO 1980, edades 25–39 | B15: 0.7 | C15: assumptions.json; edad alcanzada
A16: Factor sobre CSO 1980, edades 40–49 | B16: 0.75 | C16: assumptions.json
A17: Factor sobre CSO 1980, edades 50+ | B17: 0.95 | C17: assumptions.json
A18: Mejora anual de mortalidad | B18: 0.01 | C18: assumptions.json; desde 2025 (B58)
A19: Caducidad, año póliza 1 | B19: 0.08 | C19: assumptions.json
A20: Caducidad, año póliza 2 | B20: 0.06 | C20: assumptions.json
A21: Caducidad, año póliza 3 en adelante | B21: 0.04 | C21: assumptions.json
A22: Costo de suscripción por póliza nueva (USD) | B22: 150 | C22: assumptions.json; flujo de adquisición
A23: Mantenimiento por póliza y año (USD) | B23: 60 | C23: assumptions.json (B65(h))
A24: Costo por siniestro (USD) | B24: 200 | C24: assumptions.json (B65(f))
A25: Inflación de gastos | B25: 0.025 | C25: assumptions.json
A26: Ajuste por riesgo: costo de capital (par. 37, B86–B92)
A27: Tasa de costo de capital | B27: 0.06 | C27: Política de la entidad, tomada de Solvencia II (Reg. Delegado 2015/35, art. 39). Ver sensibilidad en RA_CSM.
A28: Choque de mortalidad | B28: 0.15 | C28: Referencia: Reg. Delegado 2015/35, art. 137
A29: Choque de caducidad (+/−) | B29: 0.5 | C29: Referencia: art. 142; se toma el peor sentido
A30: Choque de gastos | B30: 0.1 | C30: Referencia: art. 140
A31: Choque de inflación de gastos (puntos) | B31: 0.01 | C31: Referencia: art. 140
A32: Correlación mortalidad–caducidad | B32: 0 | C32: Referencia: art. 136 (matriz de vida)
A33: Correlación mortalidad–gastos | B33: 0.25 | C33: Referencia: art. 136
A34: Correlación caducidad–gastos | B34: 0.5 | C34: Referencia: art. 136
A35: Percentil del capital (a un año) | B35: 0.995 | C35: VaR al 99,5%
A36: z del percentil | B36: =NORMSINV(PercentilCapital) -> 2.5758293 | C36: Fórmula

Sheet Tablas
A1: Tablas públicas
A2: CSO 1980, edad al cumpleaños más cercano (SOA, tablas 42 y 36) · curva HQM de diciembre de 2024 (bloqueada)
A3: Edad | B3: qx hombres | C3: qx mujeres | E3: t (años) | F3: Factor de descuento bloqueado | G3: Tasa spot anual
A4: 0 | B4: 0.00418 | C4: 0.00289 | E4: 0 | F4: 1 | G4: =IF(E4=0,"",F4^(-1/E4)-1)
A5: 1 | B5: 0.00107 | C5: 0.00087 | E5: 1 | F5: 0.95563311 | G5: =IF(E5=0,"",F5^(-1/E5)-1) -> 0.046426702
A6: 2 | B6: 0.00099 | C6: 0.00081 | E6: 2 | F6: 0.91216412 | G6: =IF(E6=0,"",F6^(-1/E6)-1) -> 0.047040562
A7: 3 | B7: 0.00098 | C7: 0.00079 | E7: 3 | F7: 0.86914264 | G7: =IF(E7=0,"",F7^(-1/E7)-1) -> 0.047859322
A8: 4 | B8: 0.00095 | C8: 0.00077 | E8: 4 | F8: 0.82685757 | G8: =IF(E8=0,"",F8^(-1/E8)-1) -> 0.048678402
A9: 5 | B9: 0.0009 | C9: 0.00076 | E9: 5 | F9: 0.78501937 | G9: =IF(E9=0,"",F9^(-1/E9)-1) -> 0.04960025
A10: 6 | B10: 0.00086 | C10: 0.00073 | E10: 6 | F10: 0.74355589 | G10: =IF(E10=0,"",F10^(-1/E10)-1) -> 0.050625
A11: 7 | B11: 0.0008 | C11: 0.00072 | E11: 7 | F11: 0.70291157 | G11: =IF(E11=0,"",F11^(-1/E11)-1) -> 0.05165025
A12: 8 | B12: 0.00076 | C12: 0.0007 | E12: 8 | F12: 0.66371383 | G12: =IF(E12=0,"",F12^(-1/E12)-1) -> 0.052573402
A13: 9 | B13: 0.00074 | C13: 0.00069 | E13: 9 | F13: 0.6256053 | G13: =IF(E13=0,"",F13^(-1/E13)-1) -> 0.05349696
A14: 10 | B14: 0.00073 | C14: 0.00068 | E14: 10 | F14: 0.58922722 | G14: =IF(E14=0,"",F14^(-1/E14)-1) -> 0.05431824
A15: 11 | B15: 0.00077 | C15: 0.00069 | E15: 11 | F15: 0.55469576 | G15: =IF(E15=0,"",F15^(-1/E15)-1) -> 0.055037122
... A25: 21 | B25: 0.00191 | C25: 0.00107 | E25: 21 | F25: 0.30284011 | G25: =IF(E25=0,"",F25^(-1/E25)-1) -> 0.058532323
A26: 22 | B26: 0.00189 | C26: 0.00109
A27: 23 | B27: 0.00186 | C27: 0.00111 | E27: Fuente: data/processed/discount_curves_monthly_2024-12.csv, columna 'high' (curva de la política), meses 12, 24, …
A28: 24 | B28: 0.00182 | C28: 0.00114
A29: 25 | B29: 0.00177 | C29: 0.00116
A30: 26 | B30: 0.00173 | C30: 0.00119
A31: 27 | B31: 0.00171 | C31: 0.00122
A32: 28 | B32: 0.0017 | C32: 0.00126
A33: 29 | B33: 0.00171 | C33: 0.0013
A34: 30 | B34: 0.00173 | C34: 0.00135
A35: 31 | B35: 0.00178 | C35: 0.0014
A36: 32 | B36: 0.00183 | C36: 0.00145
A37: 33 | B37: 0.00191 | C37: 0.0015
A38: 34 | B38: 0.002 | C38: 0.00158
A39: 35 | B39: 0.00211 | C39: 0.00165
... A103: 99 | B103: 1 | C103: 1
A105: Fuente: data/raw/mortality/cso1980_anb.csv (mort.soa.org, tablas 42 y 36).

Sheet Proy_Base
A1: Proyección de flujos de cumplimiento: escenario base (mejor estimación)
A2: Misma estructura en las cinco hojas de proyección; solo cambian los multiplicadores de las celdas E3 a E6.
A3: Multiplicador de mortalidad | E3: 1 | G3: VP de primas | L3: =SUMPRODUCT(K9:K28,Q9:Q28) -> 15514.442
A4: Multiplicador de caducidad | E4: 1 | G4: VP de salidas | L4: =SUMPRODUCT(L9:L28+M9:M28+N9:N28,Q9:Q28)+SUMPRODUCT(O9:O28+P9:P28,R9:R28) -> 10757.398
A5: Multiplicador de gastos | E5: 1 | G5: Flujos de cumplimiento (salidas − entradas) | L5: =L4-L3 -> -4757.0444
A6: Inflación adicional | E6: 0 | G6: Control: suma de la columna S − L5 | L6: =ROUND(SUM(S9:S28)-L5,6) -> 0
A8: Año póliza | B8: t | C8: Edad | D8: Vigente (par. 34) | E8: q CSO 1980 | F8: Factor BE | G8: Mejora | H8: q mejor estimación | I8: Caducidad | J8: En vigor al inicio | K8: Primas | L8: Comisiones | M8: Suscripción | N8: Mantenimiento | O8: Siniestros | P8: Gasto de siniestros | Q8: FD inicio | R8: FD fin | S8: VP neto (salidas − entradas) | T8: Unidades de cobertura (B119)
A9: =B9+1 -> 1 | B9: =ROW()-9 -> 0 | C9: =EdadEmision+B9 -> 45 | D9: =IF(B9<Plazo,1,0) -> 1 | E9: =IF(Sexo="M",INDEX(CSO_H,C9+1),INDEX(CSO_M,C9+1)) -> 0.00455 | F9: =IF(C9<40,Fact_25_39,IF(C9<50,Fact_40_49,Fact_50mas)) -> 0.75 | G9: =(1-Mejora)^B9 -> 1 | H9: =D9*MIN(E9*F9*G9*$E$3,1) -> 0.0034125 | I9: =D9*MIN(IF(B9=0,Cad_Anio1,IF(B9=1,Cad_Anio2,Cad_Anio3))*$E$4,1) -> 0.08 | J9: =D9 -> 1 | K9: =J9*PrimaAnual -> 1793.78 | L9: =K9*IF(B9=0,ComisionAnio1,ComisionRenov) -> 896.89 | M9: =J9*IF(B9=0,CostoSuscripcion,0) -> 150 | N9: =J9*CostoMant*(1+Inflacion+$E$6)^B9*$E$5 -> 60 | O9: =J9*H9*SumaAsegurada -> 511.875 | P9: =J9*H9*CostoSiniestro*(1+Inflacion+$E$6)^B9*$E$5 -> 0.6825 | Q9: =INDEX(FD_Bloqueado,B9+1) -> 1 | R9: =INDEX(FD_Bloqueado,B9+2) -> 0.95563311 | S9: =(L9+M9+N9-K9)*Q9+(O9+P9)*R9 -> -197.07308 | T9: =J9*SumaAsegurada -> 150000
A10: =B10+1 -> 2 | B10: =ROW()-9 -> 1 | C10: =EdadEmision+B10 -> 46 | D10: =IF(B10<Plazo,1,0) -> 1 | E10: =IF(Sexo="M",INDEX(CSO_H,C10+1),INDEX(CSO_M,C10+1)) -> 0.00492 | F10: =IF(C10<40,Fact_25_39,IF(C10<50,Fact_40_49,Fact_50mas)) -> 0.75 | G10: =(1-Mejora)^B10 -> 0.99 | H10: =D10*MIN(E10*F10*G10*$E$3,1) -> 0.0036531 | I10: =D10*MIN(IF(B10=0,Cad_Anio1,IF(B10=1,Cad_Anio2,Cad_Anio3))*$E$4,1) -> 0.06 | J10: =J9*(1-H9)*(1-I9)*D10 -> 0.9168605 | K10: =J10*PrimaAnual -> 1644.646 | L10: =K10*IF(B10=0,ComisionAnio1,ComisionRenov) -> 82.232301 | M10: =J10*IF(B10=0,CostoSuscripcion,0) -> 0 | N10: =J10*CostoMant*(1+Inflacion+$E$6)^B10*$E$5 -> 56.386921 | O10: =J10*H10*SumaAsegurada -> 502.40746 | P10: =J10*H10*CostoSiniestro*(1+Inflacion+$E$6)^B10*$E$5 -> 0.68662353 | Q10: =INDEX(FD_Bloqueado,B10+1) -> 0.95563311 | R10: =INDEX(FD_Bloqueado,B10+2) -> 0.91216412 | S10: =(L10+M10+N10-K10)*Q10+(O10+P10)*R10 -> -980.3047 | T10: =J10*SumaAsegurada -> 137529.08
A11: =B11+1 -> 3 | B11: =ROW()-9 -> 2 | C11: =EdadEmision+B11 -> 47 | D11: =IF(B11<Plazo,1,0) -> 1 | E11: =IF(Sexo="M",INDEX(CSO_H,C11+1),INDEX(CSO_M,C11+1)) -> 0.00532 | F11: =IF(C11<40,Fact_25_39,IF(C11<50,Fact_40_49,Fact_50mas)) -> 0.75 | G11: =(1-Mejora)^B11 -> 0.9801 | H11: =D11*MIN(E11*F11*G11*$E$3,1) -> 0.003910599 | I11: =D11*MIN(IF(B11=0,Cad_Anio1,IF(B11=1,Cad_Anio2,Cad_Anio3))*$E$4,1) -> 0.04 | J11: =J10*(1-H10)*(1-I10)*D11 -> 0.85870045 | K11: =J11*PrimaAnual -> 1540.3197 | L11: =K11*IF(B11=0,ComisionAnio1,ComisionRenov) -> 77.015985 | M11: =J11*IF(B11=0,CostoSuscripcion,0) -> 0 | N11: =J11*CostoMant*(1+Inflacion+$E$6)^B11*$E$5 -> 54.13033 | O11: =J11*H11*SumaAsegurada -> 503.70497 | P11: =J11*H11*CostoSiniestro*(1+Inflacion+$E$6)^B11*$E$5 -> 0.70560671 | Q11: =INDEX(FD_Bloqueado,B11+1) -> 0.91216412 | R11: =INDEX(FD_Bloqueado,B11+2) -> 0.86914264 | S11: =(L11+M11+N11-K11)*Q11+(O11+P11)*R11 -> -846.99266 | T11: =J11*SumaAsegurada -> 128805.07
A12: =B12+1 -> 4 | B12: =ROW()-9 -> 3 | C12: =EdadEmision+B12 -> 48 | D12: =IF(B12<Plazo,1,0) -> 1 | E12: =IF(Sexo="M",INDEX(CSO_H,C12+1),INDEX(CSO_M,C12+1)) -> 0.00574 | F12: =IF(C12<40,Fact_25_39,IF(C12<50,Fact_40_49,Fact_50mas)) -> 0.75 | G12: =(1-Mejora)^B12 -> 0.970299 | H12: =D12*MIN(E12*F12*G12*$E$3,1) -> 0.0041771372 | I12: =D12*MIN(IF(B12=0,Cad_Anio1,IF(B12=1,Cad_Anio2,Cad_Anio3))*$E$4,1) -> 0.04 | J12: =J11*(1-H11)*(1-I11)*D12 -> 0.82112872 | K12: =J12*PrimaAnual -> 1472.9243 | L12: =K12*IF(B12=0,ComisionAnio1,ComisionRenov) -> 73.646214 | M12: =J12*IF(B12=0,CostoSuscripcion,0) -> 0 | N12: =J12*CostoMant*(1+Inflacion+$E$6)^B12*$E$5 -> 53.055949 | O12: =J12*H12*SumaAsegurada -> 514.4951 | P12: =J12*H12*CostoSiniestro*(1+Inflacion+$E$6)^B12*$E$5 -> 0.73873993 | Q12: =INDEX(FD_Bloqueado,B12+1) -> 0.86914264 | R12: =INDEX(FD_Bloqueado,B12+2) -> 0.82685757 | S12: =(L12+M12+N12-K12)*Q12+(O12+P12)*R12 -> -744.03404 | T12: =J12*SumaAsegurada -> 123169.31
A13: =B13+1 -> 5 | B13: =ROW()-9 -> 4 | C13: =EdadEmision+B13 -> 49 | D13: =IF(B13<Plazo,1,0) -> 1 | E13: =IF(Sexo="M",INDEX(CSO_H,C13+1),INDEX(CSO_M,C13+1)) -> 0.00621 | F13: =IF(C13<40,Fact_25_39,IF(C13<50,Fact_40_49,Fact_50mas)) -> 0.75 | G13: =(1-Mejora)^B13 -> 0.96059601 | H13: =D13*MIN(E13*F13*G13*$E$3,1) -> 0.0044739759 | I13: =D13*MIN(IF(B13=0,Cad_Anio1,IF(B13=1,Cad_Anio2,Cad_Anio3))*$E$4,1) -> 0.04 | J13: =J12*(1-H12)*(1-I12)*D13 -> 0.7849908 | K13: =J13*PrimaAnual -> 1408.1008 | L13: =K13*IF(B13=0,ComisionAnio1,ComisionRenov) -> 70.40504 | M13: =J13*IF(B13=0,CostoSuscripcion,0) -> 0 | N13: =J13*CostoMant*(1+Inflacion+$E$6)^B13*$E$5 -> 51.988978 | O13: =J13*H13*SumaAsegurada -> 526.80449 | P13: =J13*H13*CostoSiniestro*(1+Inflacion+$E$6)^B13*$E$5 -> 0.77532479 | Q13: =INDEX(FD_Bloqueado,B13+1) -> 0.82685757 | R13: =INDEX(FD_Bloqueado,B13+2) -> 0.78501937 | S13: =(L13+M13+N13-K13)*Q13+(O13+P13)*R13 -> -648.93601 | T13: =J13*SumaAsegurada -> 117748.62
A14: =B14+1 -> 6 | B14: =ROW()-9 -> 5 | C14: =EdadEmision+B14 -> 50 | D14: =IF(B14<Plazo,1,0) -> 1 | E14: =IF(Sexo="M",INDEX(CSO_H,C14+1),INDEX(CSO_M,C14+1)) -> 0.00671 | F14: =IF(C14<40,Fact_25_39,IF(C14<50,Fact_40_49,Fact_50mas)) -> 0.95 | G14: =(1-Mejora)^B14 -> 0.95099005 | H14: =D14*MIN(E14*F14*G14*$E$3,1) -> 0.0060620861 | I14: =D14*MIN(IF(B14=0,Cad_Anio1,IF(B14=1,Cad_Anio2,Cad_Anio3))*$E$4,1) -> 0.04 | J14: =J13*(1-H13)*(1-I13)*D14 -> 0.75021962 | K14: =J14*PrimaAnual -> 1345.729 | L14: =K14*IF(B14=0,ComisionAnio1,ComisionRenov) -> 67.286448 | M14: =J14*IF(B14=0,CostoSuscripcion,0) -> 0 | N14: =J14*CostoMant*(1+Inflacion+$E$6)^B14*$E$5 -> 50.928278 | O14: =J14*H14*SumaAsegurada -> 682.18439 | P14: =J14*H14*CostoSiniestro*(1+Inflacion+$E$6)^B14*$E$5 -> 1.0291054 | Q14: =INDEX(FD_Bloqueado,B14+1) -> 0.78501937 | R14: =INDEX(FD_Bloqueado,B14+2) -> 0.74355589 | S14: =(L14+M14+N14-K14)*Q14+(O14+P14)*R14 -> -455.61503 | T14: =J14*SumaAsegurada -> 112532.94
A15: =B15+1 -> 7 | B15: =ROW()-9 -> 6 | C15: =EdadEmision+B15 -> 51 | D15: =IF(B15<Plazo,1,0) -> 1 | E15: =IF(Sexo="M",INDEX(CSO_H,C15+1),INDEX(CSO_M,C15+1)) -> 0.0073 | F15: =IF(C15<40,Fact_25_39,IF(C15<50,Fact_40_49,Fact_50mas)) -> 0.95 | G15: =(1-Mejora)^B15 -> 0.94148015 | H15: =D15*MIN(E15*F15*G15*$E$3,1) -> 0.0065291648 | I15: =D15*MIN(IF(B15=0,Cad_Anio1,IF(B15=1,Cad_Anio2,Cad_Anio3))*$E$4,1) -> 0.04 | J15: =J14*(1-H14)*(1-I14)*D15 -> 0.71584486 | K15: =J15*PrimaAnual -> 1284.0682 | L15: =K15*IF(B15=0,ComisionAnio1,ComisionRenov) -> 64.203409 | M15: =J15*IF(B15=0,CostoSuscripcion,0) -> 0 | N15: =J15*CostoMant*(1+Inflacion+$E$6)^B15*$E$5 -> 49.809634 | O15: =J15*H15*SumaAsegurada -> 701.08036 | P15: =J15*H15*CostoSiniestro*(1+Inflacion+$E$6)^B15*$E$5 -> 1.084051 | Q15: =INDEX(FD_Bloqueado,B15+1) -> 0.74355589 | R15: =INDEX(FD_Bloqueado,B15+2) -> 0.70291157 | S15: =(L15+M15+N15-K15)*Q15+(O15+P15)*R15 -> -376.4419 | T15: =J15*SumaAsegurada -> 107376.73
A16: =B16+1 -> 8 | B16: =ROW()-9 -> 7 | C16: =EdadEmision+B16 -> 52 | D16: =IF(B16<Plazo,1,0) -> 1 | E16: =IF(Sexo="M",INDEX(CSO_H,C16+1),INDEX(CSO_M,C16+1)) -> 0.00796 | F16: =IF(C16<40,Fact_25_39,IF(C16<50,Fact_40_49,Fact_50mas)) -> 0.95 | G16: =(1-Mejora)^B16 -> 0.93206535 | H16: =D16*MIN(E16*F16*G16*$E$3,1) -> 0.0070482782 | I16: =D16*MIN(IF(B16=0,Cad_Anio1,IF(B16=1,Cad_Anio2,Cad_Anio3))*$E$4,1) -> 0.04 | J16: =J15*(1-H15)*(1-I15)*D16 -> 0.68272415 | K16: =J16*PrimaAnual -> 1224.6569 | L16: =K16*IF(B16=0,ComisionAnio1,ComisionRenov) -> 61.232846 | M16: =J16*IF(B16=0,CostoSuscripcion,0) -> 0 | N16: =J16*CostoMant*(1+Inflacion+$E$6)^B16*$E$5 -> 48.692668 | O16: =J16*H16*SumaAsegurada -> 721.80446 | P16: =J16*H16*CostoSiniestro*(1+Inflacion+$E$6)^B16*$E$5 -> 1.1439982 | Q16: =INDEX(FD_Bloqueado,B16+1) -> 0.70291157 | R16: =INDEX(FD_Bloqueado,B16+2) -> 0.66371383 | S16: =(L16+M16+N16-K16)*Q16+(O16+P16)*R16 -> -303.72672 | T16: =J16*SumaAsegurada -> 102408.62
A17: =B17+1 -> 9 | B17: =ROW()-9 -> 8 | C17: =EdadEmision+B17 -> 53 | D17: =IF(B17<Plazo,1,0) -> 1 | E17: =IF(Sexo="M",INDEX(CSO_H,C17+1),INDEX(CSO_M,C17+1)) -> 0.00871 | F17: =IF(C17<40,Fact_25_39,IF(C17<50,Fact_40_49,Fact_50mas)) -> 0.95 | G17: =(1-Mejora)^B17 -> 0.92274469 | H17: =D17*MIN(E17*F17*G17*$E$3,1) -> 0.007635251 | I17: =D17*MIN(IF(B17=0,Cad_Anio1,IF(B17=1,Cad_Anio2,Cad_Anio3))*$E$4,1) -> 0.04 | J17: =J16*(1-H16)*(1-I16)*D17 -> 0.65079563 | K17: =J17*PrimaAnual -> 1167.3842 | L17: =K17*IF(B17=0,ComisionAnio1,ComisionRenov) -> 58.36921 | M17: =J17*IF(B17=0,CostoSuscripcion,0) -> 0 | N17: =J17*CostoMant*(1+Inflacion+$E$6)^B17*$E$5 -> 47.575877 | O17: =J17*H17*SumaAsegurada -> 745.3482 | P17: =J17*H17*CostoSiniestro*(1+Inflacion+$E$6)^B17*$E$5 -> 1.2108459 | Q17: =INDEX(FD_Bloqueado,B17+1) -> 0.66371383 | R17: =INDEX(FD_Bloqueado,B17+2) -> 0.6256053 | S17: =(L17+M17+N17-K17)*Q17+(O17+P17)*R17 -> -237.44052 | T17: =J17*SumaAsegurada -> 97619.345
A18: =B18+1 -> 10 | B18: =ROW()-9 -> 9 | C18: =EdadEmision+B18 -> 54 | D18: =IF(B18<Plazo,1,0) -> 1 | E18: =IF(Sexo="M",INDEX(CSO_H,C18+1),INDEX(CSO_M,C18+1)) -> 0.00956 | F18: =IF(C18<40,Fact_25_39,IF(C18<50,Fact_40_49,Fact_50mas)) -> 0.95 | G18: =(1-Mejora)^B18 -> 0.91351725 | H18: =D18*MIN(E18*F18*G18*$E$3,1) -> 0.0082965636 | I18: =D18*MIN(IF(B18=0,Cad_Anio1,IF(B18=1,Cad_Anio2,Cad_Anio3))*$E$4,1) -> 0.04 | J18: =J17*(1-H17)*(1-I17)*D18 -> 0.61999358 | K18: =J18*PrimaAnual -> 1112.1321 | L18: =K18*IF(B18=0,ComisionAnio1,ComisionRenov) -> 55.606604 | M18: =J18*IF(B18=0,CostoSuscripcion,0) -> 0 | N18: =J18*CostoMant*(1+Inflacion+$E$6)^B18*$E$5 -> 46.457221 | O18: =J18*H18*SumaAsegurada -> 771.57243 | P18: =J18*H18*CostoSiniestro*(1+Inflacion+$E$6)^B18*$E$5 -> 1.2847843 | Q18: =INDEX(FD_Bloqueado,B18+1) -> 0.6256053 | R18: =INDEX(FD_Bloqueado,B18+2) -> 0.58922722 | S18: =(L18+M18+N18-K18)*Q18+(O18+P18)*R18 -> -176.51555 | T18: =J18*SumaAsegurada -> 92999.037
A19: =B19+1 -> 11 | B19: =ROW()-9 -> 10 | C19: =EdadEmision+B19 -> 55 | D19: =IF(B19<Plazo,1,0) -> 1 | E19: =IF(Sexo="M",INDEX(CSO_H,C19+1),INDEX(CSO_M,C19+1)) -> 0.01047 | F19: =IF(C19<40,Fact_25_39,IF(C19<50,Fact_40_49,Fact_50mas)) -> 0.95 | G19: =(1-Mejora)^B19 -> 0.90438208 | H19: =D19*MIN(E19*F19*G19*$E$3,1) -> 0.0089954363 | I19: =D19*MIN(IF(B19=0,Cad_Anio1,IF(B19=1,Cad_Anio2,Cad_Anio3))*$E$4,1) -> 0.04 | J19: =J18*(1-H18)*(1-I18)*D19 -> 0.59025577 | K19: =J19*PrimaAnual -> 1058.789 | L19: =K19*IF(B19=0,ComisionAnio1,ComisionRenov) -> 52.93945 | M19: =J19*IF(B19=0,CostoSuscripcion,0) -> 0 | N19: =J19*CostoMant*(1+Inflacion+$E$6)^B19*$E$5 -> 45.334638 | O19: =J19*H19*SumaAsegurada -> 796.44123 | P19: =J19*H19*CostoSiniestro*(1+Inflacion+$E$6)^B19*$E$5 -> 1.3593495 | Q19: =INDEX(FD_Bloqueado,B19+1) -> 0.58922722 | R19: =INDEX(FD_Bloqueado,B19+2) -> 0.55469576 | S19: =(L19+M19+N19-K19)*Q19+(O19+P19)*R19 -> -123.42493 | T19: =J19*SumaAsegurada -> 88538.366
A20: =B20+1 -> 12 | B20: =ROW()-9 -> 11 | C20: =EdadEmision+B20 -> 56 | D20: =IF(B20<Plazo,1,0) -> 1 | E20: =IF(Sexo="M",INDEX(CSO_H,C20+1),INDEX(CSO_M,C20+1)) -> 0.01146 | F20: =IF(C20<40,Fact_25_39,IF(C20<50,Fact_40_49,Fact_50mas)) -> 0.95 | G20: =(1-Mejora)^B20 -> 0.89533825 | H20: =D20*MIN(E20*F20*G20*$E$3,1) -> 0.0097475476 | I20: =D20*MIN(IF(B20=0,Cad_Anio1,IF(B20=1,Cad_Anio2,Cad_Anio3))*$E$4,1) -> 0.04 | J20: =J19*(1-H19)*(1-I19)*D20 -> 0.56154832 | K20: =J20*PrimaAnual -> 1007.2941 | L20: =K20*IF(B20=0,ComisionAnio1,ComisionRenov) -> 50.364707 | M20: =J20*IF(B20=0,CostoSuscripcion,0) -> 0 | N20: =J20*CostoMant*(1+Inflacion+$E$6)^B20*$E$5 -> 44.208003 | O20: =J20*H20*SumaAsegurada -> 821.05784 | P20: =J20*H20*CostoSiniestro*(1+Inflacion+$E$6)^B20*$E$5 -> 1.4363987 | Q20: =INDEX(FD_Bloqueado,B20+1) -> 0.55469576 | R20: =INDEX(FD_Bloqueado,B20+2) -> 0.52208749 | S20: =(L20+M20+N20-K20)*Q20+(O20+P20)*R20 -> -76.868761 | T20: =J20*SumaAsegurada -> 84232.248
A21: =B21+1 -> 13 | B21: =ROW()-9 -> 12 | C21: =EdadEmision+B21 -> 57 | D21: =IF(B21<Plazo,1,0) -> 1 | E21: =IF(Sexo="M",INDEX(CSO_H,C21+1),INDEX(CSO_M,C21+1)) -> 0.01249 | F21: =IF(C21<40,Fact_25_39,IF(C21<50,Fact_40_49,Fact_50mas)) -> 0.95 | G21: =(1-Mejora)^B21 -> 0.88638487 | H21: =D21*MIN(E21*F21*G21*$E$3,1) -> 0.0105174 | I21: =D21*MIN(IF(B21=0,Cad_Anio1,IF(B21=1,Cad_Anio2,Cad_Anio3))*$E$4,1) -> 0.04 | J21: =J20*(1-H20)*(1-I20)*D21 -> 0.53383162 | K21: =J21*PrimaAnual -> 957.57648 | L21: =K21*IF(B21=0,ComisionAnio1,ComisionRenov) -> 47.878824 | M21: =J21*IF(B21=0,CostoSuscripcion,0) -> 0 | N21: =J21*CostoMant*(1+Inflacion+$E$6)^B21*$E$5 -> 43.07665 | O21: =J21*H21*SumaAsegurada -> 842.17807 | P21: =J21*H21*CostoSiniestro*(1+Inflacion+$E$6)^B21*$E$5 -> 1.5101812 | Q21: =INDEX(FD_Bloqueado,B21+1) -> 0.52208749 | R21: =INDEX(FD_Bloqueado,B21+2) -> 0.49082353 | S21: =(L21+M21+N21-K21)*Q21+(O21+P21)*R21 -> -38.349931 | T21: =J21*SumaAsegurada -> 80074.742
... A28: =B28+1 -> 20 | B28: =ROW()-9 -> 19 | C28: =EdadEmision+B28 -> 64 | D28: =IF(B28<Plazo,1,0) -> 1 | E28: =IF(Sexo="M",INDEX(CSO_H,C28+1),INDEX(CSO_M,C28+1)) -> 0.02314 | F28: =IF(C28<40,Fact_25_39,IF(C28<50,Fact_40_49,Fact_50mas)) -> 0.95 | G28: =(1-Mejora)^B28 -> 0.82616862 | H28: =D28*MIN(E28*F28*G28*$E$3,1) -> 0.018161665 | I28: =D28*MIN(IF(B28=0,Cad_Anio1,IF(B28=1,Cad_Anio2,Cad_Anio3))*$E$4,1) -> 0.04 | J28: =J27*(1-H27)*(1-I27)*D28 -> 0.36513107 | K28: =J28*PrimaAnual -> 654.9648 | L28: =K28*IF(B28=0,ComisionAnio1,ComisionRenov) -> 32.74824 | M28: =J28*IF(B28=0,CostoSuscripcion,0) -> 0 | N28: =J28*CostoMant*(1+Inflacion+$E$6)^B28*$E$5 -> 35.023011 | O28: =J28*H28*SumaAsegurada -> 994.70821 | P28: =J28*H28*CostoSiniestro*(1+Inflacion+$E$6)^B28*$E$5 -> 2.1202539 | Q28: =INDEX(FD_Bloqueado,B28+1) -> 0.3405852 | R28: =INDEX(FD_Bloqueado,B28+2) -> 0.32118982 | S28: =(L28+M28+N28-K28)*Q28+(O28+P28)*R28 -> 120.18173 | T28: =J28*SumaAsegurada -> 54769.66
A29: Total | K29: =SUM(K9:K28) -> 22467.478 | L29: =SUM(L9:L28) -> 1930.5749 | M29: =SUM(M9:M28) -> 150 | N29: =SUM(N9:N28) -> 921.14325 | O29: =SUM(O9:O28) -> 15109.069 | P29: =SUM(P9:P28) -> 26.496104 | S29: =SUM(S9:S28) -> -4757.0444 | T29: =SUM(T9:T28) -> 1878782

Sheet Proy_Mort
A1: Proyección de flujos de cumplimiento: choque de mortalidad
A2: Misma estructura en las cinco hojas de proyección; solo cambian los multiplicadores de las celdas E3 a E6.
A3: Multiplicador de mortalidad | E3: =1+ChoqueMort -> 1.15 | G3: VP de primas | L3: =SUMPRODUCT(K9:K28,Q9:Q28) -> 15430.862
A4: Multiplicador de caducidad | E4: 1 | G4: VP de salidas | L4: =SUMPRODUCT(L9:L28+M9:M28+N9:N28,Q9:Q28)+SUMPRODUCT(O9:O28+P9:P28,R9:R28) -> 11928.983
A5: Multiplicador de gastos | E5: 1 | G5: Flujos de cumplimiento (salidas − entradas) | L5: =L4-L3 -> -3501.8787
A6: Inflación adicional | E6: 0 | G6: Control: suma de la columna S − L5 | L6: =ROUND(SUM(S9:S28)-L5,6) -> 0
A8: Año póliza | B8: t | C8: Edad | D8: Vigente (par. 34) | E8: q CSO 1980 | F8: Factor BE | G8: Mejora | H8: q mejor estimación | I8: Caducidad | J8: En vigor al inicio | K8: Primas | L8: Comisiones | M8: Suscripción | N8: Mantenimiento | O8: Siniestros | P8: Gasto de siniestros | Q8: FD inicio | R8: FD fin | S8: VP neto (salidas − entradas) | T8: Unidades de cobertura (B119)
A9: =B9+1 -> 1 | B9: =ROW()-9 -> 0 | C9: =EdadEmision+B9 -> 45 | D9: =IF(B9<Plazo,1,0) -> 1 | E9: =IF(Sexo="M",INDEX(CSO_H,C9+1),INDEX(CSO_M,C9+1)) -> 0.00455 | F9: =IF(C9<40,Fact_25_39,IF(C9<50,Fact_40_49,Fact_50mas)) -> 0.75 | G9: =(1-Mejora)^B9 -> 1 | H9: =D9*MIN(E9*F9*G9*$E$3,1) -> 0.003924375 | I9: =D9*MIN(IF(B9=0,Cad_Anio1,IF(B9=1,Cad_Anio2,Cad_Anio3))*$E$4,1) -> 0.08 | J9: =D9 -> 1 | K9: =J9*PrimaAnual -> 1793.78 | L9: =K9*IF(B9=0,ComisionAnio1,ComisionRenov) -> 896.89 | M9: =J9*IF(B9=0,CostoSuscripcion,0) -> 150 | N9: =J9*CostoMant*(1+Inflacion+$E$6)^B9*$E$5 -> 60 | O9: =J9*H9*SumaAsegurada -> 588.65625 | P9: =J9*H9*CostoSiniestro*(1+Inflacion+$E$6)^B9*$E$5 -> 0.784875 | Q9: =INDEX(FD_Bloqueado,B9+1) -> 1 | R9: =INDEX(FD_Bloqueado,B9+2) -> 0.95563311 | S9: =(L9+M9+N9-K9)*Q9+(O9+P9)*R9 -> -123.60055 | T9: =J9*SumaAsegurada -> 150000
A10: =B10+1 -> 2 | B10: =ROW()-9 -> 1 | C10: =EdadEmision+B10 -> 46 | D10: =IF(B10<Plazo,1,0) -> 1 | E10: =IF(Sexo="M",INDEX(CSO_H,C10+1),INDEX(CSO_M,C10+1)) -> 0.00492 | F10: =IF(C10<40,Fact_25_39,IF(C10<50,Fact_40_49,Fact_50mas)) -> 0.75 | G10: =(1-Mejora)^B10 -> 0.99 | H10: =D10*MIN(E10*F10*G10*$E$3,1) -> 0.004201065 | I10: =D10*MIN(IF(B10=0,Cad_Anio1,IF(B10=1,Cad_Anio2,Cad_Anio3))*$E$4,1) -> 0.06 | J10: =J9*(1-H9)*(1-I9)*D10 -> 0.91638957 | K10: =J10*PrimaAnual -> 1643.8013 | L10: =K10*IF(B10=0,ComisionAnio1,ComisionRenov) -> 82.190065 | M10: =J10*IF(B10=0,CostoSuscripcion,0) -> 0 | N10: =J10*CostoMant*(1+Inflacion+$E$6)^B10*$E$5 -> 56.357959 | O10: =J10*H10*SumaAsegurada -> 577.47183 | P10: =J10*H10*CostoSiniestro*(1+Inflacion+$E$6)^B10*$E$5 -> 0.78921149 | Q10: =INDEX(FD_Bloqueado,B10+1) -> 0.95563311 | R10: =INDEX(FD_Bloqueado,B10+2) -> 0.91216412 | S10: =(L10+M10+N10-K10)*Q10+(O10+P10)*R10 -> -911.00088 | T10: =J10*SumaAsegurada -> 137458.44
A11: =B11+1 -> 3 | B11: =ROW()-9 -> 2 | C11: =EdadEmision+B11 -> 47 | D11: =IF(B11<Plazo,1,0) -> 1 | E11: =IF(Sexo="M",INDEX(CSO_H,C11+1),INDEX(CSO_M,C11+1)) -> 0.00532 | F11: =IF(C11<40,Fact_25_39,IF(C11<50,Fact_40_49,Fact_50mas)) -> 0.75 | G11: =(1-Mejora)^B11 -> 0.9801 | H11: =D11*MIN(E11*F11*G11*$E$3,1) -> 0.0044971889 | I11: =D11*MIN(IF(B11=0,Cad_Anio1,IF(B11=1,Cad_Anio2,Cad_Anio3))*$E$4,1) -> 0.04 | J11: =J10*(1-H10)*(1-I10)*D11 -> 0.85778738 | K11: =J11*PrimaAnual -> 1538.6818 | L11: =K11*IF(B11=0,ComisionAnio1,ComisionRenov) -> 76.934092 | M11: =J11*IF(B11=0,CostoSuscripcion,0) -> 0 | N11: =J11*CostoMant*(1+Inflacion+$E$6)^B11*$E$5 -> 54.072772 | O11: =J11*H11*SumaAsegurada -> 578.64477 | P11: =J11*H11*CostoSiniestro*(1+Inflacion+$E$6)^B11*$E$5 -> 0.81058489 | Q11: =INDEX(FD_Bloqueado,B11+1) -> 0.91216412 | R11: =INDEX(FD_Bloqueado,B11+2) -> 0.86914264 | S11: =(L11+M11+N11-K11)*Q11+(O11+P11)*R11 -> -780.40125 | T11: =J11*SumaAsegurada -> 128668.11
A12: =B12+1 -> 4 | B12: =ROW()-9 -> 3 | C12: =EdadEmision+B12 -> 48 | D12: =IF(B12<Plazo,1,0) -> 1 | E12: =IF(Sexo="M",INDEX(CSO_H,C12+1),INDEX(CSO_M,C12+1)) -> 0.00574 | F12: =IF(C12<40,Fact_25_39,IF(C12<50,Fact_40_49,Fact_50mas)) -> 0.75 | G12: =(1-Mejora)^B12 -> 0.970299 | H12: =D12*MIN(E12*F12*G12*$E$3,1) -> 0.0048037078 | I12: =D12*MIN(IF(B12=0,Cad_Anio1,IF(B12=1,Cad_Anio2,Cad_Anio3))*$E$4,1) -> 0.04 | J12: =J11*(1-H11)*(1-I11)*D12 -> 0.81977256 | K12: =J12*PrimaAnual -> 1470.4916 | L12: =K12*IF(B12=0,ComisionAnio1,ComisionRenov) -> 73.524581 | M12: =J12*IF(B12=0,CostoSuscripcion,0) -> 0 | N12: =J12*CostoMant*(1+Inflacion+$E$6)^B12*$E$5 -> 52.968323 | O12: =J12*H12*SumaAsegurada -> 590.69217 | P12: =J12*H12*CostoSiniestro*(1+Inflacion+$E$6)^B12*$E$5 -> 0.84814781 | Q12: =INDEX(FD_Bloqueado,B12+1) -> 0.86914264 | R12: =INDEX(FD_Bloqueado,B12+2) -> 0.82685757 | S12: =(L12+M12+N12-K12)*Q12+(O12+P12)*R12 -> -679.007 | T12: =J12*SumaAsegurada -> 122965.88
A13: =B13+1 -> 5 | B13: =ROW()-9 -> 4 | C13: =EdadEmision+B13 -> 49 | D13: =IF(B13<Plazo,1,0) -> 1 | E13: =IF(Sexo="M",INDEX(CSO_H,C13+1),INDEX(CSO_M,C13+1)) -> 0.00621 | F13: =IF(C13<40,Fact_25_39,IF(C13<50,Fact_40_49,Fact_50mas)) -> 0.75 | G13: =(1-Mejora)^B13 -> 0.96059601 | H13: =D13*MIN(E13*F13*G13*$E$3,1) -> 0.0051450723 | I13: =D13*MIN(IF(B13=0,Cad_Anio1,IF(B13=1,Cad_Anio2,Cad_Anio3))*$E$4,1) -> 0.04 | J13: =J12*(1-H12)*(1-I12)*D13 -> 0.78320122 | K13: =J13*PrimaAnual -> 1404.8907 | L13: =K13*IF(B13=0,ComisionAnio1,ComisionRenov) -> 70.244535 | M13: =J13*IF(B13=0,CostoSuscripcion,0) -> 0 | N13: =J13*CostoMant*(1+Inflacion+$E$6)^B13*$E$5 -> 51.870456 | O13: =J13*H13*SumaAsegurada -> 604.44404 | P13: =J13*H13*CostoSiniestro*(1+Inflacion+$E$6)^B13*$E$5 -> 0.88959083 | Q13: =INDEX(FD_Bloqueado,B13+1) -> 0.82685757 | R13: =INDEX(FD_Bloqueado,B13+2) -> 0.78501937 | S13: =(L13+M13+N13-K13)*Q13+(O13+P13)*R13 -> -585.47417 | T13: =J13*SumaAsegurada -> 117480.18
A14: =B14+1 -> 6 | B14: =ROW()-9 -> 5 | C14: =EdadEmision+B14 -> 50 | D14: =IF(B14<Plazo,1,0) -> 1 | E14: =IF(Sexo="M",INDEX(CSO_H,C14+1),INDEX(CSO_M,C14+1)) -> 0.00671 | F14: =IF(C14<40,Fact_25_39,IF(C14<50,Fact_40_49,Fact_50mas)) -> 0.95 | G14: =(1-Mejora)^B14 -> 0.95099005 | H14: =D14*MIN(E14*F14*G14*$E$3,1) -> 0.006971399 | I14: =D14*MIN(IF(B14=0,Cad_Anio1,IF(B14=1,Cad_Anio2,Cad_Anio3))*$E$4,1) -> 0.04 | J14: =J13*(1-H13)*(1-I13)*D14 -> 0.74800473 | K14: =J14*PrimaAnual -> 1341.7559 | L14: =K14*IF(B14=0,ComisionAnio1,ComisionRenov) -> 67.087796 | M14: =J14*IF(B14=0,CostoSuscripcion,0) -> 0 | N14: =J14*CostoMant*(1+Inflacion+$E$6)^B14*$E$5 -> 50.777922 | O14: =J14*H14*SumaAsegurada -> 782.19591 | P14: =J14*H14*CostoSiniestro*(1+Inflacion+$E$6)^B14*$E$5 -> 1.1799772 | Q14: =INDEX(FD_Bloqueado,B14+1) -> 0.78501937 | R14: =INDEX(FD_Bloqueado,B14+2) -> 0.74355589 | S14: =(L14+M14+N14-K14)*Q14+(O14+P14)*R14 -> -378.29377 | T14: =J14*SumaAsegurada -> 112200.71
A15: =B15+1 -> 7 | B15: =ROW()-9 -> 6 | C15: =EdadEmision+B15 -> 51 | D15: =IF(B15<Plazo,1,0) -> 1 | E15: =IF(Sexo="M",INDEX(CSO_H,C15+1),INDEX(CSO_M,C15+1)) -> 0.0073 | F15: =IF(C15<40,Fact_25_39,IF(C15<50,Fact_40_49,Fact_50mas)) -> 0.95 | G15: =(1-Mejora)^B15 -> 0.94148015 | H15: =D15*MIN(E15*F15*G15*$E$3,1) -> 0.0075085396 | I15: =D15*MIN(IF(B15=0,Cad_Anio1,IF(B15=1,Cad_Anio2,Cad_Anio3))*$E$4,1) -> 0.04 | J15: =J14*(1-H14)*(1-I14)*D15 -> 0.71307849 | K15: =J15*PrimaAnual -> 1279.1059 | L15: =K15*IF(B15=0,ComisionAnio1,ComisionRenov) -> 63.955297 | M15: =J15*IF(B15=0,CostoSuscripcion,0) -> 0 | N15: =J15*CostoMant*(1+Inflacion+$E$6)^B15*$E$5 -> 49.617146 | O15: =J15*H15*SumaAsegurada -> 803.12671 | P15: =J15*H15*CostoSiniestro*(1+Inflacion+$E$6)^B15*$E$5 -> 1.241841 | Q15: =INDEX(FD_Bloqueado,B15+1) -> 0.74355589 | R15: =INDEX(FD_Bloqueado,B15+2) -> 0.70291157 | S15: =(L15+M15+N15-K15)*Q15+(O15+P15)*R15 -> -301.23932 | T15: =J15*SumaAsegurada -> 106961.77
A16: =B16+1 -> 8 | B16: =ROW()-9 -> 7 | C16: =EdadEmision+B16 -> 52 | D16: =IF(B16<Plazo,1,0) -> 1 | E16: =IF(Sexo="M",INDEX(CSO_H,C16+1),INDEX(CSO_M,C16+1)) -> 0.00796 | F16: =IF(C16<40,Fact_25_39,IF(C16<50,Fact_40_49,Fact_50mas)) -> 0.95 | G16: =(1-Mejora)^B16 -> 0.93206535 | H16: =D16*MIN(E16*F16*G16*$E$3,1) -> 0.0081055199 | I16: =D16*MIN(IF(B16=0,Cad_Anio1,IF(B16=1,Cad_Anio2,Cad_Anio3))*$E$4,1) -> 0.04 | J16: =J15*(1-H15)*(1-I15)*D16 -> 0.67941534 | K16: =J16*PrimaAnual -> 1218.7216 | L16: =K16*IF(B16=0,ComisionAnio1,ComisionRenov) -> 60.936082 | M16: =J16*IF(B16=0,CostoSuscripcion,0) -> 0 | N16: =J16*CostoMant*(1+Inflacion+$E$6)^B16*$E$5 -> 48.45668 | O16: =J16*H16*SumaAsegurada -> 826.05218 | P16: =J16*H16*CostoSiniestro*(1+Inflacion+$E$6)^B16*$E$5 -> 1.3092219 | Q16: =INDEX(FD_Bloqueado,B16+1) -> 0.70291157 | R16: =INDEX(FD_Bloqueado,B16+2) -> 0.66371383 | S16: =(L16+M16+N16-K16)*Q16+(O16+P16)*R16 -> -230.62891 | T16: =J16*SumaAsegurada -> 101912.3
A17: =B17+1 -> 9 | B17: =ROW()-9 -> 8 | C17: =EdadEmision+B17 -> 53 | D17: =IF(B17<Plazo,1,0) -> 1 | E17: =IF(Sexo="M",INDEX(CSO_H,C17+1),INDEX(CSO_M,C17+1)) -> 0.00871 | F17: =IF(C17<40,Fact_25_39,IF(C17<50,Fact_40_49,Fact_50mas)) -> 0.95 | G17: =(1-Mejora)^B17 -> 0.92274469 | H17: =D17*MIN(E17*F17*G17*$E$3,1) -> 0.0087805386 | I17: =D17*MIN(IF(B17=0,Cad_Anio1,IF(B17=1,Cad_Anio2,Cad_Anio3))*$E$4,1) -> 0.04 | J17: =J16*(1-H16)*(1-I16)*D17 -> 0.64695199 | K17: =J17*PrimaAnual -> 1160.4895 | L17: =K17*IF(B17=0,ComisionAnio1,ComisionRenov) -> 58.024477 | M17: =J17*IF(B17=0,CostoSuscripcion,0) -> 0 | N17: =J17*CostoMant*(1+Inflacion+$E$6)^B17*$E$5 -> 47.294891 | O17: =J17*H17*SumaAsegurada -> 852.08804 | P17: =J17*H17*CostoSiniestro*(1+Inflacion+$E$6)^B17*$E$5 -> 1.3842487 | Q17: =INDEX(FD_Bloqueado,B17+1) -> 0.66371383 | R17: =INDEX(FD_Bloqueado,B17+2) -> 0.6256053 | S17: =(L17+M17+N17-K17)*Q17+(O17+P17)*R17 -> -166.39425 | T17: =J17*SumaAsegurada -> 97042.799
A18: =B18+1 -> 10 | B18: =ROW()-9 -> 9 | C18: =EdadEmision+B18 -> 54 | D18: =IF(B18<Plazo,1,0) -> 1 | E18: =IF(Sexo="M",INDEX(CSO_H,C18+1),INDEX(CSO_M,C18+1)) -> 0.00956 | F18: =IF(C18<40,Fact_25_39,IF(C18<50,Fact_40_49,Fact_50mas)) -> 0.95 | G18: =(1-Mejora)^B18 -> 0.91351725 | H18: =D18*MIN(E18*F18*G18*$E$3,1) -> 0.0095410482 | I18: =D18*MIN(IF(B18=0,Cad_Anio1,IF(B18=1,Cad_Anio2,Cad_Anio3))*$E$4,1) -> 0.04 | J18: =J17*(1-H17)*(1-I17)*D18 -> 0.61562055 | K18: =J18*PrimaAnual -> 1104.2878 | L18: =K18*IF(B18=0,ComisionAnio1,ComisionRenov) -> 55.214391 | M18: =J18*IF(B18=0,CostoSuscripcion,0) -> 0 | N18: =J18*CostoMant*(1+Inflacion+$E$6)^B18*$E$5 -> 46.129542 | O18: =J18*H18*SumaAsegurada -> 881.0498 | P18: =J18*H18*CostoSiniestro*(1+Inflacion+$E$6)^B18*$E$5 -> 1.4670806 | Q18: =INDEX(FD_Bloqueado,B18+1) -> 0.6256053 | R18: =INDEX(FD_Bloqueado,B18+2) -> 0.58922722 | S18: =(L18+M18+N18-K18)*Q18+(O18+P18)*R18 -> -107.44405 | T18: =J18*SumaAsegurada -> 92343.082
A19: =B19+1 -> 11 | B19: =ROW()-9 -> 10 | C19: =EdadEmision+B19 -> 55 | D19: =IF(B19<Plazo,1,0) -> 1 | E19: =IF(Sexo="M",INDEX(CSO_H,C19+1),INDEX(CSO_M,C19+1)) -> 0.01047 | F19: =IF(C19<40,Fact_25_39,IF(C19<50,Fact_40_49,Fact_50mas)) -> 0.95 | G19: =(1-Mejora)^B19 -> 0.90438208 | H19: =D19*MIN(E19*F19*G19*$E$3,1) -> 0.010344752 | I19: =D19*MIN(IF(B19=0,Cad_Anio1,IF(B19=1,Cad_Anio2,Cad_Anio3))*$E$4,1) -> 0.04 | J19: =J18*(1-H18)*(1-I18)*D19 -> 0.58535701 | K19: =J19*PrimaAnual -> 1050.0017 | L19: =K19*IF(B19=0,ComisionAnio1,ComisionRenov) -> 52.500085 | M19: =J19*IF(B19=0,CostoSuscripcion,0) -> 0 | N19: =J19*CostoMant*(1+Inflacion+$E$6)^B19*$E$5 -> 44.958387 | O19: =J19*H19*SumaAsegurada -> 908.30594 | P19: =J19*H19*CostoSiniestro*(1+Inflacion+$E$6)^B19*$E$5 -> 1.5502779 | Q19: =INDEX(FD_Bloqueado,B19+1) -> 0.58922722 | R19: =INDEX(FD_Bloqueado,B19+2) -> 0.55469576 | S19: =(L19+M19+N19-K19)*Q19+(O19+P19)*R19 -> -56.571003 | T19: =J19*SumaAsegurada -> 87803.551
A20: =B20+1 -> 12 | B20: =ROW()-9 -> 11 | C20: =EdadEmision+B20 -> 56 | D20: =IF(B20<Plazo,1,0) -> 1 | E20: =IF(Sexo="M",INDEX(CSO_H,C20+1),INDEX(CSO_M,C20+1)) -> 0.01146 | F20: =IF(C20<40,Fact_25_39,IF(C20<50,Fact_40_49,Fact_50mas)) -> 0.95 | G20: =(1-Mejora)^B20 -> 0.89533825 | H20: =D20*MIN(E20*F20*G20*$E$3,1) -> 0.01120968 | I20: =D20*MIN(IF(B20=0,Cad_Anio1,IF(B20=1,Cad_Anio2,Cad_Anio3))*$E$4,1) -> 0.04 | J20: =J19*(1-H19)*(1-I19)*D20 -> 0.55612957 | K20: =J20*PrimaAnual -> 997.5741 | L20: =K20*IF(B20=0,ComisionAnio1,ComisionRenov) -> 49.878705 | M20: =J20*IF(B20=0,CostoSuscripcion,0) -> 0 | N20: =J20*CostoMant*(1+Inflacion+$E$6)^B20*$E$5 -> 43.781411 | O20: =J20*H20*SumaAsegurada -> 935.10515 | P20: =J20*H20*CostoSiniestro*(1+Inflacion+$E$6)^B20*$E$5 -> 1.6359187 | Q20: =INDEX(FD_Bloqueado,B20+1) -> 0.55469576 | R20: =INDEX(FD_Bloqueado,B20+2) -> 0.52208749 | S20: =(L20+M20+N20-K20)*Q20+(O20+P20)*R20 -> -12.336465 | T20: =J20*SumaAsegurada -> 83419.435
A21: =B21+1 -> 13 | B21: =ROW()-9 -> 12 | C21: =EdadEmision+B21 -> 57 | D21: =IF(B21<Plazo,1,0) -> 1 | E21: =IF(Sexo="M",INDEX(CSO_H,C21+1),INDEX(CSO_M,C21+1)) -> 0.01249 | F21: =IF(C21<40,Fact_25_39,IF(C21<50,Fact_40_49,Fact_50mas)) -> 0.95 | G21: =(1-Mejora)^B21 -> 0.88638487 | H21: =D21*MIN(E21*F21*G21*$E$3,1) -> 0.01209501 | I21: =D21*MIN(IF(B21=0,Cad_Anio1,IF(B21=1,Cad_Anio2,Cad_Anio3))*$E$4,1) -> 0.04 | J21: =J20*(1-H20)*(1-I20)*D21 -> 0.52789971 | K21: =J21*PrimaAnual -> 946.93595 | L21: =K21*IF(B21=0,ComisionAnio1,ComisionRenov) -> 47.346797 | M21: =J21*IF(B21=0,CostoSuscripcion,0) -> 0 | N21: =J21*CostoMant*(1+Inflacion+$E$6)^B21*$E$5 -> 42.597986 | O21: =J21*H21*SumaAsegurada -> 957.74282 | P21: =J21*H21*CostoSiniestro*(1+Inflacion+$E$6)^B21*$E$5 -> 1.7174102 | Q21: =INDEX(FD_Bloqueado,B21+1) -> 0.52208749 | R21: =INDEX(FD_Bloqueado,B21+2) -> 0.49082353 | S21: =(L21+M21+N21-K21)*Q21+(O21+P21)*R21 -> 23.501297 | T21: =J21*SumaAsegurada -> 79184.957
... A28: =B28+1 -> 20 | B28: =ROW()-9 -> 19 | C28: =EdadEmision+B28 -> 64 | D28: =IF(B28<Plazo,1,0) -> 1 | E28: =IF(Sexo="M",INDEX(CSO_H,C28+1),INDEX(CSO_M,C28+1)) -> 0.02314 | F28: =IF(C28<40,Fact_25_39,IF(C28<50,Fact_40_49,Fact_50mas)) -> 0.95 | G28: =(1-Mejora)^B28 -> 0.82616862 | H28: =D28*MIN(E28*F28*G28*$E$3,1) -> 0.020885915 | I28: =D28*MIN(IF(B28=0,Cad_Anio1,IF(B28=1,Cad_Anio2,Cad_Anio3))*$E$4,1) -> 0.04 | J28: =J27*(1-H27)*(1-I27)*D28 -> 0.3559746 | K28: =J28*PrimaAnual -> 638.54012 | L28: =K28*IF(B28=0,ComisionAnio1,ComisionRenov) -> 31.927006 | M28: =J28*IF(B28=0,CostoSuscripcion,0) -> 0 | N28: =J28*CostoMant*(1+Inflacion+$E$6)^B28*$E$5 -> 34.144732 | O28: =J28*H28*SumaAsegurada -> 1115.2283 | P28: =J28*H28*CostoSiniestro*(1+Inflacion+$E$6)^B28*$E$5 -> 2.3771465 | Q28: =INDEX(FD_Bloqueado,B28+1) -> 0.3405852 | R28: =INDEX(FD_Bloqueado,B28+2) -> 0.32118982 | S28: =(L28+M28+N28-K28)*Q28+(O28+P28)*R28 -> 163.98923 | T28: =J28*SumaAsegurada -> 53396.191
A29: Total | K29: =SUM(K9:K28) -> 22302.273 | L29: =SUM(L9:L28) -> 1922.3146 | M29: =SUM(M9:M28) -> 150 | N29: =SUM(N9:N28) -> 913.46548 | O29: =SUM(O9:O28) -> 17184.911 | P29: =SUM(P9:P28) -> 30.105146 | S29: =SUM(S9:S28) -> -3501.8787 | T29: =SUM(T9:T28) -> 1864967.2

Sheet Proy_CadAlza
A1: Proyección de flujos de cumplimiento: choque de caducidad al alza
A2: Misma estructura en las cinco hojas de proyección; solo cambian los multiplicadores de las celdas E3 a E6.
A3: Multiplicador de mortalidad | E3: 1 | G3: VP de primas | L3: =SUMPRODUCT(K9:K28,Q9:Q28) -> 13305.658
A4: Multiplicador de caducidad | E4: =1+ChoqueCad -> 1.5 | G4: VP de salidas | L4: =SUMPRODUCT(L9:L28+M9:M28+N9:N28,Q9:Q28)+SUMPRODUCT(O9:O28+P9:P28,R9:R28) -> 8948.3673
A5: Multiplicador de gastos | E5: 1 | G5: Flujos de cumplimiento (salidas − entradas) | L5: =L4-L3 -> -4357.2903
A6: Inflación adicional | E6: 0 | G6: Control: suma de la columna S − L5 | L6: =ROUND(SUM(S9:S28)-L5,6) -> 0
A8: Año póliza | B8: t | C8: Edad | D8: Vigente (par. 34) | E8: q CSO 1980 | F8: Factor BE | G8: Mejora | H8: q mejor estimación | I8: Caducidad | J8: En vigor al inicio | K8: Primas | L8: Comisiones | M8: Suscripción | N8: Mantenimiento | O8: Siniestros | P8: Gasto de siniestros | Q8: FD inicio | R8: FD fin | S8: VP neto (salidas − entradas) | T8: Unidades de cobertura (B119)
A9: =B9+1 -> 1 | B9: =ROW()-9 -> 0 | C9: =EdadEmision+B9 -> 45 | D9: =IF(B9<Plazo,1,0) -> 1 | E9: =IF(Sexo="M",INDEX(CSO_H,C9+1),INDEX(CSO_M,C9+1)) -> 0.00455 | F9: =IF(C9<40,Fact_25_39,IF(C9<50,Fact_40_49,Fact_50mas)) -> 0.75 | G9: =(1-Mejora)^B9 -> 1 | H9: =D9*MIN(E9*F9*G9*$E$3,1) -> 0.0034125 | I9: =D9*MIN(IF(B9=0,Cad_Anio1,IF(B9=1,Cad_Anio2,Cad_Anio3))*$E$4,1) -> 0.12 | J9: =D9 -> 1 | K9: =J9*PrimaAnual -> 1793.78 | L9: =K9*IF(B9=0,ComisionAnio1,ComisionRenov) -> 896.89 | M9: =J9*IF(B9=0,CostoSuscripcion,0) -> 150 | N9: =J9*CostoMant*(1+Inflacion+$E$6)^B9*$E$5 -> 60 | O9: =J9*H9*SumaAsegurada -> 511.875 | P9: =J9*H9*CostoSiniestro*(1+Inflacion+$E$6)^B9*$E$5 -> 0.6825 | Q9: =INDEX(FD_Bloqueado,B9+1) -> 1 | R9: =INDEX(FD_Bloqueado,B9+2) -> 0.95563311 | S9: =(L9+M9+N9-K9)*Q9+(O9+P9)*R9 -> -197.07308 | T9: =J9*SumaAsegurada -> 150000
A10: =B10+1 -> 2 | B10: =ROW()-9 -> 1 | C10: =EdadEmision+B10 -> 46 | D10: =IF(B10<Plazo,1,0) -> 1 | E10: =IF(Sexo="M",INDEX(CSO_H,C10+1),INDEX(CSO_M,C10+1)) -> 0.00492 | F10: =IF(C10<40,Fact_25_39,IF(C10<50,Fact_40_49,Fact_50mas)) -> 0.75 | G10: =(1-Mejora)^B10 -> 0.99 | H10: =D10*MIN(E10*F10*G10*$E$3,1) -> 0.0036531 | I10: =D10*MIN(IF(B10=0,Cad_Anio1,IF(B10=1,Cad_Anio2,Cad_Anio3))*$E$4,1) -> 0.09 | J10: =J9*(1-H9)*(1-I9)*D10 -> 0.876997 | K10: =J10*PrimaAnual -> 1573.1397 | L10: =K10*IF(B10=0,ComisionAnio1,ComisionRenov) -> 78.656984 | M10: =J10*IF(B10=0,CostoSuscripcion,0) -> 0 | N10: =J10*CostoMant*(1+Inflacion+$E$6)^B10*$E$5 -> 53.935316 | O10: =J10*H10*SumaAsegurada -> 480.56366 | P10: =J10*H10*CostoSiniestro*(1+Inflacion+$E$6)^B10*$E$5 -> 0.65677034 | Q10: =INDEX(FD_Bloqueado,B10+1) -> 0.95563311 | R10: =INDEX(FD_Bloqueado,B10+2) -> 0.91216412 | S10: =(L10+M10+N10-K10)*Q10+(O10+P10)*R10 -> -937.68275 | T10: =J10*SumaAsegurada -> 131549.55
A11: =B11+1 -> 3 | B11: =ROW()-9 -> 2 | C11: =EdadEmision+B11 -> 47 | D11: =IF(B11<Plazo,1,0) -> 1 | E11: =IF(Sexo="M",INDEX(CSO_H,C11+1),INDEX(CSO_M,C11+1)) -> 0.00532 | F11: =IF(C11<40,Fact_25_39,IF(C11<50,Fact_40_49,Fact_50mas)) -> 0.75 | G11: =(1-Mejora)^B11 -> 0.9801 | H11: =D11*MIN(E11*F11*G11*$E$3,1) -> 0.003910599 | I11: =D11*MIN(IF(B11=0,Cad_Anio1,IF(B11=1,Cad_Anio2,Cad_Anio3))*$E$4,1) -> 0.06 | J11: =J10*(1-H10)*(1-I10)*D11 -> 0.79515185 | K11: =J11*PrimaAnual -> 1426.3275 | L11: =K11*IF(B11=0,ComisionAnio1,ComisionRenov) -> 71.316374 | M11: =J11*IF(B11=0,CostoSuscripcion,0) -> 0 | N11: =J11*CostoMant*(1+Inflacion+$E$6)^B11*$E$5 -> 50.124385 | O11: =J11*H11*SumaAsegurada -> 466.428 | P11: =J11*H11*CostoSiniestro*(1+Inflacion+$E$6)^B11*$E$5 -> 0.6533879 | Q11: =INDEX(FD_Bloqueado,B11+1) -> 0.91216412 | R11: =INDEX(FD_Bloqueado,B11+2) -> 0.86914264 | S11: =(L11+M11+N11-K11)*Q11+(O11+P11)*R11 -> -784.3105 | T11: =J11*SumaAsegurada -> 119272.78
A12: =B12+1 -> 4 | B12: =ROW()-9 -> 3 | C12: =EdadEmision+B12 -> 48 | D12: =IF(B12<Plazo,1,0) -> 1 | E12: =IF(Sexo="M",INDEX(CSO_H,C12+1),INDEX(CSO_M,C12+1)) -> 0.00574 | F12: =IF(C12<40,Fact_25_39,IF(C12<50,Fact_40_49,Fact_50mas)) -> 0.75 | G12: =(1-Mejora)^B12 -> 0.970299 | H12: =D12*MIN(E12*F12*G12*$E$3,1) -> 0.0041771372 | I12: =D12*MIN(IF(B12=0,Cad_Anio1,IF(B12=1,Cad_Anio2,Cad_Anio3))*$E$4,1) -> 0.06 | J12: =J11*(1-H11)*(1-I11)*D12 -> 0.74451979 | K12: =J12*PrimaAnual -> 1335.5047 | L12: =K12*IF(B12=0,ComisionAnio1,ComisionRenov) -> 66.775235 | M12: =J12*IF(B12=0,CostoSuscripcion,0) -> 0 | N12: =J12*CostoMant*(1+Inflacion+$E$6)^B12*$E$5 -> 48.105983 | O12: =J12*H12*SumaAsegurada -> 466.4942 | P12: =J12*H12*CostoSiniestro*(1+Inflacion+$E$6)^B12*$E$5 -> 0.66981764 | Q12: =INDEX(FD_Bloqueado,B12+1) -> 0.86914264 | R12: =INDEX(FD_Bloqueado,B12+2) -> 0.82685757 | S12: =(L12+M12+N12-K12)*Q12+(O12+P12)*R12 -> -674.61782 | T12: =J12*SumaAsegurada -> 111677.97
A13: =B13+1 -> 5 | B13: =ROW()-9 -> 4 | C13: =EdadEmision+B13 -> 49 | D13: =IF(B13<Plazo,1,0) -> 1 | E13: =IF(Sexo="M",INDEX(CSO_H,C13+1),INDEX(CSO_M,C13+1)) -> 0.00621 | F13: =IF(C13<40,Fact_25_39,IF(C13<50,Fact_40_49,Fact_50mas)) -> 0.75 | G13: =(1-Mejora)^B13 -> 0.96059601 | H13: =D13*MIN(E13*F13*G13*$E$3,1) -> 0.0044739759 | I13: =D13*MIN(IF(B13=0,Cad_Anio1,IF(B13=1,Cad_Anio2,Cad_Anio3))*$E$4,1) -> 0.06 | J13: =J12*(1-H12)*(1-I12)*D13 -> 0.69692524 | K13: =J13*PrimaAnual -> 1250.1306 | L13: =K13*IF(B13=0,ComisionAnio1,ComisionRenov) -> 62.506528 | M13: =J13*IF(B13=0,CostoSuscripcion,0) -> 0 | N13: =J13*CostoMant*(1+Inflacion+$E$6)^B13*$E$5 -> 46.156504 | O13: =J13*H13*SumaAsegurada -> 467.70401 | P13: =J13*H13*CostoSiniestro*(1+Inflacion+$E$6)^B13*$E$5 -> 0.68834362 | Q13: =INDEX(FD_Bloqueado,B13+1) -> 0.82685757 | R13: =INDEX(FD_Bloqueado,B13+2) -> 0.78501937 | S13: =(L13+M13+N13-K13)*Q13+(O13+P13)*R13 -> -576.13399 | T13: =J13*SumaAsegurada -> 104538.79
A14: =B14+1 -> 6 | B14: =ROW()-9 -> 5 | C14: =EdadEmision+B14 -> 50 | D14: =IF(B14<Plazo,1,0) -> 1 | E14: =IF(Sexo="M",INDEX(CSO_H,C14+1),INDEX(CSO_M,C14+1)) -> 0.00671 | F14: =IF(C14<40,Fact_25_39,IF(C14<50,Fact_40_49,Fact_50mas)) -> 0.95 | G14: =(1-Mejora)^B14 -> 0.95099005 | H14: =D14*MIN(E14*F14*G14*$E$3,1) -> 0.0060620861 | I14: =D14*MIN(IF(B14=0,Cad_Anio1,IF(B14=1,Cad_Anio2,Cad_Anio3))*$E$4,1) -> 0.06 | J14: =J13*(1-H13)*(1-I13)*D14 -> 0.65217878 | K14: =J14*PrimaAnual -> 1169.8653 | L14: =K14*IF(B14=0,ComisionAnio1,ComisionRenov) -> 58.493263 | M14: =J14*IF(B14=0,CostoSuscripcion,0) -> 0 | N14: =J14*CostoMant*(1+Inflacion+$E$6)^B14*$E$5 -> 44.272826 | O14: =J14*H14*SumaAsegurada -> 593.03458 | P14: =J14*H14*CostoSiniestro*(1+Inflacion+$E$6)^B14*$E$5 -> 0.89461893 | Q14: =INDEX(FD_Bloqueado,B14+1) -> 0.78501937 | R14: =INDEX(FD_Bloqueado,B14+2) -> 0.74355589 | S14: =(L14+M14+N14-K14)*Q14+(O14+P14)*R14 -> -396.07396 | T14: =J14*SumaAsegurada -> 97826.817
A15: =B15+1 -> 7 | B15: =ROW()-9 -> 6 | C15: =EdadEmision+B15 -> 51 | D15: =IF(B15<Plazo,1,0) -> 1 | E15: =IF(Sexo="M",INDEX(CSO_H,C15+1),INDEX(CSO_M,C15+1)) -> 0.0073 | F15: =IF(C15<40,Fact_25_39,IF(C15<50,Fact_40_49,Fact_50mas)) -> 0.95 | G15: =(1-Mejora)^B15 -> 0.94148015 | H15: =D15*MIN(E15*F15*G15*$E$3,1) -> 0.0065291648 | I15: =D15*MIN(IF(B15=0,Cad_Anio1,IF(B15=1,Cad_Anio2,Cad_Anio3))*$E$4,1) -> 0.06 | J15: =J14*(1-H14)*(1-I14)*D15 -> 0.6093317 | K15: =J15*PrimaAnual -> 1093.007 | L15: =K15*IF(B15=0,ComisionAnio1,ComisionRenov) -> 54.650351 | M15: =J15*IF(B15=0,CostoSuscripcion,0) -> 0 | N15: =J15*CostoMant*(1+Inflacion+$E$6)^B15*$E$5 -> 42.398278 | O15: =J15*H15*SumaAsegurada -> 596.76407 | P15: =J15*H15*CostoSiniestro*(1+Inflacion+$E$6)^B15*$E$5 -> 0.92275115 | Q15: =INDEX(FD_Bloqueado,B15+1) -> 0.74355589 | R15: =INDEX(FD_Bloqueado,B15+2) -> 0.70291157 | S15: =(L15+M15+N15-K15)*Q15+(O15+P15)*R15 -> -320.42974 | T15: =J15*SumaAsegurada -> 91399.755
A16: =B16+1 -> 8 | B16: =ROW()-9 -> 7 | C16: =EdadEmision+B16 -> 52 | D16: =IF(B16<Plazo,1,0) -> 1 | E16: =IF(Sexo="M",INDEX(CSO_H,C16+1),INDEX(CSO_M,C16+1)) -> 0.00796 | F16: =IF(C16<40,Fact_25_39,IF(C16<50,Fact_40_49,Fact_50mas)) -> 0.95 | G16: =(1-Mejora)^B16 -> 0.93206535 | H16: =D16*MIN(E16*F16*G16*$E$3,1) -> 0.0070482782 | I16: =D16*MIN(IF(B16=0,Cad_Anio1,IF(B16=1,Cad_Anio2,Cad_Anio3))*$E$4,1) -> 0.06 | J16: =J15*(1-H15)*(1-I15)*D16 -> 0.56903208 | K16: =J16*PrimaAnual -> 1020.7184 | L16: =K16*IF(B16=0,ComisionAnio1,ComisionRenov) -> 51.035918 | M16: =J16*IF(B16=0,CostoSuscripcion,0) -> 0 | N16: =J16*CostoMant*(1+Inflacion+$E$6)^B16*$E$5 -> 40.58402 | O16: =J16*H16*SumaAsegurada -> 601.60446 | P16: =J16*H16*CostoSiniestro*(1+Inflacion+$E$6)^B16*$E$5 -> 0.95349153 | Q16: =INDEX(FD_Bloqueado,B16+1) -> 0.70291157 | R16: =INDEX(FD_Bloqueado,B16+2) -> 0.66371383 | S16: =(L16+M16+N16-K16)*Q16+(O16+P16)*R16 -> -253.14799 | T16: =J16*SumaAsegurada -> 85354.812
A17: =B17+1 -> 9 | B17: =ROW()-9 -> 8 | C17: =EdadEmision+B17 -> 53 | D17: =IF(B17<Plazo,1,0) -> 1 | E17: =IF(Sexo="M",INDEX(CSO_H,C17+1),INDEX(CSO_M,C17+1)) -> 0.00871 | F17: =IF(C17<40,Fact_25_39,IF(C17<50,Fact_40_49,Fact_50mas)) -> 0.95 | G17: =(1-Mejora)^B17 -> 0.92274469 | H17: =D17*MIN(E17*F17*G17*$E$3,1) -> 0.007635251 | I17: =D17*MIN(IF(B17=0,Cad_Anio1,IF(B17=1,Cad_Anio2,Cad_Anio3))*$E$4,1) -> 0.06 | J17: =J16*(1-H16)*(1-I16)*D17 -> 0.5311201 | K17: =J17*PrimaAnual -> 952.71261 | L17: =K17*IF(B17=0,ComisionAnio1,ComisionRenov) -> 47.635631 | M17: =J17*IF(B17=0,CostoSuscripcion,0) -> 0 | N17: =J17*CostoMant*(1+Inflacion+$E$6)^B17*$E$5 -> 38.827096 | O17: =J17*H17*SumaAsegurada -> 608.28529 | P17: =J17*H17*CostoSiniestro*(1+Inflacion+$E$6)^B17*$E$5 -> 0.98818208 | Q17: =INDEX(FD_Bloqueado,B17+1) -> 0.66371383 | R17: =INDEX(FD_Bloqueado,B17+2) -> 0.6256053 | S17: =(L17+M17+N17-K17)*Q17+(O17+P17)*R17 -> -193.77732 | T17: =J17*SumaAsegurada -> 79668.015
A18: =B18+1 -> 10 | B18: =ROW()-9 -> 9 | C18: =EdadEmision+B18 -> 54 | D18: =IF(B18<Plazo,1,0) -> 1 | E18: =IF(Sexo="M",INDEX(CSO_H,C18+1),INDEX(CSO_M,C18+1)) -> 0.00956 | F18: =IF(C18<40,Fact_25_39,IF(C18<50,Fact_40_49,Fact_50mas)) -> 0.95 | G18: =(1-Mejora)^B18 -> 0.91351725 | H18: =D18*MIN(E18*F18*G18*$E$3,1) -> 0.0082965636 | I18: =D18*MIN(IF(B18=0,Cad_Anio1,IF(B18=1,Cad_Anio2,Cad_Anio3))*$E$4,1) -> 0.06 | J18: =J17*(1-H17)*(1-I17)*D18 -> 0.49544097 | K18: =J18*PrimaAnual -> 888.71211 | L18: =K18*IF(B18=0,ComisionAnio1,ComisionRenov) -> 44.435605 | M18: =J18*IF(B18=0,CostoSuscripcion,0) -> 0 | N18: =J18*CostoMant*(1+Inflacion+$E$6)^B18*$E$5 -> 37.124273 | O18: =J18*H18*SumaAsegurada -> 616.56863 | P18: =J18*H18*CostoSiniestro*(1+Inflacion+$E$6)^B18*$E$5 -> 1.0266796 | Q18: =INDEX(FD_Bloqueado,B18+1) -> 0.6256053 | R18: =INDEX(FD_Bloqueado,B18+2) -> 0.58922722 | S18: =(L18+M18+N18-K18)*Q18+(O18+P18)*R18 -> -141.05474 | T18: =J18*SumaAsegurada -> 74316.146
A19: =B19+1 -> 11 | B19: =ROW()-9 -> 10 | C19: =EdadEmision+B19 -> 55 | D19: =IF(B19<Plazo,1,0) -> 1 | E19: =IF(Sexo="M",INDEX(CSO_H,C19+1),INDEX(CSO_M,C19+1)) -> 0.01047 | F19: =IF(C19<40,Fact_25_39,IF(C19<50,Fact_40_49,Fact_50mas)) -> 0.95 | G19: =(1-Mejora)^B19 -> 0.90438208 | H19: =D19*MIN(E19*F19*G19*$E$3,1) -> 0.0089954363 | I19: =D19*MIN(IF(B19=0,Cad_Anio1,IF(B19=1,Cad_Anio2,Cad_Anio3))*$E$4,1) -> 0.06 | J19: =J18*(1-H18)*(1-I18)*D19 -> 0.46185068 | K19: =J19*PrimaAnual -> 828.45852 | L19: =K19*IF(B19=0,ComisionAnio1,ComisionRenov) -> 41.422926 | M19: =J19*IF(B19=0,CostoSuscripcion,0) -> 0 | N19: =J19*CostoMant*(1+Inflacion+$E$6)^B19*$E$5 -> 35.472475 | O19: =J19*H19*SumaAsegurada -> 623.18226 | P19: =J19*H19*CostoSiniestro*(1+Inflacion+$E$6)^B19*$E$5 -> 1.0636346 | Q19: =INDEX(FD_Bloqueado,B19+1) -> 0.58922722 | R19: =INDEX(FD_Bloqueado,B19+2) -> 0.55469576 | S19: =(L19+M19+N19-K19)*Q19+(O19+P19)*R19 -> -96.574891 | T19: =J19*SumaAsegurada -> 69277.603
A20: =B20+1 -> 12 | B20: =ROW()-9 -> 11 | C20: =EdadEmision+B20 -> 56 | D20: =IF(B20<Plazo,1,0) -> 1 | E20: =IF(Sexo="M",INDEX(CSO_H,C20+1),INDEX(CSO_M,C20+1)) -> 0.01146 | F20: =IF(C20<40,Fact_25_39,IF(C20<50,Fact_40_49,Fact_50mas)) -> 0.95 | G20: =(1-Mejora)^B20 -> 0.89533825 | H20: =D20*MIN(E20*F20*G20*$E$3,1) -> 0.0097475476 | I20: =D20*MIN(IF(B20=0,Cad_Anio1,IF(B20=1,Cad_Anio2,Cad_Anio3))*$E$4,1) -> 0.06 | J20: =J19*(1-H19)*(1-I19)*D20 -> 0.43023437 | K20: =J20*PrimaAnual -> 771.7458 | L20: =K20*IF(B20=0,ComisionAnio1,ComisionRenov) -> 38.58729 | M20: =J20*IF(B20=0,CostoSuscripcion,0) -> 0 | N20: =J20*CostoMant*(1+Inflacion+$E$6)^B20*$E$5 -> 33.870286 | O20: =J20*H20*SumaAsegurada -> 629.0595 | P20: =J20*H20*CostoSiniestro*(1+Inflacion+$E$6)^B20*$E$5 -> 1.1005074 | Q20: =INDEX(FD_Bloqueado,B20+1) -> 0.55469576 | R20: =INDEX(FD_Bloqueado,B20+2) -> 0.52208749 | S20: =(L20+M20+N20-K20)*Q20+(O20+P20)*R20 -> -58.893566 | T20: =J20*SumaAsegurada -> 64535.155
A21: =B21+1 -> 13 | B21: =ROW()-9 -> 12 | C21: =EdadEmision+B21 -> 57 | D21: =IF(B21<Plazo,1,0) -> 1 | E21: =IF(Sexo="M",INDEX(CSO_H,C21+1),INDEX(CSO_M,C21+1)) -> 0.01249 | F21: =IF(C21<40,Fact_25_39,IF(C21<50,Fact_40_49,Fact_50mas)) -> 0.95 | G21: =(1-Mejora)^B21 -> 0.88638487 | H21: =D21*MIN(E21*F21*G21*$E$3,1) -> 0.0105174 | I21: =D21*MIN(IF(B21=0,Cad_Anio1,IF(B21=1,Cad_Anio2,Cad_Anio3))*$E$4,1) -> 0.06 | J21: =J20*(1-H20)*(1-I20)*D21 -> 0.4004782 | K21: =J21*PrimaAnual -> 718.36978 | L21: =K21*IF(B21=0,ComisionAnio1,ComisionRenov) -> 35.918489 | M21: =J21*IF(B21=0,CostoSuscripcion,0) -> 0 | N21: =J21*CostoMant*(1+Inflacion+$E$6)^B21*$E$5 -> 32.315919 | O21: =J21*H21*SumaAsegurada -> 631.79839 | P21: =J21*H21*CostoSiniestro*(1+Inflacion+$E$6)^B21*$E$5 -> 1.1329315 | Q21: =INDEX(FD_Bloqueado,B21+1) -> 0.52208749 | R21: =INDEX(FD_Bloqueado,B21+2) -> 0.49082353 | S21: =(L21+M21+N21-K21)*Q21+(O21+P21)*R21 -> -28.769955 | T21: =J21*SumaAsegurada -> 60071.73
... A28: =B28+1 -> 20 | B28: =ROW()-9 -> 19 | C28: =EdadEmision+B28 -> 64 | D28: =IF(B28<Plazo,1,0) -> 1 | E28: =IF(Sexo="M",INDEX(CSO_H,C28+1),INDEX(CSO_M,C28+1)) -> 0.02314 | F28: =IF(C28<40,Fact_25_39,IF(C28<50,Fact_40_49,Fact_50mas)) -> 0.95 | G28: =(1-Mejora)^B28 -> 0.82616862 | H28: =D28*MIN(E28*F28*G28*$E$3,1) -> 0.018161665 | I28: =D28*MIN(IF(B28=0,Cad_Anio1,IF(B28=1,Cad_Anio2,Cad_Anio3))*$E$4,1) -> 0.06 | J28: =J27*(1-H27)*(1-I27)*D28 -> 0.23638489 | K28: =J28*PrimaAnual -> 424.02249 | L28: =K28*IF(B28=0,ComisionAnio1,ComisionRenov) -> 21.201125 | M28: =J28*IF(B28=0,CostoSuscripcion,0) -> 0 | N28: =J28*CostoMant*(1+Inflacion+$E$6)^B28*$E$5 -> 22.673805 | O28: =J28*H28*SumaAsegurada -> 643.97148 | P28: =J28*H28*CostoSiniestro*(1+Inflacion+$E$6)^B28*$E$5 -> 1.3726468 | Q28: =INDEX(FD_Bloqueado,B28+1) -> 0.3405852 | R28: =INDEX(FD_Bloqueado,B28+2) -> 0.32118982 | S28: =(L28+M28+N28-K28)*Q28+(O28+P28)*R28 -> 77.805334 | T28: =J28*SumaAsegurada -> 35457.734
A29: Total | K29: =SUM(K9:K28) -> 18601.471 | L29: =SUM(L9:L28) -> 1737.2745 | M29: =SUM(M9:M28) -> 150 | N29: =SUM(N9:N28) -> 749.66838 | O29: =SUM(O9:O28) -> 11748.772 | P29: =SUM(P9:P28) -> 20.265685 | S29: =SUM(S9:S28) -> -4357.2903 | T29: =SUM(T9:T28) -> 1555497.7

Sheet Proy_CadBaja
A1: Proyección de flujos de cumplimiento: choque de caducidad a la baja
A2: Misma estructura en las cinco hojas de proyección; solo cambian los multiplicadores de las celdas E3 a E6.
A3: Multiplicador de mortalidad | E3: 1 | G3: VP de primas | L3: =SUMPRODUCT(K9:K28,Q9:Q28) -> 18242.913
A4: Multiplicador de caducidad | E4: =1-ChoqueCad -> 0.5 | G4: VP de salidas | L4: =SUMPRODUCT(L9:L28+M9:M28+N9:N28,Q9:Q28)+SUMPRODUCT(O9:O28+P9:P28,R9:R28) -> 13086.647
A5: Multiplicador de gastos | E5: 1 | G5: Flujos de cumplimiento (salidas − entradas) | L5: =L4-L3 -> -5156.2663
A6: Inflación adicional | E6: 0 | G6: Control: suma de la columna S − L5 | L6: =ROUND(SUM(S9:S28)-L5,6) -> 0
A8: Año póliza | B8: t | C8: Edad | D8: Vigente (par. 34) | E8: q CSO 1980 | F8: Factor BE | G8: Mejora | H8: q mejor estimación | I8: Caducidad | J8: En vigor al inicio | K8: Primas | L8: Comisiones | M8: Suscripción | N8: Mantenimiento | O8: Siniestros | P8: Gasto de siniestros | Q8: FD inicio | R8: FD fin | S8: VP neto (salidas − entradas) | T8: Unidades de cobertura (B119)
A9: =B9+1 -> 1 | B9: =ROW()-9 -> 0 | C9: =EdadEmision+B9 -> 45 | D9: =IF(B9<Plazo,1,0) -> 1 | E9: =IF(Sexo="M",INDEX(CSO_H,C9+1),INDEX(CSO_M,C9+1)) -> 0.00455 | F9: =IF(C9<40,Fact_25_39,IF(C9<50,Fact_40_49,Fact_50mas)) -> 0.75 | G9: =(1-Mejora)^B9 -> 1 | H9: =D9*MIN(E9*F9*G9*$E$3,1) -> 0.0034125 | I9: =D9*MIN(IF(B9=0,Cad_Anio1,IF(B9=1,Cad_Anio2,Cad_Anio3))*$E$4,1) -> 0.04 | J9: =D9 -> 1 | K9: =J9*PrimaAnual -> 1793.78 | L9: =K9*IF(B9=0,ComisionAnio1,ComisionRenov) -> 896.89 | M9: =J9*IF(B9=0,CostoSuscripcion,0) -> 150 | N9: =J9*CostoMant*(1+Inflacion+$E$6)^B9*$E$5 -> 60 | O9: =J9*H9*SumaAsegurada -> 511.875 | P9: =J9*H9*CostoSiniestro*(1+Inflacion+$E$6)^B9*$E$5 -> 0.6825 | Q9: =INDEX(FD_Bloqueado,B9+1) -> 1 | R9: =INDEX(FD_Bloqueado,B9+2) -> 0.95563311 | S9: =(L9+M9+N9-K9)*Q9+(O9+P9)*R9 -> -197.07308 | T9: =J9*SumaAsegurada -> 150000
A10: =B10+1 -> 2 | B10: =ROW()-9 -> 1 | C10: =EdadEmision+B10 -> 46 | D10: =IF(B10<Plazo,1,0) -> 1 | E10: =IF(Sexo="M",INDEX(CSO_H,C10+1),INDEX(CSO_M,C10+1)) -> 0.00492 | F10: =IF(C10<40,Fact_25_39,IF(C10<50,Fact_40_49,Fact_50mas)) -> 0.75 | G10: =(1-Mejora)^B10 -> 0.99 | H10: =D10*MIN(E10*F10*G10*$E$3,1) -> 0.0036531 | I10: =D10*MIN(IF(B10=0,Cad_Anio1,IF(B10=1,Cad_Anio2,Cad_Anio3))*$E$4,1) -> 0.03 | J10: =J9*(1-H9)*(1-I9)*D10 -> 0.956724 | K10: =J10*PrimaAnual -> 1716.1524 | L10: =K10*IF(B10=0,ComisionAnio1,ComisionRenov) -> 85.807619 | M10: =J10*IF(B10=0,CostoSuscripcion,0) -> 0 | N10: =J10*CostoMant*(1+Inflacion+$E$6)^B10*$E$5 -> 58.838526 | O10: =J10*H10*SumaAsegurada -> 524.25127 | P10: =J10*H10*CostoSiniestro*(1+Inflacion+$E$6)^B10*$E$5 -> 0.71647673 | Q10: =INDEX(FD_Bloqueado,B10+1) -> 0.95563311 | R10: =INDEX(FD_Bloqueado,B10+2) -> 0.91216412 | S10: =(L10+M10+N10-K10)*Q10+(O10+P10)*R10 -> -1022.9266 | T10: =J10*SumaAsegurada -> 143508.6
A11: =B11+1 -> 3 | B11: =ROW()-9 -> 2 | C11: =EdadEmision+B11 -> 47 | D11: =IF(B11<Plazo,1,0) -> 1 | E11: =IF(Sexo="M",INDEX(CSO_H,C11+1),INDEX(CSO_M,C11+1)) -> 0.00532 | F11: =IF(C11<40,Fact_25_39,IF(C11<50,Fact_40_49,Fact_50mas)) -> 0.75 | G11: =(1-Mejora)^B11 -> 0.9801 | H11: =D11*MIN(E11*F11*G11*$E$3,1) -> 0.003910599 | I11: =D11*MIN(IF(B11=0,Cad_Anio1,IF(B11=1,Cad_Anio2,Cad_Anio3))*$E$4,1) -> 0.02 | J11: =J10*(1-H10)*(1-I10)*D11 -> 0.92463212 | K11: =J11*PrimaAnual -> 1658.5866 | L11: =K11*IF(B11=0,ComisionAnio1,ComisionRenov) -> 82.92933 | M11: =J11*IF(B11=0,CostoSuscripcion,0) -> 0 | N11: =J11*CostoMant*(1+Inflacion+$E$6)^B11*$E$5 -> 58.286497 | O11: =J11*H11*SumaAsegurada -> 542.37982 | P11: =J11*H11*CostoSiniestro*(1+Inflacion+$E$6)^B11*$E$5 -> 0.75978373 | Q11: =INDEX(FD_Bloqueado,B11+1) -> 0.91216412 | R11: =INDEX(FD_Bloqueado,B11+2) -> 0.86914264 | S11: =(L11+M11+N11-K11)*Q11+(O11+P11)*R11 -> -912.0254 | T11: =J11*SumaAsegurada -> 138694.82
A12: =B12+1 -> 4 | B12: =ROW()-9 -> 3 | C12: =EdadEmision+B12 -> 48 | D12: =IF(B12<Plazo,1,0) -> 1 | E12: =IF(Sexo="M",INDEX(CSO_H,C12+1),INDEX(CSO_M,C12+1)) -> 0.00574 | F12: =IF(C12<40,Fact_25_39,IF(C12<50,Fact_40_49,Fact_50mas)) -> 0.75 | G12: =(1-Mejora)^B12 -> 0.970299 | H12: =D12*MIN(E12*F12*G12*$E$3,1) -> 0.0041771372 | I12: =D12*MIN(IF(B12=0,Cad_Anio1,IF(B12=1,Cad_Anio2,Cad_Anio3))*$E$4,1) -> 0.02 | J12: =J11*(1-H11)*(1-I11)*D12 -> 0.90259593 | K12: =J12*PrimaAnual -> 1619.0585 | L12: =K12*IF(B12=0,ComisionAnio1,ComisionRenov) -> 80.952926 | M12: =J12*IF(B12=0,CostoSuscripcion,0) -> 0 | N12: =J12*CostoMant*(1+Inflacion+$E$6)^B12*$E$5 -> 58.319826 | O12: =J12*H12*SumaAsegurada -> 565.54006 | P12: =J12*H12*CostoSiniestro*(1+Inflacion+$E$6)^B12*$E$5 -> 0.81203305 | Q12: =INDEX(FD_Bloqueado,B12+1) -> 0.86914264 | R12: =INDEX(FD_Bloqueado,B12+2) -> 0.82685757 | S12: =(L12+M12+N12-K12)*Q12+(O12+P12)*R12 -> -817.8524 | T12: =J12*SumaAsegurada -> 135389.39
A13: =B13+1 -> 5 | B13: =ROW()-9 -> 4 | C13: =EdadEmision+B13 -> 49 | D13: =IF(B13<Plazo,1,0) -> 1 | E13: =IF(Sexo="M",INDEX(CSO_H,C13+1),INDEX(CSO_M,C13+1)) -> 0.00621 | F13: =IF(C13<40,Fact_25_39,IF(C13<50,Fact_40_49,Fact_50mas)) -> 0.75 | G13: =(1-Mejora)^B13 -> 0.96059601 | H13: =D13*MIN(E13*F13*G13*$E$3,1) -> 0.0044739759 | I13: =D13*MIN(IF(B13=0,Cad_Anio1,IF(B13=1,Cad_Anio2,Cad_Anio3))*$E$4,1) -> 0.02 | J13: =J12*(1-H12)*(1-I12)*D13 -> 0.88084915 | K13: =J13*PrimaAnual -> 1580.0496 | L13: =K13*IF(B13=0,ComisionAnio1,ComisionRenov) -> 79.002479 | M13: =J13*IF(B13=0,CostoSuscripcion,0) -> 0 | N13: =J13*CostoMant*(1+Inflacion+$E$6)^B13*$E$5 -> 58.337559 | O13: =J13*H13*SumaAsegurada -> 591.13468 | P13: =J13*H13*CostoSiniestro*(1+Inflacion+$E$6)^B13*$E$5 -> 0.87000278 | Q13: =INDEX(FD_Bloqueado,B13+1) -> 0.82685757 | R13: =INDEX(FD_Bloqueado,B13+2) -> 0.78501937 | S13: =(L13+M13+N13-K13)*Q13+(O13+P13)*R13 -> -728.18016 | T13: =J13*SumaAsegurada -> 132127.37
A14: =B14+1 -> 6 | B14: =ROW()-9 -> 5 | C14: =EdadEmision+B14 -> 50 | D14: =IF(B14<Plazo,1,0) -> 1 | E14: =IF(Sexo="M",INDEX(CSO_H,C14+1),INDEX(CSO_M,C14+1)) -> 0.00671 | F14: =IF(C14<40,Fact_25_39,IF(C14<50,Fact_40_49,Fact_50mas)) -> 0.95 | G14: =(1-Mejora)^B14 -> 0.95099005 | H14: =D14*MIN(E14*F14*G14*$E$3,1) -> 0.0060620861 | I14: =D14*MIN(IF(B14=0,Cad_Anio1,IF(B14=1,Cad_Anio2,Cad_Anio3))*$E$4,1) -> 0.02 | J14: =J13*(1-H13)*(1-I13)*D14 -> 0.85937009 | K14: =J14*PrimaAnual -> 1541.5209 | L14: =K14*IF(B14=0,ComisionAnio1,ComisionRenov) -> 77.076044 | M14: =J14*IF(B14=0,CostoSuscripcion,0) -> 0 | N14: =J14*CostoMant*(1+Inflacion+$E$6)^B14*$E$5 -> 58.337903 | O14: =J14*H14*SumaAsegurada -> 781.43632 | P14: =J14*H14*CostoSiniestro*(1+Inflacion+$E$6)^B14*$E$5 -> 1.1788313 | Q14: =INDEX(FD_Bloqueado,B14+1) -> 0.78501937 | R14: =INDEX(FD_Bloqueado,B14+2) -> 0.74355589 | S14: =(L14+M14+N14-K14)*Q14+(O14+P14)*R14 -> -521.90308 | T14: =J14*SumaAsegurada -> 128905.51
A15: =B15+1 -> 7 | B15: =ROW()-9 -> 6 | C15: =EdadEmision+B15 -> 51 | D15: =IF(B15<Plazo,1,0) -> 1 | E15: =IF(Sexo="M",INDEX(CSO_H,C15+1),INDEX(CSO_M,C15+1)) -> 0.0073 | F15: =IF(C15<40,Fact_25_39,IF(C15<50,Fact_40_49,Fact_50mas)) -> 0.95 | G15: =(1-Mejora)^B15 -> 0.94148015 | H15: =D15*MIN(E15*F15*G15*$E$3,1) -> 0.0065291648 | I15: =D15*MIN(IF(B15=0,Cad_Anio1,IF(B15=1,Cad_Anio2,Cad_Anio3))*$E$4,1) -> 0.02 | J15: =J14*(1-H14)*(1-I14)*D15 -> 0.8370773 | K15: =J15*PrimaAnual -> 1501.5325 | L15: =K15*IF(B15=0,ComisionAnio1,ComisionRenov) -> 75.076626 | M15: =J15*IF(B15=0,CostoSuscripcion,0) -> 0 | N15: =J15*CostoMant*(1+Inflacion+$E$6)^B15*$E$5 -> 58.245182 | O15: =J15*H15*SumaAsegurada -> 819.81235 | P15: =J15*H15*CostoSiniestro*(1+Inflacion+$E$6)^B15*$E$5 -> 1.2676413 | Q15: =INDEX(FD_Bloqueado,B15+1) -> 0.74355589 | R15: =INDEX(FD_Bloqueado,B15+2) -> 0.70291157 | S15: =(L15+M15+N15-K15)*Q15+(O15+P15)*R15 -> -440.1945 | T15: =J15*SumaAsegurada -> 125561.6
